Workbook
Name HCData: #REF!

Sheet Dashboard
A1: AUH1 | S1: AUH3 | AF1: DAD1
A2: Previous Day HC | B2: L3 Ops Supervisors | C2: FTE HC | D2: NFTE HC | E2: Today's HC | F2: HC LM Target | G2: Achievement % | H2: Remarks | S2: Previous Day HC | T2: L3 Ops Supervisors | U2: FTE HC | V2: NFTE HC | W2: Today's HC | X2: HC LM Target | Y2: Achievement % | Z2: Remarks | AF2: Previous Day HC | AG2: L3 Ops Supervisors | AH2: FTE HC | AI2: NFTE HC | AJ2: Today's HC | AK2: HC LM Target | AL2: Achievement % | AM2: Remarks
A3: 1198 | B3: =COUNTIFS(Roster!N:N,"FC Associate III",Roster!G:G,"AUH1",Roster!P:P,"Direct") -> 30 | C3: =COUNTIFS(Roster!E:E,"Regular",Roster!G:G,"AUH1",Roster!P:P,"Direct") -> 60 | D3: =COUNTIFS(Roster!E:E,"Temporary",Roster!G:G,"AUH1",Roster!P:P,"Direct") -> 1137 | E3: =C3+D3 -> 1197 | F3: =E3 -> 1197 | G3: =E3/F3 -> 1 | H3: 1 NFTE Terminated | S3: 82 | T3: =COUNTIFS(Roster!N:N,"Hub Supervisor",Roster!P:P,"Direct",Roster!O:O,"Warehouse Deals") -> 4 | U3: =COUNTIFS(Roster!E:E,"Regular",Roster!P:P,"Direct",Roster!O:O,"Warehouse Deals") -> 14 | V3: =COUNTIFS(Roster!E:E,"Temporary",Roster!P:P,"Direct",Roster!O:O,"Warehouse Deals") -> 89 | W3: =U3+V3 -> 103 | X3: =W3 -> 103 | Y3: =W3/X3 -> 1 | AF3: 12 | AG3: =COUNTIFS(Roster!N:N,"FC Associate III",Roster!G:G,"DAD1",Roster!P:P,"Support") -> 0 | AH3: =COUNTIFS(Roster!E:E,"Regular",Roster!G:G,"DAD1",Roster!P:P,"Support") -> 0 | AI3: =COUNTIFS(Roster!E:E,"Temporary",Roster!G:G,"DAD1",Roster!P:P,"Support") -> 12 | AJ3: =AH3+AI3 -> 12 | AK3: =AJ3 -> 12 | AL3: =AJ3/AK3 -> 1
A4: =Roster!B1 -> 46267 | S4: =Roster!B1 -> 46267 | AF4: =Roster!B1 -> 46267
A5: Shift | B5: Total HC | C5: Unscheduled | D5: Schedule to Work | E5: PL | F5: OT | G5: UPL | H5: Present | I5: Present % (without OT) | J5: LM Target | K5: Target Achievement | S5: Shift | T5: Total HC | U5: Unscheduled | V5: Schedule to Work | W5: PL | X5: OT | Y5: UPL | Z5: Present | AA5: Present % | AB5: LM Target | AC5: Target Achievement | AF5: Shift | AG5: Total HC | AH5: Unscheduled | AI5: Schedule to Work | AJ5: PL | AK5: UPL | AL5: OT | AM5: Present | AN5: Present % | AO5: LM Target | AP5: Target Achievement
A6: Day Shift | B6: =COUNTIFS(Roster!G:G,"AUH1",Roster!P:P,"Direct",Roster!J:J,"Day Shift") -> 641 | C6: =SUMIFS($D$12:$D$27,$B$12:$B$27,"Day Shift") -> 140 | D6: =SUMIFS($K$12:$K$27,$B$12:$B$27,"Day Shift") -> 463 | E6: =SUMIFS($E$12:$E$27,$B$12:$B$27,"Day Shift") -> 48 | F6: =COUNTIFS(Table1[[#All],[Building]],"AUH1",Table1[[#All],[Shift]],"Day Shift",Table1[[#All],[OFF1]],"OT",Table1[[#All],[Type]],"Direct")+COUNTIFS(Table1[[#All],[Building]],"AUH1",Table1[[#All],[Shift]],"Day Shift",Table1[[#All],[OFF2]],"OT",Table1[[#All],[Type]],"Direct") -> 38 | G6: =SUMIFS($H$12:$H$26,$B$12:$B$26,"Day Shift")+SUMIFS($I$12:$I$26,$B$12:$B$26,"Day Shift") -> 33 | H6: =D6-E6-G6 -> 382 | I6: =H6/D6 -> 0.825054 | J6: 0.87225806 | K6: =I6/J6 -> 0.94588291 | S6: Day Shift | T6: =COUNTIFS(Roster!G:G,"AUH3",Roster!P:P,"Direct",Roster!J:J,"Day Shift")+COUNTIFS(Roster!G:G,"DDB1",Roster!P:P,"Direct",Roster!J:J,"Day Shift") -> 46 | U6: =SUMIFS($V$12:$V$14,$T$12:$T$14,"Day Shift") -> 12 | V6: =SUMIFS($AC$12:$AC$14,$T$12:$T$14,"Day Shift") -> 32 | W6: =SUMIFS($W$12:$W$14,$T$12:$T$14,"Day Shift") -> 3 | X6: =COUNTIFS(Table1[[#All],[Building]],"AUH3",Table1[[#All],[Shift]],"Day Shift",Table1[[#All],[OFF1]],"OT",Table1[[#All],[Type]],"Direct")+COUNTIFS(Table1[[#All],[Building]],"AUH3",Table1[[#All],[Shift]],"Day Shift",Table1[[#All],[OFF2]],"OT",Table1[[#All],[Type]],"Direct") -> 2 | Y6: =SUMIFS($Z$12:$Z$14,$T$12:$T$14,"Day Shift")+SUMIFS($AA$12:$AA$14,$T$12:$T$14,"Day Shift") -> 3 | Z6: =V6-W6-Y6 -> 26 | AA6: =Z6/V6 -> 0.8125 | AB6: 0.89857143 | AC6: =AA6/AB6 -> 0.90421304 | AF6: Day Shift | AG6: =COUNTIFS(Roster!G:G,"DAD1",Roster!P:P,"Support",Roster!J:J,"Day Shift") -> 0 | AH6: =SUMIFS($AI$12:$AI$15,$AG$12:$AG$15,"Day Shift") -> 0 | AI6: =SUMIFS($AP$12:$AP$15,$AG$12:$AG$15,"Day Shift") -> 0 | AJ6: =SUMIFS($AJ$12:$AJ$15,$AG$12:$AG$15,"Day Shift") -> 0 | AK6: =SUMIFS($AM$12:$AM$15,$AG$12:$AG$15,"Day Shift")+SUMIFS($AN$12:$AN$15,$AG$12:$AG$15,"Day Shift") -> 0 | AL6: =COUNTIFS(Table1[[#All],[Building]],"DAD1",Table1[[#All],[Shift]],"Day Shift",Table1[[#All],[OFF1]],"OT",Table1[[#All],[Type]],"Direct")+COUNTIFS(Table1[[#All],[Building]],"DAD1",Table1[[#All],[Shift]],"Day Shift",Table1[[#All],[OFF2]],"OT",Table1[[#All],[Type]],"Support") -> 0 | AM6: =AI6-AJ6-AK6 -> 0 | AN6: =AM6/AI6 -> #DIV/0! | AO6: 0.9512 | AP6: =AN6/AO6 -> #DIV/0!
A7: Mid Shift | B7: =COUNTIFS(Roster!G:G,"AUH1",Roster!P:P,"Direct",Roster!J:J,"Mid Shift") -> 0 | C7: =SUMIFS($D$12:$D$27,$B$12:$B$27,"Mid Shift") -> 0 | D7: =SUMIFS($K$12:$K$27,$B$12:$B$27,"Mid Shift") -> 0 | E7: =SUMIFS($E$12:$E$27,$B$12:$B$27,"Mid Shift") -> 0 | F7: =COUNTIFS(Table1[[#All],[Building]],"AUH1",Table1[[#All],[Shift]],"Mid Shift",Table1[[#All],[OFF1]],"OT",Table1[[#All],[Type]],"Direct")+COUNTIFS(Table1[[#All],[Building]],"AUH1",Table1[[#All],[Shift]],"Mid Shift",Table1[[#All],[OFF2]],"OT",Table1[[#All],[Type]],"Direct") -> 0 | G7: =SUMIFS($H$12:$H$27,$B$12:$B$27,"Mid Shift")+SUMIFS($I$12:$I$27,$B$12:$B$27,"Mid Shift") -> 0 | H7: =D7-E7-G7 -> 0 | I7: =H7/D7 -> #DIV/0! | J7: 0 | K7: =I7/J7 -> #DIV/0! | S7: Mid Shift | T7: =COUNTIFS(Roster!G:G,"AUH3",Roster!P:P,"Direct",Roster!J:J,"Mid Shift")+COUNTIFS(Roster!G:G,"DDB1",Roster!P:P,"Direct",Roster!J:J,"Mid Shift") -> 0 | U7: =SUMIFS($V$12:$V$14,$T$12:$T$14,"Mid Shift") -> 0 | V7: =SUMIFS($AC$12:$AC$14,$T$12:$T$14,"Mid Shift") -> 0 | W7: =SUMIFS($W$12:$W$14,$T$12:$T$14,"Mid Shift") -> 0 | X7: =COUNTIFS(Table1[[#All],[Building]],"AUH3",Table1[[#All],[Shift]],"Mid Shift",Table1[[#All],[OFF1]],"OT",Table1[[#All],[Type]],"Direct")+COUNTIFS(Table1[[#All],[Building]],"AUH3",Table1[[#All],[Shift]],"Mid Shift",Table1[[#All],[OFF2]],"OT",Table1[[#All],[Type]],"Direct") -> 0 | Y7: =SUMIFS($Z$12:$Z$14,$T$12:$T$14,"Mid Shift")+SUMIFS($AA$12:$AA$14,$T$12:$T$14,"Mid Shift") -> 0 | Z7: =V7-W7-Y7 -> 0 | AA7: =Z7/V7 -> #DIV/0! | AB7: 0 | AC7: =AA7/AB7 -> #DIV/0! | AF7: Mid Shift | AG7: =COUNTIFS(Roster!G:G,"DAD1",Roster!P:P,"Support",Roster!J:J,"Mid Shift") -> 0 | AH7: =SUMIFS($AI$12:$AI$15,$AG$12:$AG$15,"Mid Shift") -> 0 | AI7: =SUMIFS($AP$12:$AP$15,$AF$12:$AF$15,"Mid Shift") -> 0 | AJ7: =SUMIFS($AJ$12:$AJ$15,$AG$12:$AG$15,"Mid Shift") -> 0 | AK7: =SUMIFS($AM$12:$AM$15,$AG$12:$AG$15,"Mid Shift")+SUMIFS($AN$12:$AN$15,$AG$12:$AG$15,"Mid Shift") -> 0 | AL7: =COUNTIFS(Table1[[#All],[Building]],"DAD1",Table1[[#All],[Shift]],"Mid Shift",Table1[[#All],[OFF1]],"OT",Table1[[#All],[Type]],"Direct")+COUNTIFS(Table1[[#All],[Building]],"DAD1",Table1[[#All],[Shift]],"Mid Shift",Table1[[#All],[OFF2]],"OT",Table1[[#All],[Type]],"Direct") -> 0 | AM7: =AI7-AJ7-AK7 -> 0 | AN7: =AM7/AI7 -> #DIV/0! | AO7: 0.9565 | AP7: =AN7/AO7 -> #DIV/0!
A8: Night Shift | B8: =COUNTIFS(Roster!G:G,"AUH1",Roster!P:P,"Direct",Roster!J:J,"Night Shift") -> 556 | C8: =SUMIFS($D$12:$D$27,$B$12:$B$27,"Night Shift") -> 138 | D8: =SUMIFS($K$12:$K$27,$B$12:$B$27,"Night Shift") -> 398 | E8: =SUMIFS($E$12:$E$27,$B$12:$B$27,"Night Shift") -> 24 | F8: =COUNTIFS(Table1[[#All],[Building]],"AUH1",Table1[[#All],[Shift]],"Night Shift",Table1[[#All],[OFF1]],"OT",Table1[[#All],[Type]],"Direct")+COUNTIFS(Table1[[#All],[Building]],"AUH1",Table1[[#All],[Shift]],"Night Shift",Table1[[#All],[OFF2]],"OT",Table1[[#All],[Type]],"Direct") -> 20 | G8: =SUMIFS($H$12:$H$27,$B$12:$B$27,"Night Shift")+SUMIFS($I$12:$I$27,$B$12:$B$27,"Night Shift") -> 30 | H8: =D8-E8-G8 -> 344 | I8: =H8/D8 -> 0.86432161 | J8: 0.90957831 | K8: =I8/J8 -> 0.9502443 | S8: Night Shift | T8: =COUNTIFS(Roster!G:G,"AUH3",Roster!P:P,"Direct",Roster!J:J,"Night Shift")+COUNTIFS(Roster!G:G,"DDB1",Roster!P:P,"Direct",Roster!J:J,"Night Shift") -> 57 | U8: =SUMIFS($V$12:$V$14,$T$12:$T$14,"Night Shift") -> 15 | V8: =SUMIFS($AC$12:$AC$14,$T$12:$T$14,"Night Shift") -> 39 | W8: =SUMIFS($W$12:$W$14,$T$12:$T$14,"Night Shift") -> 4 | X8: =COUNTIFS(Table1[[#All],[Building]],"AUH3",Table1[[#All],[Shift]],"Night Shift",Table1[[#All],[OFF1]],"OT",Table1[[#All],[Type]],"Direct")+COUNTIFS(Table1[[#All],[Building]],"AUH3",Table1[[#All],[Shift]],"Night Shift",Table1[[#All],[OFF2]],"OT",Table1[[#All],[Type]],"Direct") -> 3 | Y8: =SUMIFS($Z$12:$Z$14,$T$12:$T$14,"Night Shift")+SUMIFS($AA$12:$AA$14,$T$12:$T$14,"Night Shift") -> 0 | Z8: =V8-W8-Y8 -> 35 | AA8: =Z8/V8 -> 0.8974359 | AB8: 0.92744681 | AC8: =AA8/AB8 -> 0.96764137 | AF8: Night Shift | AG8: =COUNTIFS(Roster!G:G,"DAD1",Roster!P:P,"Support",Roster!J:J,"Night Shift") -> 12 | AH8: =SUMIFS($AI$12:$AI$15,$AG$12:$AG$15,"Night Shift") -> 4 | AI8: =SUMIFS($AP$12:$AP$15,$AG$12:$AG$15,"Night Shift") -> 8 | AJ8: =SUMIFS($AJ$12:$AJ$15,$AG$12:$AG$15,"Night Shift") -> 0 | AK8: =SUMIFS($AM$12:$AM$15,$AG$12:$AG$15,"Night Shift")+SUMIFS($AN$12:$AN$15,$AG$12:$AG$15,"Night Shift") -> 0 | AL8: =COUNTIFS(Table1[[#All],[Building]],"DAD1",Table1[[#All],[Shift]],"Night Shift",Table1[[#All],[OFF1]],"OT",Table1[[#All],[Type]],"Support")+COUNTIFS(Table1[[#All],[Building]],"DAD1",Table1[[#All],[Shift]],"Night Shift",Table1[[#All],[OFF1]],"OT",Table1[[#All],[Type]],"Support") -> 0 | AM8: =AI8-AJ8-AK8 -> 8 | AN8: =AM8/AI8 -> 1 | AO8: 0.9568 | AP8: =AN8/AO8 -> 1.0451505
A9: Grand Total | B9: =SUM(B6:B8) -> 1197 | C9: =SUM(C6:C8) -> 278 | D9: =SUM(D6:D8) -> 861 | E9: =SUM(E6:E8) -> 72 | F9: =SUM(F6:F8) -> 58 | G9: =SUM(G6:G8) -> 63 | H9: =SUM(H6:H8) -> 726 | I9: =H9/D9 -> 0.84320557 | J9: 0.88925906 | K9: =I9/J9 -> 0.9482114 | S9: Grand Total | T9: =SUM(T6:T8) -> 103 | U9: =SUM(U6:U8) -> 27 | V9: =SUM(V6:V8) -> 71 | W9: =SUM(W6:W8) -> 7 | X9: =SUM(X6:X8) -> 5 | Y9: =SUM(Y6:Y8) -> 3 | Z9: =SUM(Z6:Z8) -> 61 | AA9: =Z9/V9 -> 0.85915493 | AB9: 0.91666667 | AC9: =AA9/AB9 -> 0.93725992 | AF9: Grand Total | AG9: =SUM(AG6:AG8) -> 12 | AH9: =SUM(AH6:AH8) -> 4 | AI9: =SUM(AI6:AI8) -> 8 | AJ9: =SUM(AJ6:AJ8) -> 0 | AK9: =SUM(AK6:AK8) -> 0 | AL9: =SUM(AL6:AL8) -> 0 | AM9: =SUM(AM6:AM8) -> 8 | AN9: =AM9/AI9 -> 1 | AO9: =AVERAGE(AO6,AO7,AO8) -> 0.95483333 | AP9: =AN9/AO9 -> 1.0473032
A11: Department | B11: Shift | C11: 0 | D11: OFF | E11: PL | F11: OT | G11: Present(Including OT) | H11: SL | I11: AB/ABWI | J11: Grand Total | K11: Scheduled | L11: Target | M11: Actual (without OT) | N11: Actual (with OT) | O11: HC As per Target % | P11: Actual HC Achived Without OT | Q11: Delta | S11: Department | T11: Shift | U11: 0 | V11: OFF | W11: PL | X11: OT | Y11: Present | Z11: SL | AA11: AB/ABWI | AB11: Grand Total | AC11: Scheduled | AD11: % | AF11: Department | AG11: Shift | AH11: 0 | AI11: OFF | AJ11: PL | AK11: Present | AL11: OT | AM11: SL | AN11: AB/ABWI | AO11: Grand Total | AP11: Scheduled | AQ11: %
A12: ICQA | B12: Day Shift | C12: =COUNTIFS(Roster!T:T,"0",Roster!O:O,"ICQA",Roster!J:J,"Day Shift",Roster!P:P,"Direct",Roster!G:G,"AUH1") -> 0 | D12: =COUNTIFS(Roster!T:T,"OFF",Roster!O:O,"ICQA",Roster!J:J,"Day Shift",Roster!P:P,"Direct",Roster!G:G,"AUH1") -> 11 | E12: =COUNTIFS(Roster!T:T,"PL",Roster!O:O,"ICQA",Roster!J:J,"Day Shift",Roster!P:P,"Direct",Roster!G:G,"AUH1") -> 3 | F12: =COUNTIFS(Table1[[#All],[Building]],"AUH1",Table1[[#All],[Shift]],"Day Shift",Table1[[#All],[OFF1]],"OT",Table1[[#All],[Department]],Dashboard!A12)+COUNTIFS(Table1[[#All],[Building]],"AUH1",Table1[[#All],[Shift]],"Day Shift",Table1[[#All],[OFF2]],"OT",Table1[[#All],[Department]],Dashboard!A12) -> 0 | G12: =COUNTIFS(Roster!T:T,"P",Roster!O:O,"ICQA",Roster!J:J,"Day Shift",Roster!P:P,"Direct",Roster!G:G,"AUH1") -> 27 | H12: =COUNTIFS(Roster!T:T,"SL",Roster!O:O,"ICQA",Roster!J:J,"Day Shift",Roster!P:P,"Direct",Roster!G:G,"AUH1") -> 1 | I12: =COUNTIFS(Roster!T:T,"AB",Roster!O:O,"ICQA",Roster!J:J,"Day Shift",Roster!P:P,"Direct",Roster!G:G,"AUH1")+COUNTIFS(Roster!T:T,"ABWI",Roster!O:O,"ICQA",Roster!J:J,"Day Shift",Roster!P:P,"Direct",Roster!G:G,"AUH1") -> 2 | J12: =SUM(G12:I12,)+SUM(C12:E12) -> 44 | K12: =(J12-D12)-C12-F12 -> 33 | L12: 0.86822581 | M12: =(G12-F12)/(K12) -> 0.81818182 | N12: =G12/K12 -> 0.81818182 | S12: Warehouse Deals | T12: Day Shift | U12: =COUNTIFS(Roster!T:T,"0",Roster!O:O,"Warehouse Deals",Roster!J:J,"Day Shift",Roster!P:P,"Direct",Roster!G:G,"AUH3")+COUNTIFS(Roster!T:T,"0",Roster!O:O,"Warehouse Deals",Roster!J:J,"Day Shift",Roster!P:P,"Direct",Roster!G:G,"DDB1") -> 0 | V12: =COUNTIFS(Roster!T:T,"OFF",Roster!O:O,"Warehouse Deals",Roster!J:J,"Day Shift",Roster!P:P,"Direct",Roster!G:G,"AUH3")+COUNTIFS(Roster!T:T,"OFF",Roster!O:O,"Warehouse Deals",Roster!J:J,"Day Shift",Roster!P:P,"Direct",Roster!G:G,"DDB1") -> 12 | W12: =COUNTIFS(Roster!T:T,"PL",Roster!O:O,"Warehouse Deals",Roster!J:J,"Day Shift",Roster!P:P,"Direct",Roster!G:G,"AUH3")+COUNTIFS(Roster!T:T,"PL",Roster!O:O,"Warehouse Deals",Roster!J:J,"Day Shift",Roster!P:P,"Direct",Roster!G:G,"DDB1") -> 3 | X12: =COUNTIFS(Table1[[#All],[Building]],"AUH3",Table1[[#All],[Shift]],"Day Shift",Table1[[#All],[OFF1]],"OT",Table1[[#All],[Department]],Dashboard!S12)+COUNTIFS(Table1[[#All],[Building]],"AUH3",Table1[[#All],[Shift]],"Day Shift",Table1[[#All],[OFF2]],"OT",Table1[[#All],[Department]],Dashboard!S12) -> 2 | Y12: =COUNTIFS(Roster!T:T,"P",Roster!O:O,"Warehouse Deals",Roster!J:J,"Day Shift",Roster!P:P,"Direct",Roster!G:G,"AUH3")+COUNTIFS(Roster!T:T,"P",Roster!O:O,"Warehouse Deals",Roster!J:J,"Day Shift",Roster!P:P,"Direct",Roster!G:G,"DDB1") -> 28 | Z12: =COUNTIFS(Roster!T:T,"SL",Roster!O:O,"Warehouse Deals",Roster!J:J,"Day Shift",Roster!P:P,"Direct",Roster!G:G,"AUH3")+COUNTIFS(Roster!T:T,"SL",Roster!O:O,"Warehouse Deals",Roster!J:J,"Day Shift",Roster!P:P,"Direct",Roster!G:G,"DDB1") -> 0 | AA12: =COUNTIFS(Roster!T:T,"AB",Roster!O:O,"Warehouse Deals",Roster!J:J,"Day Shift",Roster!P:P,"Direct",Roster!G:G,"AUH3")+COUNTIFS(Roster!T:T,"AB",Roster!O:O,"Warehouse Deals",Roster!J:J,"Day Shift",Roster!P:P,"Direct",Roster!G:G,"DDB1")+COUNTIFS(Roster!T:T,"ABWI",Roster!O:O,"Warehouse Deals",Roster!J:J,"Day Shift",Roster!P:P,"Direct",Roster!G:G,"AUH3")+COUNTIFS(Roster!T:T,"ABWI",Roster!O:O,"Warehouse Deals",Roster!J:J,"Day Shift",Roster!P:P,"Direct",Roster!G:G,"DDB1") -> 3 | AB12: =SUM(Y12:AA12,)+SUM(U12:W12) -> 46 | AC12: =(AB12-V12)-U12-X12 -> 32 | AD12: =Y12/AC12 -> 0.875 | AF12: Warehouse Deals | AG12: Day Shift | AH12: =COUNTIFS(Roster!T:T,"0",Roster!O:O,"Warehouse Deals",Roster!J:J,"Day Shift",Roster!P:P,"Support",Roster!G:G,"DAD1") -> 0 | AI12: =COUNTIFS(Roster!T:T,"OFF",Roster!O:O,"Warehouse Deals",Roster!J:J,"Day Shift",Roster!P:P,"Support",Roster!G:G,"DAD1") -> 0 | AJ12: =COUNTIFS(Roster!T:T,"PL",Roster!O:O,"Warehouse Deals",Roster!J:J,"Day Shift",Roster!P:P,"Support",Roster!G:G,"DAD1") -> 0 | AK12: =COUNTIFS(Roster!T:T,"P",Roster!O:O,"Warehouse Deals",Roster!J:J,"Day Shift",Roster!P:P,"Support",Roster!G:G,"DAD1") -> 0 | AL12: =COUNTIFS(Table1[[#All],[Building]],"DAD1",Table1[[#All],[Shift]],"Day Shift",Table1[[#All],[OFF1]],"OT",Table1[[#All],[Type]],"Support")+COUNTIFS(Table1[[#All],[Building]],"DAD1",Table1[[#All],[Shift]],"Day Shift",Table1[[#All],[OFF2]],"OT",Table1[[#All],[Type]],"Support") -> 0 | AM12: =COUNTIFS(Roster!T:T,"SL",Roster!O:O,"Warehouse Deals",Roster!J:J,"Day Shift",Roster!P:P,"Support",Roster!G:G,"DAD1") -> 0 | AN12: =COUNTIFS(Roster!T:T,"AB",Roster!O:O,"Warehouse Deals",Roster!J:J,"Day Shift",Roster!P:P,"Support",Roster!G:G,"DAD1")+COUNTIFS(Roster!T:T,"ABWI",Roster!O:O,"Warehouse Deals",Roster!J:J,"Day Shift",Roster!P:P,"Support",Roster!G:G,"DAD1") -> 0 | AO12: =SUM(AM12:AN12,)+SUM(AH12:AK12) -> 0 | AP12: =(AO12-AI12)-AH12 -> 0 | AQ12: =AK12/AP12 -> #DIV/0!
B13: Mid Shift | C13: 0 | D13: =COUNTIFS(Roster!T:T,"OFF",Roster!O:O,"ICQA",Roster!J:J,"Mid Shift",Roster!P:P,"Direct",Roster!G:G,"AUH1") -> 0 | E13: =COUNTIFS(Roster!T:T,"PL",Roster!O:O,"ICQA",Roster!J:J,"Mid Shift",Roster!P:P,"Direct",Roster!G:G,"AUH1") -> 0 | F13: =COUNTIFS(Table1[[#All],[Building]],"AUH1",Table1[[#All],[Shift]],"Mid Shift",Table1[[#All],[OFF1]],"OT",Table1[[#All],[Department]],Dashboard!A12)+COUNTIFS(Table1[[#All],[Building]],"AUH1",Table1[[#All],[Shift]],"Mid Shift",Table1[[#All],[OFF2]],"OT",Table1[[#All],[Department]],Dashboard!A12) -> 0 | G13: =COUNTIFS(Roster!T:T,"P",Roster!O:O,"ICQA",Roster!J:J,"Mid Shift",Roster!P:P,"Direct",Roster!G:G,"AUH1") -> 0 | H13: =COUNTIFS(Roster!T:T,"SL",Roster!O:O,"ICQA",Roster!J:J,"Mid Shift",Roster!P:P,"Direct",Roster!G:G,"AUH1") -> 0 | I13: =COUNTIFS(Roster!T:T,"AB",Roster!O:O,"ICQA",Roster!J:J,"Mid Shift",Roster!P:P,"Direct",Roster!G:G,"AUH1")+COUNTIFS(Roster!T:T,"ABWI",Roster!O:O,"ICQA",Roster!J:J,"Mid Shift",Roster!P:P,"Direct",Roster!G:G,"AUH1") -> 0 | J13: =SUM(G13:I13,)+SUM(C13:E13) -> 0 | K13: =(J13-D13)-C13-F13 -> 0 | M13: =(G13-F13)/(K13) -> #DIV/0! | N13: =(H13-G13)/(L13) -> #DIV/0! | T13: Mid Shift | U13: =COUNTIFS(Roster!T:T,"0",Roster!O:O,"Warehouse Deals",Roster!J:J,"Mid Shift",Roster!P:P,"Direct",Roster!G:G,"AUH3")+COUNTIFS(Roster!T:T,"0",Roster!O:O,"Warehouse Deals",Roster!J:J,"Mid Shift",Roster!P:P,"Direct",Roster!G:G,"DDB1") -> 0 | V13: =COUNTIFS(Roster!T:T,"OFF",Roster!O:O,"Warehouse Deals",Roster!J:J,"Mid Shift",Roster!P:P,"Direct",Roster!G:G,"AUH3")+COUNTIFS(Roster!T:T,"OFF",Roster!O:O,"Warehouse Deals",Roster!J:J,"Mid Shift",Roster!P:P,"Direct",Roster!G:G,"DDB1") -> 0 | W13: =COUNTIFS(Roster!T:T,"PL",Roster!O:O,"Warehouse Deals",Roster!J:J,"Mid Shift",Roster!P:P,"Direct",Roster!G:G,"AUH3")+COUNTIFS(Roster!T:T,"PL",Roster!O:O,"Warehouse Deals",Roster!J:J,"Mid Shift",Roster!P:P,"Direct",Roster!G:G,"DDB1") -> 0 | X13: =COUNTIFS(Table1[[#All],[Building]],"AUH3",Table1[[#All],[Shift]],"Mid Shift",Table1[[#All],[OFF1]],"OT",Table1[[#All],[Department]],Dashboard!S12)+COUNTIFS(Table1[[#All],[Building]],"AUH3",Table1[[#All],[Shift]],"Mid Shift",Table1[[#All],[OFF2]],"OT",Table1[[#All],[Department]],Dashboard!S12) -> 0 | Y13: =COUNTIFS(Roster!T:T,"P",Roster!O:O,"Warehouse Deals",Roster!J:J,"Mid Shift",Roster!P:P,"Direct",Roster!G:G,"AUH3")+COUNTIFS(Roster!T:T,"P",Roster!O:O,"Warehouse Deals",Roster!J:J,"Mid Shift",Roster!P:P,"Direct",Roster!G:G,"DDB1") -> 0 | Z13: =COUNTIFS(Roster!T:T,"SL",Roster!O:O,"Warehouse Deals",Roster!J:J,"Mid Shift",Roster!P:P,"Direct",Roster!G:G,"AUH3")+COUNTIFS(Roster!T:T,"SL",Roster!O:O,"Warehouse Deals",Roster!J:J,"Mid Shift",Roster!P:P,"Direct",Roster!G:G,"DDB1") -> 0 | AA13: =COUNTIFS(Roster!T:T,"AB",Roster!O:O,"Warehouse Deals",Roster!J:J,"Mid Shift",Roster!P:P,"Direct",Roster!G:G,"AUH3")+COUNTIFS(Roster!T:T,"AB",Roster!O:O,"Warehouse Deals",Roster!J:J,"Mid Shift",Roster!P:P,"Direct",Roster!G:G,"DDB1")+COUNTIFS(Roster!T:T,"ABWI",Roster!O:O,"Warehouse Deals",Roster!J:J,"Mid Shift",Roster!P:P,"Direct",Roster!G:G,"AUH3")+COUNTIFS(Roster!T:T,"ABWI",Roster!O:O,"Warehouse Deals",Roster!J:J,"Mid Shift",Roster!P:P,"Direct",Roster!G:G,"DDB1") -> 0 | AB13: =SUM(Y13:AA13,)+SUM(U13:W13) -> 0 | AC13: =(AB13-V13)-U13-X13 -> 0 | AD13: =Y13/AC13 -> #DIV/0! | AG13: Mid Shift | AH13: =COUNTIFS(Roster!T:T,"0",Roster!O:O,"Warehouse Deals",Roster!J:J,"Mid Shift",Roster!P:P,"Support",Roster!G:G,"DAD1") -> 0 | AI13: =COUNTIFS(Roster!T:T,"OFF",Roster!O:O,"Warehouse Deals",Roster!J:J,"Mid Shift",Roster!P:P,"Support",Roster!G:G,"DAD1") -> 0 | AJ13: =COUNTIFS(Roster!T:T,"PL",Roster!O:O,"Warehouse Deals",Roster!J:J,"Mid Shift",Roster!P:P,"Support",Roster!G:G,"DAD1") -> 0 | AK13: =COUNTIFS(Roster!T:T,"P",Roster!O:O,"Warehouse Deals",Roster!J:J,"Mid Shift",Roster!P:P,"Support",Roster!G:G,"DAD1") -> 0 | AL13: =COUNTIFS(Table1[[#All],[Building]],"DAD1",Table1[[#All],[Shift]],"Mid Shift",Table1[[#All],[OFF1]],"OT",Table1[[#All],[Type]],"Direct")+COUNTIFS(Table1[[#All],[Building]],"DAD1",Table1[[#All],[Shift]],"Mid Shift",Table1[[#All],[OFF2]],"OT",Table1[[#All],[Type]],"Direct") -> 0 | AM13: =COUNTIFS(Roster!T:T,"SL",Roster!O:O,"Warehouse Deals",Roster!J:J,"Mid Shift",Roster!P:P,"Support",Roster!G:G,"DAD1") -> 0 | AN13: =COUNTIFS(Roster!T:T,"AB",Roster!O:O,"Warehouse Deals",Roster!J:J,"Mid Shift",Roster!P:P,"Support",Roster!G:G,"DAD1")+COUNTIFS(Roster!T:T,"ABWI",Roster!O:O,"Warehouse Deals",Roster!J:J,"Mid Shift",Roster!P:P,"Support",Roster!G:G,"DAD1") -> 0 | AO13: =SUM(AM13:AN13,)+SUM(AH13:AK13) -> 0 | AP13: =(AO13-AI13)-AH13 -> 0 | AQ13: =AK13/AP13 -> #DIV/0!
B14: Night Shift | C14: =COUNTIFS(Roster!T:T,"0",Roster!O:O,"ICQA",Roster!J:J,"Night Shift",Roster!P:P,"Direct",Roster!G:G,"AUH1") -> 0 | D14: =COUNTIFS(Roster!T:T,"OFF",Roster!O:O,"ICQA",Roster!J:J,"Night Shift",Roster!P:P,"Direct",Roster!G:G,"AUH1") -> 2 | E14: =COUNTIFS(Roster!T:T,"PL",Roster!O:O,"ICQA",Roster!J:J,"Night Shift",Roster!P:P,"Direct",Roster!G:G,"AUH1") -> 0 | F14: =COUNTIFS(Table1[[#All],[Building]],"AUH1",Table1[[#All],[Shift]],"Night Shift",Table1[[#All],[OFF1]],"OT",Table1[[#All],[Department]],Dashboard!A12)+COUNTIFS(Table1[[#All],[Building]],"AUH1",Table1[[#All],[Shift]],"Night Shift",Table1[[#All],[OFF2]],"OT",Table1[[#All],[Department]],Dashboard!A12) -> 0 | G14: =COUNTIFS(Roster!T:T,"P",Roster!O:O,"ICQA",Roster!J:J,"Night Shift",Roster!P:P,"Direct",Roster!G:G,"AUH1") -> 5 | H14: =COUNTIFS(Roster!T:T,"SL",Roster!O:O,"ICQA",Roster!J:J,"Night Shift",Roster!P:P,"Direct",Roster!G:G,"AUH1") -> 0 | I14: =COUNTIFS(Roster!T:T,"AB",Roster!O:O,"ICQA",Roster!J:J,"Night Shift",Roster!P:P,"Direct",Roster!G:G,"AUH1")+COUNTIFS(Roster!T:T,"ABWI",Roster!O:O,"ICQA",Roster!J:J,"Night Shift",Roster!P:P,"Direct",Roster!G:G,"AUH1") -> 0 | J14: =SUM(G14:I14,)+SUM(C14:E14) -> 7 | K14: =(J14-D14)-C14-F14 -> 5 | L14: 0.765 | M14: =(G14-F14)/(K14) -> 1 | N14: =G14/K14 -> 1 | T14: Night Shift | U14: =COUNTIFS(Roster!T:T,"0",Roster!O:O,"Warehouse Deals",Roster!J:J,"Mid Shift",Roster!P:P,"Direct",Roster!G:G,"AUH3")+COUNTIFS(Roster!T:T,"0",Roster!O:O,"Warehouse Deals",Roster!J:J,"Mid Shift",Roster!P:P,"Direct",Roster!G:G,"DDB1") -> 0 | V14: =COUNTIFS(Roster!T:T,"OFF",Roster!O:O,"Warehouse Deals",Roster!J:J,"Night Shift",Roster!P:P,"Direct",Roster!G:G,"AUH3")+COUNTIFS(Roster!T:T,"OFF",Roster!O:O,"Warehouse Deals",Roster!J:J,"Night Shift",Roster!P:P,"Direct",Roster!G:G,"DDB1") -> 15 | W14: =COUNTIFS(Roster!T:T,"PL",Roster!O:O,"Warehouse Deals",Roster!J:J,"Night Shift",Roster!P:P,"Direct",Roster!G:G,"AUH3")+COUNTIFS(Roster!T:T,"PL",Roster!O:O,"Warehouse Deals",Roster!J:J,"Night Shift",Roster!P:P,"Direct",Roster!G:G,"DDB1") -> 4 | X14: =COUNTIFS(Table1[[#All],[Building]],"AUH3",Table1[[#All],[Shift]],"Night Shift",Table1[[#All],[OFF1]],"OT",Table1[[#All],[Department]],Dashboard!S12)+COUNTIFS(Table1[[#All],[Building]],"AUH3",Table1[[#All],[Shift]],"Night Shift",Table1[[#All],[OFF2]],"OT",Table1[[#All],[Department]],Dashboard!S12) -> 3 | Y14: =COUNTIFS(Roster!T:T,"P",Roster!O:O,"Warehouse Deals",Roster!J:J,"Night Shift",Roster!P:P,"Direct",Roster!G:G,"AUH3")+COUNTIFS(Roster!T:T,"P",Roster!O:O,"Warehouse Deals",Roster!J:J,"Night Shift",Roster!P:P,"Direct",Roster!G:G,"DDB1") -> 38 | Z14: =COUNTIFS(Roster!T:T,"SL",Roster!O:O,"Warehouse Deals",Roster!J:J,"Night Shift",Roster!P:P,"Direct",Roster!G:G,"AUH3")+COUNTIFS(Roster!T:T,"SL",Roster!O:O,"Warehouse Deals",Roster!J:J,"Night Shift",Roster!P:P,"Direct",Roster!G:G,"DDB1") -> 0 | AA14: =COUNTIFS(Roster!T:T,"AB",Roster!O:O,"Warehouse Deals",Roster!J:J,"Night Shift",Roster!P:P,"Direct",Roster!G:G,"AUH3")+COUNTIFS(Roster!T:T,"AB",Roster!O:O,"Warehouse Deals",Roster!J:J,"Night Shift",Roster!P:P,"Direct",Roster!G:G,"DDB1")+COUNTIFS(Roster!T:T,"ABWI",Roster!O:O,"Warehouse Deals",Roster!J:J,"Night Shift",Roster!P:P,"Direct",Roster!G:G,"AUH3")+COUNTIFS(Roster!T:T,"ABWI",Roster!O:O,"Warehouse Deals",Roster!J:J,"Night Shift",Roster!P:P,"Direct",Roster!G:G,"DDB1") -> 0 | AB14: =SUM(Y14:AA14,)+SUM(U14:W14) -> 57 | AC14: =(AB14-V14)-U14-X14 -> 39 | AD14: =Y14/AC14 -> 0.97435897 | AG14: Night Shift | AH14: =COUNTIFS(Roster!T:T,"0",Roster!O:O,"Warehouse Deals",Roster!J:J,"Night Shift",Roster!P:P,"Support",Roster!G:G,"DAD1") -> 0 | AI14: =COUNTIFS(Roster!T:T,"OFF",Roster!O:O,"Warehouse Deals",Roster!J:J,"Night Shift",Roster!P:P,"Support",Roster!G:G,"DAD1") -> 4 | AJ14: =COUNTIFS(Roster!T:T,"PL",Roster!O:O,"Warehouse Deals",Roster!J:J,"Night Shift",Roster!P:P,"Support",Roster!G:G,"DAD1") -> 0 | AK14: =COUNTIFS(Roster!T:T,"P",Roster!O:O,"Warehouse Deals",Roster!J:J,"Night Shift",Roster!P:P,"Support",Roster!G:G,"DAD1") -> 8 | AL14: =COUNTIFS(Table1[[#All],[Building]],"DAD1",Table1[[#All],[Shift]],"Night Shift",Table1[[#All],[OFF1]],"OT",Table1[[#All],[Type]],"Support")+COUNTIFS(Table1[[#All],[Building]],"DAD1",Table1[[#All],[Shift]],"Night Shift",Table1[[#All],[OFF1]],"OT",Table1[[#All],[Type]],"Support") -> 0 | AM14: =COUNTIFS(Roster!T:T,"SL",Roster!O:O,"Warehouse Deals",Roster!J:J,"Night Shift",Roster!P:P,"Support",Roster!G:G,"DAD1") -> 0 | AN14: =COUNTIFS(Roster!T:T,"AB",Roster!O:O,"Warehouse Deals",Roster!J:J,"Night Shift",Roster!P:P,"Support",Roster!G:G,"DAD1")+COUNTIFS(Roster!T:T,"ABWI",Roster!O:O,"Warehouse Deals",Roster!J:J,"Night Shift",Roster!P:P,"Support",Roster!G:G,"DAD1") -> 0 | AO14: =SUM(AM14:AN14,)+SUM(AH14:AK14) -> 12 | AP14: =(AO14-AI14)-AH14 -> 8 | AQ14: =AK14/AP14 -> 1
A15: ICQA Total | C15: =SUM(C12:C14) -> 0 | D15: =SUM(D12:D14) -> 13 | E15: =SUM(E12:E14) -> 3 | F15: =SUM(F12:F14) -> 0 | G15: =SUM(G12:G14) -> 32 | H15: =SUM(H12:H14) -> 1 | I15: =SUM(I12:I14) -> 2 | J15: =SUM(J12:J14) -> 51 | K15: =SUM(K12:K14) -> 38 | L15: 0.85388889 | M15: =(G15-F15)/(K15) -> 0.84210526 | N15: =G15/K15 -> 0.84210526 | O15: =L15*K15 -> 32.447778 | P15: =G15-F15 -> 32 | Q15: =P15-O15 -> -0.44777778 | S15: SC Total | U15: =SUM(U12:U14) -> 0 | V15: =SUM(V12:V14) -> 27 | W15: =SUM(W12:W14) -> 7 | X15: =SUM(X12:X14) -> 5 | Y15: =SUM(Y12:Y14) -> 66 | Z15: =SUM(Z12:Z14) -> 0 | AA15: =SUM(AA12:AA14) -> 3 | AB15: =SUM(AB12:AB14) -> 103 | AC15: =SUM(AC12:AC14) -> 71 | AF15: Warehouse Deals | AH15: =SUM(AH12:AH14) -> 0 | AI15: =SUM(AI12:AI14) -> 4 | AJ15: =SUM(AJ12:AJ14) -> 0 | AK15: =SUM(AK12:AK14) -> 8 | AL15: =SUM(AL12:AL14) -> 0 | AM15: =SUM(AM12:AM14) -> 0 | AN15: =SUM(AN12:AN14) -> 0 | AO15: =SUM(AO12:AO14) -> 12 | AP15: =SUM(AP12:AP14) -> 8
A16: Inbound | B16: Day Shift | C16: =COUNTIFS(Roster!T:T,"0",Roster!O:O,"Inbound",Roster!J:J,"Day Shift",Roster!P:P,"Direct",Roster!G:G,"AUH1") -> 0 | D16: =COUNTIFS(Roster!T:T,"OFF",Roster!O:O,"Inbound",Roster!J:J,"Day Shift",Roster!P:P,"Direct",Roster!G:G,"AUH1") -> 51 | E16: =COUNTIFS(Roster!T:T,"PL",Roster!O:O,"Inbound",Roster!J:J,"Day Shift",Roster!P:P,"Direct",Roster!G:G,"AUH1") -> 17 | F16: =COUNTIFS(Table1[[#All],[Building]],"AUH1",Table1[[#All],[Shift]],"Day Shift",Table1[[#All],[OFF1]],"OT",Table1[[#All],[Department]],Dashboard!A16)+COUNTIFS(Table1[[#All],[Building]],"AUH1",Table1[[#All],[Shift]],"Day Shift",Table1[[#All],[OFF2]],"OT",Table1[[#All],[Department]],Dashboard!A16) -> 8 | G16: =COUNTIFS(Roster!T:T,"P",Roster!O:O,"Inbound",Roster!J:J,"Day Shift",Roster!P:P,"Direct",Roster!G:G,"AUH1") -> 142 | H16: =COUNTIFS(Roster!T:T,"SL",Roster!O:O,"Inbound",Roster!J:J,"Day Shift",Roster!P:P,"Direct",Roster!G:G,"AUH1") -> 1 | I16: =COUNTIFS(Roster!T:T,"AB",Roster!O:O,"Inbound",Roster!J:J,"Day Shift",Roster!P:P,"Direct",Roster!G:G,"AUH1")+COUNTIFS(Roster!T:T,"ABWI",Roster!O:O,"Inbound",Roster!J:J,"Day Shift",Roster!P:P,"Direct",Roster!G:G,"AUH1") -> 9 | J16: =SUM(G16:I16,)+SUM(C16:E16) -> 220 | K16: =(J16-D16)-C16-F16 -> 161 | L16: 0.88336735 | M16: =(G16-F16)/(K16) -> 0.83229814 | N16: =G16/K16 -> 0.88198758 | AF16: Grand Total | AH16: =AH15 -> 0 | AI16: =AI15 -> 4 | AJ16: =AJ15 -> 0 | AK16: =AK15 -> 8 | AL16: =AL15 -> 0 | AM16: =AM15 -> 0 | AN16: =AN15 -> 0 | AO16: =AO15 -> 12 | AP16: =AP15 -> 8
B17: Mid Shift | C17: =COUNTIFS(Roster!T:T,"0",Roster!O:O,"Inbound",Roster!J:J,"Mid Shift",Roster!P:P,"Direct",Roster!G:G,"AUH1") -> 0 | D17: =COUNTIFS(Roster!T:T,"OFF",Roster!O:O,"Inbound",Roster!J:J,"Mid Shift",Roster!P:P,"Direct",Roster!G:G,"AUH1") -> 0 | E17: =COUNTIFS(Roster!T:T,"PL",Roster!O:O,"Inbound",Roster!J:J,"Mid Shift",Roster!P:P,"Direct",Roster!G:G,"AUH1") -> 0 | F17: =COUNTIFS(Table1[[#All],[Building]],"AUH1",Table1[[#All],[Shift]],"Mid Shift",Table1[[#All],[OFF1]],"OT",Table1[[#All],[Department]],Dashboard!A16)+COUNTIFS(Table1[[#All],[Building]],"AUH1",Table1[[#All],[Shift]],"Mid Shift",Table1[[#All],[OFF2]],"OT",Table1[[#All],[Department]],Dashboard!A16) -> 0 | G17: =COUNTIFS(Roster!T:T,"P",Roster!O:O,"Inbound",Roster!J:J,"Mid Shift",Roster!P:P,"Direct",Roster!G:G,"AUH1") -> 0 | H17: =COUNTIFS(Roster!T:T,"SL",Roster!O:O,"Inbound",Roster!J:J,"Mid Shift",Roster!P:P,"Direct",Roster!G:G,"AUH1") -> 0 | I17: =COUNTIFS(Roster!T:T,"AB",Roster!O:O,"Inbound",Roster!J:J,"Mid Shift",Roster!P:P,"Direct",Roster!G:G,"AUH1")+COUNTIFS(Roster!T:T,"ABWI",Roster!O:O,"Inbound",Roster!J:J,"Mid Shift",Roster!P:P,"Direct",Roster!G:G,"AUH1") -> 0 | J17: =SUM(G17:I17,)+SUM(C17:E17) -> 0 | K17: =(J17-D17)-C17-F17 -> 0 | L17: 0.8456 | M17: =(G17-F17)/(K17) -> #DIV/0! | N17: =G17/K17 -> #DIV/0! | S17: Department | T17: Shift | U17: 0 | V17: OFF | W17: PL | X17: OT | Y17: Present | Z17: SL | AA17: AB/ABWI | AB17: Grand Total | AC17: Scheduled | AD17: %
B18: Night Shift | C18: =COUNTIFS(Roster!T:T,"0",Roster!O:O,"Inbound",Roster!J:J,"Night Shift",Roster!P:P,"Direct",Roster!G:G,"AUH1") -> 0 | D18: =COUNTIFS(Roster!T:T,"OFF",Roster!O:O,"Inbound",Roster!J:J,"Night Shift",Roster!P:P,"Direct",Roster!G:G,"AUH1") -> 25 | E18: =COUNTIFS(Roster!T:T,"PL",Roster!O:O,"Inbound",Roster!J:J,"Night Shift",Roster!P:P,"Direct",Roster!G:G,"AUH1") -> 2 | F18: =COUNTIFS(Table1[[#All],[Building]],"AUH1",Table1[[#All],[Shift]],"Night Shift",Table1[[#All],[OFF1]],"OT",Table1[[#All],[Department]],Dashboard!A16)+COUNTIFS(Table1[[#All],[Building]],"AUH1",Table1[[#All],[Shift]],"Night Shift",Table1[[#All],[OFF2]],"OT",Table1[[#All],[Department]],Dashboard!A16) -> 3 | G18: =COUNTIFS(Roster!T:T,"P",Roster!O:O,"Inbound",Roster!J:J,"Night Shift",Roster!P:P,"Direct",Roster!G:G,"AUH1") -> 55 | H18: =COUNTIFS(Roster!T:T,"SL",Roster!O:O,"Inbound",Roster!J:J,"Night Shift",Roster!P:P,"Direct",Roster!G:G,"AUH1") -> 0 | I18: =COUNTIFS(Roster!T:T,"AB",Roster!O:O,"Inbound",Roster!J:J,"Night Shift",Roster!P:P,"Direct",Roster!G:G,"AUH1")+COUNTIFS(Roster!T:T,"ABWI",Roster!O:O,"Inbound",Roster!J:J,"Night Shift",Roster!P:P,"Direct",Roster!G:G,"AUH1") -> 4 | J18: =SUM(G18:I18,)+SUM(C18:E18) -> 86 | K18: =(J18-D18)-C18-F18 -> 58 | L18: 0.9025 | M18: =(G18-F18)/(K18) -> 0.89655172 | N18: =G18/K18 -> 0.94827586 | S18: Warehouse Deals | T18: Regular | U18: =COUNTIFS(Roster!G:G,"AUH3",Roster!P:P,"Direct",Roster!T:T,"0",Roster!E:E,"Regular")+COUNTIFS(Roster!G:G,"DDB1",Roster!P:P,"Direct",Roster!T:T,"0",Roster!E:E,"Regular") -> 0 | V18: =COUNTIFS(Roster!G:G,"AUH3",Roster!P:P,"Direct",Roster!T:T,"OFF",Roster!E:E,"Regular")+COUNTIFS(Roster!G:G,"DDB1",Roster!P:P,"Direct",Roster!T:T,"OFF",Roster!E:E,"Regular") -> 1 | W18: =COUNTIFS(Roster!G:G,"AUH3",Roster!P:P,"Direct",Roster!T:T,"PL",Roster!E:E,"Regular")+COUNTIFS(Roster!G:G,"DDB1",Roster!P:P,"Direct",Roster!T:T,"PL",Roster!E:E,"Regular") -> 1 | X18: =COUNTIFS(Table1[[#All],[Building]],"AUH3",Table1[[#All],[Employment Type]],"Regular",Table1[[#All],[OFF1]],"OT",Table1[[#All],[Department]],Dashboard!S18)+COUNTIFS(Table1[[#All],[Building]],"AUH3",Table1[[#All],[Employment Type]],"Regular",Table1[[#All],[OFF2]],"OT",Table1[[#All],[Department]],Dashboard!S18) -> 1 | Y18: =COUNTIFS(Roster!G:G,"AUH3",Roster!P:P,"Direct",Roster!T:T,"P",Roster!E:E,"Regular")+COUNTIFS(Roster!G:G,"DDB1",Roster!P:P,"Direct",Roster!T:T,"P",Roster!E:E,"Regular") -> 12 | Z18: =COUNTIFS(Roster!G:G,"AUH3",Roster!P:P,"Direct",Roster!T:T,"SL",Roster!E:E,"Regular")+COUNTIFS(Roster!G:G,"DDB1",Roster!P:P,"Direct",Roster!T:T,"SL",Roster!E:E,"Regular") -> 0 | AA18: =COUNTIFS(Roster!G:G,"AUH3",Roster!P:P,"Direct",Roster!T:T,"AB",Roster!E:E,"Regular")+COUNTIFS(Roster!G:G,"DDB1",Roster!P:P,"Direct",Roster!T:T,"AB",Roster!E:E,"Regular")+COUNTIFS(Roster!G:G,"AUH3",Roster!P:P,"Direct",Roster!T:T,"ABWI",Roster!E:E,"Regular")+COUNTIFS(Roster!G:G,"DDB1",Roster!P:P,"Direct",Roster!T:T,"ABWI",Roster!E:E,"Regular") -> 0 | AB18: =SUM(Y18:AA18,)+SUM(U18:W18) -> 14 | AC18: =(AB18-V18)-U18 -> 13 | AD18: =Y18/AC18 -> 0.92307692 | AL18: =1443+83 -> 1526
A19: Inbound Total | C19: =SUM(C16:C18) -> 0 | D19: =SUM(D16:D18) -> 76 | E19: =SUM(E16:E18) -> 19 | F19: =SUM(F16:F18) -> 11 | G19: =SUM(G16:G18) -> 197 | H19: =SUM(H16:H18) -> 1 | I19: =SUM(I16:I18) -> 13 | J19: =SUM(J16:J18) -> 306 | K19: =SUM(K16:K18) -> 219 | L19: 0.88807692 | M19: =(G19-F19)/(K19) -> 0.84931507 | N19: =G19/K19 -> 0.89954338 | O19: =L19*K19 -> 194.48885 | P19: =G19-F19 -> 186 | Q19: =P19-O19 -> -8.4888462 | T19: Temporary | U19: =COUNTIFS(Roster!G:G,"AUH3",Roster!P:P,"Direct",Roster!T:T,"0",Roster!E:E,"Temporary")+COUNTIFS(Roster!G:G,"DDB1",Roster!P:P,"Direct",Roster!T:T,"0",Roster!E:E,"Temporary") -> 0 | V19: =COUNTIFS(Roster!G:G,"AUH3",Roster!P:P,"Direct",Roster!T:T,"OFF",Roster!E:E,"Temporary")+COUNTIFS(Roster!G:G,"DDB1",Roster!P:P,"Direct",Roster!T:T,"OFF",Roster!E:E,"Temporary") -> 26 | W19: =COUNTIFS(Roster!G:G,"AUH3",Roster!P:P,"Direct",Roster!T:T,"PL",Roster!E:E,"Temporary")+COUNTIFS(Roster!G:G,"DDB1",Roster!P:P,"Direct",Roster!T:T,"PL",Roster!E:E,"Temporary") -> 6 | X19: =COUNTIFS(Table1[[#All],[Building]],"AUH3",Table1[[#All],[Employment Type]],"Temporary",Table1[[#All],[OFF1]],"OT",Table1[[#All],[Department]],Dashboard!S18)+COUNTIFS(Table1[[#All],[Building]],"AUH3",Table1[[#All],[Employment Type]],"Temporary",Table1[[#All],[OFF2]],"OT",Table1[[#All],[Department]],Dashboard!S18) -> 4 | Y19: =COUNTIFS(Roster!G:G,"AUH3",Roster!P:P,"Direct",Roster!T:T,"P",Roster!E:E,"Temporary")+COUNTIFS(Roster!G:G,"DDB1",Roster!P:P,"Direct",Roster!T:T,"P",Roster!E:E,"Temporary") -> 54 | Z19: =COUNTIFS(Roster!G:G,"AUH3",Roster!P:P,"Direct",Roster!T:T,"SL",Roster!E:E,"Temporary")+COUNTIFS(Roster!G:G,"DDB1",Roster!P:P,"Direct",Roster!T:T,"SL",Roster!E:E,"Temporary") -> 0 | AA19: =COUNTIFS(Roster!G:G,"AUH3",Roster!P:P,"Direct",Roster!T:T,"AB",Roster!E:E,"Temporary")+COUNTIFS(Roster!G:G,"DDB1",Roster!P:P,"Direct",Roster!T:T,"AB",Roster!E:E,"Temporary")+COUNTIFS(Roster!G:G,"AUH3",Roster!P:P,"Direct",Roster!T:T,"ABWI",Roster!E:E,"Temporary")+COUNTIFS(Roster!G:G,"DDB1",Roster!P:P,"Direct",Roster!T:T,"ABWI",Roster!E:E,"Temporary") -> 3 | AB19: =SUM(Y19:AA19,)+SUM(U19:W19) -> 89 | AC19: =(AB19-V19)-U19 -> 63 | AD19: =Y19/AC19 -> 0.85714286
A20: Outbound | B20: Day Shift | C20: =COUNTIFS(Roster!T:T,"0",Roster!O:O,"Outbound",Roster!J:J,"Day Shift",Roster!P:P,"Direct",Roster!G:G,"AUH1") -> 0 | D20: =COUNTIFS(Roster!T:T,"OFF",Roster!O:O,"Outbound",Roster!J:J,"Day Shift",Roster!P:P,"Direct",Roster!G:G,"AUH1") -> 55 | E20: =COUNTIFS(Roster!T:T,"PL",Roster!O:O,"Outbound",Roster!J:J,"Day Shift",Roster!P:P,"Direct",Roster!G:G,"AUH1") -> 16 | F20: =COUNTIFS(Table1[[#All],[Building]],"AUH1",Table1[[#All],[Shift]],"Day Shift",Table1[[#All],[OFF1]],"OT",Table1[[#All],[Department]],Dashboard!A20)+COUNTIFS(Table1[[#All],[Building]],"AUH1",Table1[[#All],[Shift]],"Day Shift",Table1[[#All],[OFF2]],"OT",Table1[[#All],[Department]],Dashboard!A20) -> 19 | G20: =COUNTIFS(Roster!T:T,"P",Roster!O:O,"Outbound",Roster!J:J,"Day Shift",Roster!P:P,"Direct",Roster!G:G,"AUH1") -> 165 | H20: =COUNTIFS(Roster!T:T,"SL",Roster!O:O,"Outbound",Roster!J:J,"Day Shift",Roster!P:P,"Direct",Roster!G:G,"AUH1") -> 0 | I20: =COUNTIFS(Roster!T:T,"AB",Roster!O:O,"Outbound",Roster!J:J,"Day Shift",Roster!P:P,"Direct",Roster!G:G,"AUH1")+COUNTIFS(Roster!T:T,"ABWI",Roster!O:O,"Outbound",Roster!J:J,"Day Shift",Roster!P:P,"Direct",Roster!G:G,"AUH1") -> 13 | J20: =SUM(G20:I20,)+SUM(C20:E20) -> 249 | K20: =(J20-D20)-C20-F20 -> 175 | L20: 0.87251445 | M20: =(G20-F20)/(K20) -> 0.83428571 | N20: =G20/K20 -> 0.94285714 | S20: SC Total | U20: =SUM(U17:U19) -> 0 | V20: =SUM(V17:V19) -> 27 | W20: =SUM(W17:W19) -> 7 | X20: =SUM(X17:X19) -> 5 | Y20: =SUM(Y17:Y19) -> 66 | Z20: =SUM(Z17:Z19) -> 0 | AA20: =SUM(AA17:AA19) -> 3 | AB20: =SUM(AB17:AB19) -> 103 | AC20: =SUM(AC18:AC19) -> 76
B21: Mid Shift | C21: =COUNTIFS(Roster!T:T,"0",Roster!O:O,"Outbound",Roster!J:J,"Mid Shift",Roster!P:P,"Direct",Roster!G:G,"AUH1") -> 0 | D21: =COUNTIFS(Roster!T:T,"OFF",Roster!O:O,"Outbound",Roster!J:J,"Mid Shift",Roster!P:P,"Direct",Roster!G:G,"AUH1") -> 0 | E21: =COUNTIFS(Roster!T:T,"PL",Roster!O:O,"Outbound",Roster!J:J,"Mid Shift",Roster!P:P,"Direct",Roster!G:G,"AUH1") -> 0 | F21: =COUNTIFS(Table1[[#All],[Building]],"AUH1",Table1[[#All],[Shift]],"Mid Shift",Table1[[#All],[OFF1]],"OT",Table1[[#All],[Department]],Dashboard!A20)+COUNTIFS(Table1[[#All],[Building]],"AUH1",Table1[[#All],[Shift]],"Mid Shift",Table1[[#All],[OFF2]],"OT",Table1[[#All],[Department]],Dashboard!A20) -> 0 | G21: =COUNTIFS(Roster!T:T,"P",Roster!O:O,"Outbound",Roster!J:J,"Mid Shift",Roster!P:P,"Direct",Roster!G:G,"AUH1") -> 0 | H21: =COUNTIFS(Roster!T:T,"SL",Roster!O:O,"Outbound",Roster!J:J,"Mid Shift",Roster!P:P,"Direct",Roster!G:G,"AUH1") -> 0 | I21: =COUNTIFS(Roster!T:T,"AB",Roster!O:O,"Outbound",Roster!J:J,"Mid Shift",Roster!P:P,"Direct",Roster!G:G,"AUH1")+COUNTIFS(Roster!T:T,"ABWI",Roster!O:O,"Outbound",Roster!J:J,"Mid Shift",Roster!P:P,"Direct",Roster!G:G,"AUH1") -> 0 | J21: =SUM(G21:I21,)+SUM(C21:E21) -> 0 | K21: =(J21-D21)-C21-F21 -> 0 | M21: =(G21-F21)/(K21) -> #DIV/0! | N21: =G21/K21 -> #DIV/0!
B22: Night Shift | C22: =COUNTIFS(Roster!T:T,"0",Roster!O:O,"Outbound",Roster!J:J,"Night Shift",Roster!P:P,"Direct",Roster!G:G,"AUH1") -> 0 | D22: =COUNTIFS(Roster!T:T,"OFF",Roster!O:O,"Outbound",Roster!J:J,"Night Shift",Roster!P:P,"Direct",Roster!G:G,"AUH1") -> 95 | E22: =COUNTIFS(Roster!T:T,"PL",Roster!O:O,"Outbound",Roster!J:J,"Night Shift",Roster!P:P,"Direct",Roster!G:G,"AUH1") -> 16 | F22: =COUNTIFS(Table1[[#All],[Building]],"AUH1",Table1[[#All],[Shift]],"Night Shift",Table1[[#All],[OFF1]],"OT",Table1[[#All],[Department]],Dashboard!A20)+COUNTIFS(Table1[[#All],[Building]],"AUH1",Table1[[#All],[Shift]],"Night Shift",Table1[[#All],[OFF2]],"OT",Table1[[#All],[Department]],Dashboard!A20) -> 11 | G22: =COUNTIFS(Roster!T:T,"P",Roster!O:O,"Outbound",Roster!J:J,"Night Shift",Roster!P:P,"Direct",Roster!G:G,"AUH1") -> 242 | H22: =COUNTIFS(Roster!T:T,"SL",Roster!O:O,"Outbound",Roster!J:J,"Night Shift",Roster!P:P,"Direct",Roster!G:G,"AUH1") -> 0 | I22: =COUNTIFS(Roster!T:T,"AB",Roster!O:O,"Outbound",Roster!J:J,"Night Shift",Roster!P:P,"Direct",Roster!G:G,"AUH1")+COUNTIFS(Roster!T:T,"ABWI",Roster!O:O,"Outbound",Roster!J:J,"Night Shift",Roster!P:P,"Direct",Roster!G:G,"AUH1") -> 22 | J22: =SUM(G22:I22,)+SUM(C22:E22) -> 375 | K22: =(J22-D22)-C22-F22 -> 269 | L22: 0.91873665 | M22: =(G22-F22)/(K22) -> 0.85873606 | N22: =G22/K22 -> 0.89962825 | S22: Shift | T22: Total HC | U22: Unscheduled | V22: Schedule to Work | W22: PL | X22: OT | Y22: UPL | Z22: Present | AA22: Present % | AB22: LM Target | AC22: Target Achievement
A23: Outbound Total | C23: =SUM(C20:C22) -> 0 | D23: =SUM(D20:D22) -> 150 | E23: =SUM(E20:E22) -> 32 | F23: =SUM(F20:F22) -> 30 | G23: =SUM(G20:G22) -> 407 | H23: =SUM(H20:H22) -> 0 | I23: =SUM(I20:I22) -> 35 | J23: =SUM(J20:J22) -> 624 | K23: =SUM(K20:K22) -> 444 | L23: 0.90112335 | M23: =(G23-F23)/(K23) -> 0.8490991 | N23: =G23/K23 -> 0.91666667 | O23: =L23*K23 -> 400.09877 | P23: =G23-F23 -> 377 | Q23: =P23-O23 -> -23.098767 | S23: Regular | T23: =COUNTIFS(Roster!G:G,"AUH3",Roster!E:E,"Regular")+COUNTIFS(Roster!G:G,"DDB1",Roster!E:E,"Regular",Roster!P:P,"Direct") -> 14 | U23: =COUNTIFS(Roster!G:G,"AUH3",Roster!E:E,"Regular",Roster!T:T,"OFF",Roster!P:P,"Direct")+COUNTIFS(Roster!G:G,"DDB1",Roster!E:E,"Regular",Roster!T:T,"OFF",Roster!P:P,"Direct") -> 1 | V23: =SUMIFS($AC$18:$AC$19,$T$18:$T$19,"Regular") -> 13 | W23: =COUNTIFS(Roster!G:G,"AUH3",Roster!E:E,"Regular",Roster!T:T,"PL",Roster!P:P,"Direct")+COUNTIFS(Roster!G:G,"DDB1",Roster!E:E,"Regular",Roster!T:T,"PL",Roster!P:P,"Direct") -> 1 | X23: =COUNTIFS(Table1[[#All],[Building]],"AUH3",Table1[[#All],[Employment Type]],"Regular",Table1[[#All],[OFF1]],"OT",Table1[[#All],[Department]],Dashboard!S23)+COUNTIFS(Table1[[#All],[Building]],"AUH3",Table1[[#All],[Employment Type]],"Regular",Table1[[#All],[OFF2]],"OT",Table1[[#All],[Department]],Dashboard!S23) -> 0 | Y23: =COUNTIFS(Roster!G:G,"AUH3",Roster!E:E,"Regular",Roster!T:T,"AB",Roster!P:P,"Direct")+COUNTIFS(Roster!G:G,"AUH3",Roster!E:E,"Regular",Roster!T:T,"SL",Roster!P:P,"Direct")+COUNTIFS(Roster!G:G,"AUH3",Roster!E:E,"Regular",Roster!T:T,"ABWI",Roster!P:P,"Direct")+COUNTIFS(Roster!G:G,"DDB1",Roster!E:E,"Regular",Roster!T:T,"ABWI") -> 0 | Z23: =V23-W23-Y23 -> 12 | AA23: =Z23/V23 -> 0.92307692 | AB23: 0.92384615 | AC23: =AA23/AB23 -> 0.99916736
A24: CRET | B24: Day Shift | C24: =COUNTIFS(Roster!T:T,"0",Roster!O:O,"CRET",Roster!J:J,"Day Shift",Roster!P:P,"Direct",Roster!G:G,"AUH1") -> 0 | D24: =COUNTIFS(Roster!T:T,"OFF",Roster!O:O,"CRET",Roster!J:J,"Day Shift",Roster!P:P,"Direct",Roster!G:G,"AUH1") -> 23 | E24: =COUNTIFS(Roster!T:T,"PL",Roster!O:O,"CRET",Roster!J:J,"Day Shift",Roster!P:P,"Direct",Roster!G:G,"AUH1") -> 12 | F24: =COUNTIFS(Table1[[#All],[Building]],"AUH1",Table1[[#All],[Shift]],"Day Shift",Table1[[#All],[OFF1]],"OT",Table1[[#All],[Department]],Dashboard!A24)+COUNTIFS(Table1[[#All],[Building]],"AUH1",Table1[[#All],[Shift]],"Day Shift",Table1[[#All],[OFF2]],"OT",Table1[[#All],[Department]],Dashboard!A24) -> 11 | G24: =COUNTIFS(Roster!T:T,"P",Roster!O:O,"CRET",Roster!J:J,"Day Shift",Roster!P:P,"Direct",Roster!G:G,"AUH1") -> 86 | H24: =COUNTIFS(Roster!T:T,"SL",Roster!O:O,"CRET",Roster!J:J,"Day Shift",Roster!P:P,"Direct",Roster!G:G,"AUH1") -> 0 | I24: =COUNTIFS(Roster!T:T,"AB",Roster!O:O,"CRET",Roster!J:J,"Day Shift",Roster!P:P,"Direct",Roster!G:G,"AUH1")+COUNTIFS(Roster!T:T,"ABWI",Roster!O:O,"CRET",Roster!J:J,"Day Shift",Roster!P:P,"Direct",Roster!G:G,"AUH1") -> 7 | J24: =SUM(G24:I24,)+SUM(C24:E24) -> 128 | K24: =(J24-D24)-C24-F24 -> 94 | L24: 0.85041667 | M24: =(G24-F24)/(K24) -> 0.79787234 | N24: =G24/K24 -> 0.91489362 | S24: Temporary | T24: =COUNTIFS(Roster!G:G,"AUH3",Roster!E:E,"Temporary")+COUNTIFS(Roster!G:G,"DDB1",Roster!E:E,"Temporary",Roster!P:P,"Direct") -> 89 | U24: =COUNTIFS(Roster!G:G,"AUH3",Roster!E:E,"Temporary",Roster!T:T,"OFF",Roster!P:P,"Direct")+COUNTIFS(Roster!G:G,"DDB1",Roster!E:E,"Temporary",Roster!T:T,"OFF",Roster!P:P,"Direct") -> 26 | V24: =SUMIFS($AC$18:$AC$19,$T$18:$T$19,"Temporary") -> 63 | W24: =COUNTIFS(Roster!G:G,"AUH3",Roster!E:E,"Temporary",Roster!T:T,"PL",Roster!P:P,"Direct")+COUNTIFS(Roster!G:G,"DDB1",Roster!E:E,"Temporary",Roster!T:T,"PL",Roster!P:P,"Direct") -> 6 | X24: =COUNTIFS(Table1[[#All],[Building]],"AUH3",Table1[[#All],[Employment Type]],"Temporary",Table1[[#All],[OFF1]],"OT",Table1[[#All],[Department]],Dashboard!S23)+COUNTIFS(Table1[[#All],[Building]],"AUH3",Table1[[#All],[Employment Type]],"Temporary",Table1[[#All],[OFF2]],"OT",Table1[[#All],[Department]],Dashboard!S23) -> 0 | Y24: =COUNTIFS(Roster!G:G,"AUH3",Roster!E:E,"Temporary",Roster!T:T,"AB")+COUNTIFS(Roster!G:G,"AUH3",Roster!E:E,"Temporary",Roster!T:T,"SL")+COUNTIFS(Roster!G:G,"AUH3",Roster!E:E,"Temporary",Roster!T:T,"ABWI")+COUNTIFS(Roster!G:G,"DDB1",Roster!E:E,"Temporary",Roster!T:T,"ABWI",Roster!P:P,"Direct") -> 3 | Z24: =V24-W24-Y24 -> 54 | AA24: =Z24/V24 -> 0.85714286 | AB24: 0.90181818 | AC24: =AA24/AB24 -> 0.95046083
B25: Mid Shift | C25: =COUNTIFS(Roster!T:T,"0",Roster!O:O,"CRET",Roster!J:J,"Mid Shift",Roster!P:P,"Direct",Roster!G:G,"AUH1") -> 0 | D25: =COUNTIFS(Roster!T:T,"OFF",Roster!O:O,"CRET",Roster!J:J,"Mid Shift",Roster!P:P,"Direct",Roster!G:G,"AUH1") -> 0 | E25: =COUNTIFS(Roster!T:T,"PL",Roster!O:O,"CRET",Roster!J:J,"Mid Shift",Roster!P:P,"Direct",Roster!G:G,"AUH1") -> 0 | F25: =COUNTIFS(Table1[[#All],[Building]],"AUH1",Table1[[#All],[Shift]],"Mid Shift",Table1[[#All],[OFF1]],"OT",Table1[[#All],[Department]],Dashboard!A24)+COUNTIFS(Table1[[#All],[Building]],"AUH1",Table1[[#All],[Shift]],"Mid Shift",Table1[[#All],[OFF2]],"OT",Table1[[#All],[Department]],Dashboard!A24) -> 0 | G25: =COUNTIFS(Roster!T:T,"P",Roster!O:O,"CRET",Roster!J:J,"Mid Shift",Roster!P:P,"Direct",Roster!G:G,"AUH1") -> 0 | H25: =COUNTIFS(Roster!T:T,"SL",Roster!O:O,"CRET",Roster!J:J,"Mid Shift",Roster!P:P,"Direct",Roster!G:G,"AUH1") -> 0 | I25: =COUNTIFS(Roster!T:T,"AB",Roster!O:O,"CRET",Roster!J:J,"Mid Shift",Roster!P:P,"Direct",Roster!G:G,"AUH1")+COUNTIFS(Roster!T:T,"ABWI",Roster!O:O,"CRET",Roster!J:J,"Mid Shift",Roster!P:P,"Direct",Roster!G:G,"AUH1") -> 0 | J25: =SUM(G25:I25,)+SUM(C25:E25) -> 0 | K25: =(J25-D25)-C25-F25 -> 0 | M25: =(G25-F25)/(K25) -> #DIV/0! | N25: =G25/K25 -> #DIV/0!
B26: Night Shift | C26: =COUNTIFS(Roster!T:T,"0",Roster!O:O,"CRET",Roster!J:J,"Night Shift",Roster!P:P,"Direct",Roster!G:G,"AUH1") -> 0 | D26: =COUNTIFS(Roster!T:T,"OFF",Roster!O:O,"CRET",Roster!J:J,"Night Shift",Roster!P:P,"Direct",Roster!G:G,"AUH1") -> 16 | E26: =COUNTIFS(Roster!T:T,"PL",Roster!O:O,"CRET",Roster!J:J,"Night Shift",Roster!P:P,"Direct",Roster!G:G,"AUH1") -> 6 | F26: =COUNTIFS(Table1[[#All],[Building]],"AUH1",Table1[[#All],[Shift]],"Night Shift",Table1[[#All],[OFF1]],"OT",Table1[[#All],[Department]],Dashboard!A24)+COUNTIFS(Table1[[#All],[Building]],"AUH1",Table1[[#All],[Shift]],"Night Shift",Table1[[#All],[OFF2]],"OT",Table1[[#All],[Department]],Dashboard!A24) -> 6 | G26: =COUNTIFS(Roster!T:T,"P",Roster!O:O,"CRET",Roster!J:J,"Night Shift",Roster!P:P,"Direct",Roster!G:G,"AUH1") -> 62 | H26: =COUNTIFS(Roster!T:T,"SL",Roster!O:O,"CRET",Roster!J:J,"Night Shift",Roster!P:P,"Direct",Roster!G:G,"AUH1") -> 0 | I26: =COUNTIFS(Roster!T:T,"AB",Roster!O:O,"CRET",Roster!J:J,"Night Shift",Roster!P:P,"Direct",Roster!G:G,"AUH1")+COUNTIFS(Roster!T:T,"ABWI",Roster!O:O,"CRET",Roster!J:J,"Night Shift",Roster!P:P,"Direct",Roster!G:G,"AUH1") -> 4 | J26: =SUM(G26:I26,)+SUM(C26:E26) -> 88 | K26: =(J26-D26)-C26-F26 -> 66 | L26: 0.88807692 | M26: =(G26-F26)/(K26) -> 0.84848485 | N26: =G26/K26 -> 0.93939394
A27: CRET Total | C27: =SUM(C24:C26) -> 0 | D27: =SUM(D24:D26) -> 39 | E27: =SUM(E24:E26) -> 18 | F27: =SUM(F24:F26) -> 17 | G27: =SUM(G24:G26) -> 148 | H27: =SUM(H24:H26) -> 0 | I27: =SUM(I24:I26) -> 11 | J27: =SUM(J24:J26) -> 216 | K27: =SUM(K24:K26) -> 160 | L27: 0.86562112 | M27: =(G27-F27)/(K27) -> 0.81875 | N27: =G27/K27 -> 0.925 | O27: =L27*K27 -> 138.49938 | P27: =G27-F27 -> 131 | Q27: =P27-O27 -> -7.4993789 | W27: =W9/(V9-X9) -> 0.10606061 | Y27: =Y9/(V9-X9) -> 0.045454545
A28: Grand Total | C28: =C15+C19+C23+C27 -> 0 | D28: =D15+D19+D23+D27 -> 278 | E28: =E15+E19+E23+E27 -> 72 | F28: =F15+F19+F23+F27 -> 58 | G28: =G15+G19+G23+G27 -> 784 | H28: =H15+H19+H23+H27 -> 2 | I28: =I15+I19+I23+I27 -> 61 | J28: =J15+J19+J23+J27 -> 1197 | K28: =K15+K19+K23+K27 -> 861 | L28: 0.8893 | M28: =(G28-F28)/(K28) -> 0.84320557 | N28: =G28/K28 -> 0.91056911 | O28: =L28*K28 -> 765.6873 | P28: =G28-F28 -> 726 | Q28: =P28-O28 -> -39.6873
E30: =E9/(D9-F9) -> 0.089663761
I31: 57
D33: OT | E33: 57
D34: UPL | E34: 57 | F34: =E34/(D9-E33) -> 0.070895522
F35: =E9/(D9-E33) -> 0.089552239

Sheet Roster
A1: Date | B1: 46267 | C1: =TEXT(B1,"dddd") -> Wednesday | F1: target | G1: 0.0533 | Q1: P | R1: Present | S1: SL
Q2: AB | R2: Absent | S2: EL
Q3: PL | R3: Any Planned Leave | S3: ABWI
Q4: OFF | R4: Weekly Off | S4: 0
A6: S.No | B6: Psoft No | C6: AMZ ID | D6: EMP Name | E6: Employment Type | F6: Country | G6: Building | H6: LOB | I6: Cost Center | J6: Shift | K6: Shift Difference | L6: OFF1 | M6: OFF2 | N6: Job Title | O6: Department | P6: Type | Q6: 3P | R6: Line Manager Login | S6: Line Manager | T6: Attendance | U6: Remarks | V6: DOJ | W6: Process Path | X6: Column1 | Y6: Column2
A7: 1 | B7: 206875258 | C7: bakabdal | D7: ABDALLAH ABDALLAH ISSA | E7: Temporary | F7: UAE | G7: AUH1 | H7: FC | I7: 1299 | J7: =VLOOKUP(Table1[[#This Row],[Psoft No]],[1]Roster!$C$1:$AJ$1369,9,0) -> Day Shift | K7: NA | L7: =VLOOKUP(Table1[[#This Row],[Psoft No]],[1]Roster!$C$1:$AJ$1369,11,0) -> Sunday | M7: =VLOOKUP(Table1[[#This Row],[Psoft No]],[1]Roster!$C$1:$AJ$1369,12,0) -> Monday | N7: Warehouse Associate 8W | O7: CRET | P7: Direct | Q7: Dulsco | R7: aanso | S7: Sohail,Anis | T7: =IF(COUNTIFS('DWD RAW File'!$E:$E,$B7,'DWD RAW File'!$AF:$AF,$C$1)>0, IF(COUNTIFS('DWD RAW File'!$E:$E,$B7,'DWD RAW File'!$AF:$AF,$C$1,'DWD RAW File'!$AB:$AB,"Present")>0,"6th Day OT","OFF"), IF(COUNTIFS('DWD RAW File'!$E:$E,$B7,'DWD RAW File'!$AG:$AG,$C$1)>0, IF(COUNTIFS('DWD RAW File'!$E:$E,$B7,'DWD RAW File'!$AG:$AG,$C$1,'DWD RAW File'!$AB:$AB,"Present")>0,"7th Day OT","OFF"), IF(COUNTIFS('DWD RAW File'!$E:$E,$B7,'DWD RAW File'!$AB:$AB,"Present")>0, "P", IF(COUNTIFS('DWD RAW File'!$E:$E,$B7,'DWD RAW File'!$AB:$AB,"Not Present",'DWD RAW File'!$AK:$AK,"<>")>0, _xlfn.XLOOKUP($B7,'DWD RAW File'!$E:$E,'DWD RAW File'!$AK:$AK,""), IF(COUNTIFS('DWD RAW File'!$E:$E,$B7,'DWD RAW File'!$AB:$AB,"Not Present",'DWD RAW File'!$AL:$AL,"<>")>0, _xlfn.XLOOKUP($B7,'DWD RAW File'!$E:$E,'DWD RAW File'!$AL:$AL,""), "AB"))))) -> P | V7: 46051 | W7: Customer Returns | X7: =VLOOKUP(Table1[[#This Row],[Psoft No]],[2]Roster_1788384531598!$E$1:$AU$1334,28,0) -> Sunday | Y7: =Table1[[#This Row],[Column1]]=Table1[[#This Row],[OFF1]] -> TRUE
A8: 2 | B8: 206873715 | C8: zkasabda | D8: ABDALLAH KASSIM | E8: Temporary | F8: UAE | G8: AUH1 | H8: FC | I8: 1299 | J8: =VLOOKUP(Table1[[#This Row],[Psoft No]],[1]Roster!$C$1:$AJ$1369,9,0) -> Day Shift | K8: NA | L8: =VLOOKUP(Table1[[#This Row],[Psoft No]],[1]Roster!$C$1:$AJ$1369,11,0) -> Saturday | M8: =VLOOKUP(Table1[[#This Row],[Psoft No]],[1]Roster!$C$1:$AJ$1369,12,0) -> Sunday | N8: Warehouse Associate 8W | O8: CRET | P8: Direct | Q8: Dulsco | R8: aanso | S8: Sohail,Anis | T8: =IF(COUNTIFS('DWD RAW File'!$E:$E,$B8,'DWD RAW File'!$AF:$AF,$C$1)>0, IF(COUNTIFS('DWD RAW File'!$E:$E,$B8,'DWD RAW File'!$AF:$AF,$C$1,'DWD RAW File'!$AB:$AB,"Present")>0,"6th Day OT","OFF"), IF(COUNTIFS('DWD RAW File'!$E:$E,$B8,'DWD RAW File'!$AG:$AG,$C$1)>0, IF(COUNTIFS('DWD RAW File'!$E:$E,$B8,'DWD RAW File'!$AG:$AG,$C$1,'DWD RAW File'!$AB:$AB,"Present")>0,"7th Day OT","OFF"), IF(COUNTIFS('DWD RAW File'!$E:$E,$B8,'DWD RAW File'!$AB:$AB,"Present")>0, "P", IF(COUNTIFS('DWD RAW File'!$E:$E,$B8,'DWD RAW File'!$AB:$AB,"Not Present",'DWD RAW File'!$AK:$AK,"<>")>0, _xlfn.XLOOKUP($B8,'DWD RAW File'!$E:$E,'DWD RAW File'!$AK:$AK,""), IF(COUNTIFS('DWD RAW File'!$E:$E,$B8,'DWD RAW File'!$AB:$AB,"Not Present",'DWD RAW File'!$AL:$AL,"<>")>0, _xlfn.XLOOKUP($B8,'DWD RAW File'!$E:$E,'DWD RAW File'!$AL:$AL,""), "AB"))))) -> P | V8: 46020 | W8: Customer Returns | X8: =VLOOKUP(Table1[[#This Row],[Psoft No]],[2]Roster_1788384531598!$E$1:$AU$1334,28,0) -> Saturday | Y8: =Table1[[#This Row],[Column1]]=Table1[[#This Row],[OFF1]] -> TRUE
A9: 3 | B9: 203679309 | C9: njitaria | D9: Abdel Koudous Njitari Mah | E9: Temporary | F9: UAE | G9: AUH1 | H9: FC | I9: 1299 | J9: =VLOOKUP(Table1[[#This Row],[Psoft No]],[1]Roster!$C$1:$AJ$1369,9,0) -> Night Shift | K9: NA | L9: =VLOOKUP(Table1[[#This Row],[Psoft No]],[1]Roster!$C$1:$AJ$1369,11,0) -> Sunday | M9: =VLOOKUP(Table1[[#This Row],[Psoft No]],[1]Roster!$C$1:$AJ$1369,12,0) -> Monday | N9: Warehouse Associate 12M | O9: CRET | P9: Direct | Q9: Fastlink | R9: aanso | S9: Sohail,Anis | T9: =IF(COUNTIFS('DWD RAW File'!$E:$E,$B9,'DWD RAW File'!$AF:$AF,$C$1)>0, IF(COUNTIFS('DWD RAW File'!$E:$E,$B9,'DWD RAW File'!$AF:$AF,$C$1,'DWD RAW File'!$AB:$AB,"Present")>0,"6th Day OT","OFF"), IF(COUNTIFS('DWD RAW File'!$E:$E,$B9,'DWD RAW File'!$AG:$AG,$C$1)>0, IF(COUNTIFS('DWD RAW File'!$E:$E,$B9,'DWD RAW File'!$AG:$AG,$C$1,'DWD RAW File'!$AB:$AB,"Present")>0,"7th Day OT","OFF"), IF(COUNTIFS('DWD RAW File'!$E:$E,$B9,'DWD RAW File'!$AB:$AB,"Present")>0, "P", IF(COUNTIFS('DWD RAW File'!$E:$E,$B9,'DWD RAW File'!$AB:$AB,"Not Present",'DWD RAW File'!$AK:$AK,"<>")>0, _xlfn.XLOOKUP($B9,'DWD RAW File'!$E:$E,'DWD RAW File'!$AK:$AK,""), IF(COUNTIFS('DWD RAW File'!$E:$E,$B9,'DWD RAW File'!$AB:$AB,"Not Present",'DWD RAW File'!$AL:$AL,"<>")>0, _xlfn.XLOOKUP($B9,'DWD RAW File'!$E:$E,'DWD RAW File'!$AL:$AL,""), "AB"))))) -> P | V9: 45488 | W9: Customer Returns | X9: =VLOOKUP(Table1[[#This Row],[Psoft No]],[2]Roster_1788384531598!$E$1:$AU$1334,28,0) -> Sunday | Y9: =Table1[[#This Row],[Column1]]=Table1[[#This Row],[OFF1]] -> TRUE
A10: 4 | B10: 204864408 | C10: iddabdud | D10: ABDULMALIK IDDRISU | E10: Temporary | F10: UAE | G10: AUH1 | H10: FC | I10: 1299 | J10: =VLOOKUP(Table1[[#This Row],[Psoft No]],[1]Roster!$C$1:$AJ$1369,9,0) -> Night Shift | K10: NA | L10: =VLOOKUP(Table1[[#This Row],[Psoft No]],[1]Roster!$C$1:$AJ$1369,11,0) -> Sunday | M10: =VLOOKUP(Table1[[#This Row],[Psoft No]],[1]Roster!$C$1:$AJ$1369,12,0) -> Monday | N10: Warehouse Associate 8W | O10: CRET | P10: Direct | Q10: Dulsco | R10: aanso | S10: Sohail,Anis | T10: =IF(COUNTIFS('DWD RAW File'!$E:$E,$B10,'DWD RAW File'!$AF:$AF,$C$1)>0, IF(COUNTIFS('DWD RAW File'!$E:$E,$B10,'DWD RAW File'!$AF:$AF,$C$1,'DWD RAW File'!$AB:$AB,"Present")>0,"6th Day OT","OFF"), IF(COUNTIFS('DWD RAW File'!$E:$E,$B10,'DWD RAW File'!$AG:$AG,$C$1)>0, IF(COUNTIFS('DWD RAW File'!$E:$E,$B10,'DWD RAW File'!$AG:$AG,$C$1,'DWD RAW File'!$AB:$AB,"Present")>0,"7th Day OT","OFF"), IF(COUNTIFS('DWD RAW File'!$E:$E,$B10,'DWD RAW File'!$AB:$AB,"Present")>0, "P", IF(COUNTIFS('DWD RAW File'!$E:$E,$B10,'DWD RAW File'!$AB:$AB,"Not Present",'DWD RAW File'!$AK:$AK,"<>")>0, _xlfn.XLOOKUP($B10,'DWD RAW File'!$E:$E,'DWD RAW File'!$AK:$AK,""), IF(COUNTIFS('DWD RAW File'!$E:$E,$B10,'DWD RAW File'!$AB:$AB,"Not Present",'DWD RAW File'!$AL:$AL,"<>")>0, _xlfn.XLOOKUP($B10,'DWD RAW File'!$E:$E,'DWD RAW File'!$AL:$AL,""), "AB"))))) -> P | V10: 45684 | W10: Customer Returns | X10: =VLOOKUP(Table1[[#This Row],[Psoft No]],[2]Roster_1788384531598!$E$1:$AU$1334,28,0) -> Sunday | Y10: =Table1[[#This Row],[Column1]]=Table1[[#This Row],[OFF1]] -> TRUE
A11: 5 | B11: 203800376 | C11: kiwanuab | D11: ABDURASHID KIWANUKA | E11: Temporary | F11: UAE | G11: AUH1 | H11: FC | I11: 1299 | J11: =VLOOKUP(Table1[[#This Row],[Psoft No]],[1]Roster!$C$1:$AJ$1369,9,0) -> Day Shift | K11: NA | L11: OT | M11: =VLOOKUP(Table1[[#This Row],[Psoft No]],[1]Roster!$C$1:$AJ$1369,12,0) -> Thursday | N11: Warehouse Associate 8W | O11: CRET | P11: Direct | Q11: Dulsco | R11: aanso | S11: Sohail,Anis | T11: P | U11: 6th Day OT | V11: 45516 | W11: Customer Returns | X11: =VLOOKUP(Table1[[#This Row],[Psoft No]],[2]Roster_1788384531598!$E$1:$AU$1334,28,0) -> Wednesday | Y11: =Table1[[#This Row],[Column1]]=Table1[[#This Row],[OFF1]] -> FALSE
A12: 6 | B12: 206953791 | C12: abubodon | D12: ABUBAKAESWIDIQ ODONGO | E12: Temporary | F12: UAE | G12: AUH1 | H12: FC | I12: 1299 | J12: =VLOOKUP(Table1[[#This Row],[Psoft No]],[1]Roster!$C$1:$AJ$1369,9,0) -> Day Shift | K12: NA | L12: =VLOOKUP(Table1[[#This Row],[Psoft No]],[1]Roster!$C$1:$AJ$1369,11,0) -> Thursday | M12: =VLOOKUP(Table1[[#This Row],[Psoft No]],[1]Roster!$C$1:$AJ$1369,12,0) -> Friday | N12: Warehouse Associate 24M | O12: CRET | P12: Direct | Q12: Dulsco | R12: aanso | S12: Sohail,Anis | T12: =IF(COUNTIFS('DWD RAW File'!$E:$E,$B12,'DWD RAW File'!$AF:$AF,$C$1)>0, IF(COUNTIFS('DWD RAW File'!$E:$E,$B12,'DWD RAW File'!$AF:$AF,$C$1,'DWD RAW File'!$AB:$AB,"Present")>0,"6th Day OT","OFF"), IF(COUNTIFS('DWD RAW File'!$E:$E,$B12,'DWD RAW File'!$AG:$AG,$C$1)>0, IF(COUNTIFS('DWD RAW File'!$E:$E,$B12,'DWD RAW File'!$AG:$AG,$C$1,'DWD RAW File'!$AB:$AB,"Present")>0,"7th Day OT","OFF"), IF(COUNTIFS('DWD RAW File'!$E:$E,$B12,'DWD RAW File'!$AB:$AB,"Present")>0, "P", IF(COUNTIFS('DWD RAW File'!$E:$E,$B12,'DWD RAW File'!$AB:$AB,"Not Present",'DWD RAW File'!$AK:$AK,"<>")>0, _xlfn.XLOOKUP($B12,'DWD RAW File'!$E:$E,'DWD RAW File'!$AK:$AK,""), IF(COUNTIFS('DWD RAW File'!$E:$E,$B12,'DWD RAW File'!$AB:$AB,"Not Present",'DWD RAW File'!$AL:$AL,"<>")>0, _xlfn.XLOOKUP($B12,'DWD RAW File'!$E:$E,'DWD RAW File'!$AL:$AL,""), "AB"))))) -> P | V12: 46048 | W12: Customer Returns | X12: =VLOOKUP(Table1[[#This Row],[Psoft No]],[2]Roster_1788384531598!$E$1:$AU$1334,28,0) -> Thursday | Y12: =Table1[[#This Row],[Column1]]=Table1[[#This Row],[OFF1]] -> TRUE
A13: 7 | B13: 205608373 | C13: tiacquah | D13: ACQUAH TIMOTHY | E13: Temporary | F13: UAE | G13: AUH1 | H13: FC | I13: 1299 | J13: =VLOOKUP(Table1[[#This Row],[Psoft No]],[1]Roster!$C$1:$AJ$1369,9,0) -> Night Shift | K13: NA | L13: OT | M13: =VLOOKUP(Table1[[#This Row],[Psoft No]],[1]Roster!$C$1:$AJ$1369,12,0) -> Thursday | N13: Warehouse Associate 8W | O13: CRET | P13: Direct | Q13: Dulsco | R13: aanso | S13: Sohail,Anis | T13: P | U13: 6th Day OT | V13: 45845 | W13: Customer Returns | X13: =VLOOKUP(Table1[[#This Row],[Psoft No]],[2]Roster_1788384531598!$E$1:$AU$1334,28,0) -> Wednesday | Y13: =Table1[[#This Row],[Column1]]=Table1[[#This Row],[OFF1]] -> FALSE
A14: 8 | B14: 204869098 | C14: rosadamu | D14: Adams,Rose | E14: Temporary | F14: UAE | G14: AUH1 | H14: FC | I14: 1299 | J14: =VLOOKUP(Table1[[#This Row],[Psoft No]],[1]Roster!$C$1:$AJ$1369,9,0) -> Night Shift | K14: NA | L14: =VLOOKUP(Table1[[#This Row],[Psoft No]],[1]Roster!$C$1:$AJ$1369,11,0) -> Friday | M14: =VLOOKUP(Table1[[#This Row],[Psoft No]],[1]Roster!$C$1:$AJ$1369,12,0) -> Saturday | N14: Warehouse Associate 8W | O14: CRET | P14: Direct | Q14: Quesscorp | R14: aanso | S14: Sohail,Anis | T14: =IF(COUNTIFS('DWD RAW File'!$E:$E,$B14,'DWD RAW File'!$AF:$AF,$C$1)>0, IF(COUNTIFS('DWD RAW File'!$E:$E,$B14,'DWD RAW File'!$AF:$AF,$C$1,'DWD RAW File'!$AB:$AB,"Present")>0,"6th Day OT","OFF"), IF(COUNTIFS('DWD RAW File'!$E:$E,$B14,'DWD RAW File'!$AG:$AG,$C$1)>0, IF(COUNTIFS('DWD RAW File'!$E:$E,$B14,'DWD RAW File'!$AG:$AG,$C$1,'DWD RAW File'!$AB:$AB,"Present")>0,"7th Day OT","OFF"), IF(COUNTIFS('DWD RAW File'!$E:$E,$B14,'DWD RAW File'!$AB:$AB,"Present")>0, "P", IF(COUNTIFS('DWD RAW File'!$E:$E,$B14,'DWD RAW File'!$AB:$AB,"Not Present",'DWD RAW File'!$AK:$AK,"<>")>0, _xlfn.XLOOKUP($B14,'DWD RAW File'!$E:$E,'DWD RAW File'!$AK:$AK,""), IF(COUNTIFS('DWD RAW File'!$E:$E,$B14,'DWD RAW File'!$AB:$AB,"Not Present",'DWD RAW File'!$AL:$AL,"<>")>0, _xlfn.XLOOKUP($B14,'DWD RAW File'!$E:$E,'DWD RAW File'!$AL:$AL,""), "AB"))))) -> P | V14: 45691 | W14: Customer Returns | X14: =VLOOKUP(Table1[[#This Row],[Psoft No]],[2]Roster_1788384531598!$E$1:$AU$1334,28,0) -> Friday | Y14: =Table1[[#This Row],[Column1]]=Table1[[#This Row],[OFF1]] -> TRUE
A15: 9 | B15: 206875144 | C15: ramaafid | D15: AFIDHU SWAMADU RAMADHANI | E15: Temporary | F15: UAE | G15: AUH1 | H15: FC | I15: 1299 | J15: =VLOOKUP(Table1[[#This Row],[Psoft No]],[1]Roster!$C$1:$AJ$1369,9,0) -> Night Shift | K15: NA | L15: =VLOOKUP(Table1[[#This Row],[Psoft No]],[1]Roster!$C$1:$AJ$1369,11,0) -> Sunday | M15: =VLOOKUP(Table1[[#This Row],[Psoft No]],[1]Roster!$C$1:$AJ$1369,12,0) -> Monday | N15: Warehouse Associate 8W | O15: CRET | P15: Direct | Q15: Dulsco | R15: aanso | S15: Sohail,Anis | T15: =IF(COUNTIFS('DWD RAW File'!$E:$E,$B15,'DWD RAW File'!$AF:$AF,$C$1)>0, IF(COUNTIFS('DWD RAW File'!$E:$E,$B15,'DWD RAW File'!$AF:$AF,$C$1,'DWD RAW File'!$AB:$AB,"Present")>0,"6th Day OT","OFF"), IF(COUNTIFS('DWD RAW File'!$E:$E,$B15,'DWD RAW File'!$AG:$AG,$C$1)>0, IF(COUNTIFS('DWD RAW File'!$E:$E,$B15,'DWD RAW File'!$AG:$AG,$C$1,'DWD RAW File'!$AB:$AB,"Present")>0,"7th Day OT","OFF"), IF(COUNTIFS('DWD RAW File'!$E:$E,$B15,'DWD RAW File'!$AB:$AB,"Present")>0, "P", IF(COUNTIFS('DWD RAW File'!$E:$E,$B15,'DWD RAW File'!$AB:$AB,"Not Present",'DWD RAW File'!$AK:$AK,"<>")>0, _xlfn.XLOOKUP($B15,'DWD RAW File'!$E:$E,'DWD RAW File'!$AK:$AK,""), IF(COUNTIFS('DWD RAW File'!$E:$E,$B15,'DWD RAW File'!$AB:$AB,"Not Present",'DWD RAW File'!$AL:$AL,"<>")>0, _xlfn.XLOOKUP($B15,'DWD RAW File'!$E:$E,'DWD RAW File'!$AL:$AL,""), "AB"))))) -> P | V15: 46020 | W15: Customer Returns | X15: =VLOOKUP(Table1[[#This Row],[Psoft No]],[2]Roster_1788384531598!$E$1:$AU$1334,28,0) -> Sunday | Y15: =Table1[[#This Row],[Column1]]=Table1[[#This Row],[OFF1]] -> TRUE
