Workbook
Name HCData: #REF!

Sheet Dashboard
A1: AUH1 | S1: AUH3 | AF1: DAD1
A2: Previous Day HC | B2: L3 Ops Supervisors | C2: FTE HC | D2: NFTE HC | E2: Today's HC | F2: HC LM Target | G2: Achievement % | H2: Remarks | S2: Previous Day HC | T2: L3 Ops Supervisors | U2: FTE HC | V2: NFTE HC | W2: Today's HC | X2: HC LM Target | Y2: Achievement % | Z2: Remarks | AF2: Previous Day HC | AG2: L3 Ops Supervisors | AH2: FTE HC | AI2: NFTE HC | AJ2: Today's HC | AK2: HC LM Target | AL2: Achievement % | AM2: Remarks
A3: 1244 | B3: =COUNTIFS(Roster!N:N,"FC Associate III",Roster!G:G,"AUH1",Roster!P:P,"Direct") -> 28 | C3: =COUNTIFS(Roster!E:E,"Regular",Roster!G:G,"AUH1",Roster!P:P,"Direct") -> 58 | D3: =COUNTIFS(Roster!E:E,"Temporary",Roster!G:G,"AUH1",Roster!P:P,"Direct") -> 1183 | E3: =C3+D3 -> 1241 | F3: =E3 -> 1241 | G3: =E3/F3 -> 1 | S3: 82 | T3: =COUNTIFS(Roster!N:N,"Hub Supervisor",Roster!P:P,"Direct",Roster!O:O,"Warehouse Deals") -> 4 | U3: =COUNTIFS(Roster!E:E,"Regular",Roster!P:P,"Direct",Roster!O:O,"Warehouse Deals") -> 14 | V3: =COUNTIFS(Roster!E:E,"Temporary",Roster!P:P,"Direct",Roster!O:O,"Warehouse Deals") -> 79 | W3: =U3+V3 -> 93 | X3: =W3 -> 93 | Y3: =W3/X3 -> 1 | AF3: 12 | AG3: =COUNTIFS(Roster!N:N,"FC Associate III",Roster!G:G,"DAD1",Roster!P:P,"Support") -> 0 | AH3: =COUNTIFS(Roster!E:E,"Regular",Roster!G:G,"DAD1",Roster!P:P,"Support") -> 0 | AI3: =COUNTIFS(Roster!E:E,"Temporary",Roster!G:G,"DAD1",Roster!P:P,"Support") -> 12 | AJ3: =AH3+AI3 -> 12 | AK3: =AJ3 -> 12 | AL3: =AJ3/AK3 -> 1
A4: =Roster!B1 -> 46257 | S4: =Roster!B1 -> 46257 | AF4: =Roster!B1 -> 46257
A5: Shift | B5: Total HC | C5: Unscheduled | D5: Schedule to Work | E5: PL | F5: OT | G5: UPL | H5: Present | I5: Present % (without OT) | J5: LM Target | K5: Target Achievement | S5: Shift | T5: Total HC | U5: Unscheduled | V5: Schedule to Work | W5: PL | X5: OT | Y5: UPL | Z5: Present | AA5: Present % | AB5: LM Target | AC5: Target Achievement | AF5: Shift | AG5: Total HC | AH5: Unscheduled | AI5: Schedule to Work | AJ5: PL | AK5: UPL | AL5: OT | AM5: Present | AN5: Present % | AO5: LM Target | AP5: Target Achievement
A6: Day Shift | B6: =COUNTIFS(Roster!G:G,"AUH1",Roster!P:P,"Direct",Roster!J:J,"Day Shift") -> 672 | C6: =SUMIFS($D$12:$D$27,$B$12:$B$27,"Day Shift") -> 276 | D6: =SUMIFS($K$12:$K$27,$B$12:$B$27,"Day Shift") -> 389 | E6: =SUMIFS($E$12:$E$27,$B$12:$B$27,"Day Shift") -> 26 | F6: =COUNTIFS(Table1[[#All],[Building]],"AUH1",Table1[[#All],[Shift]],"Day Shift",Table1[[#All],[OFF1]],"OT",Table1[[#All],[Type]],"Direct")+COUNTIFS(Table1[[#All],[Building]],"AUH1",Table1[[#All],[Shift]],"Day Shift",Table1[[#All],[OFF2]],"OT",Table1[[#All],[Type]],"Direct") -> 7 | G6: =SUMIFS($H$12:$H$26,$B$12:$B$26,"Day Shift")+SUMIFS($I$12:$I$26,$B$12:$B$26,"Day Shift") -> 13 | H6: =D6-E6-G6 -> 350 | I6: =H6/D6 -> 0.89974293 | J6: 0.87360215 | K6: =I6/J6 -> 1.029923 | S6: Day Shift | T6: =COUNTIFS(Roster!G:G,"AUH3",Roster!P:P,"Direct",Roster!J:J,"Day Shift")+COUNTIFS(Roster!G:G,"DDB1",Roster!P:P,"Direct",Roster!J:J,"Day Shift") -> 39 | U6: =SUMIFS($V$12:$V$14,$T$12:$T$14,"Day Shift") -> 12 | V6: =SUMIFS($AC$12:$AC$14,$T$12:$T$14,"Day Shift") -> 27 | W6: =SUMIFS($W$12:$W$14,$T$12:$T$14,"Day Shift") -> 2 | X6: =COUNTIFS(Table1[[#All],[Building]],"AUH3",Table1[[#All],[Shift]],"Day Shift",Table1[[#All],[OFF1]],"OT",Table1[[#All],[Type]],"Direct")+COUNTIFS(Table1[[#All],[Building]],"AUH3",Table1[[#All],[Shift]],"Day Shift",Table1[[#All],[OFF2]],"OT",Table1[[#All],[Type]],"Direct") -> 0 | Y6: =SUMIFS($Z$12:$Z$14,$T$12:$T$14,"Day Shift")+SUMIFS($AA$12:$AA$14,$T$12:$T$14,"Day Shift") -> 0 | Z6: =V6-W6-Y6 -> 25 | AA6: =Z6/V6 -> 0.92592593 | AB6: 0.97 | AC6: =AA6/AB6 -> 0.95456281 | AF6: Day Shift | AG6: =COUNTIFS(Roster!G:G,"DAD1",Roster!P:P,"Support",Roster!J:J,"Day Shift") -> 0 | AH6: =SUMIFS($AI$12:$AI$15,$AG$12:$AG$15,"Day Shift") -> 0 | AI6: =SUMIFS($AP$12:$AP$15,$AG$12:$AG$15,"Day Shift") -> 0 | AJ6: =SUMIFS($AJ$12:$AJ$15,$AG$12:$AG$15,"Day Shift") -> 0 | AK6: =SUMIFS($AM$12:$AM$15,$AG$12:$AG$15,"Day Shift")+SUMIFS($AN$12:$AN$15,$AG$12:$AG$15,"Day Shift") -> 0 | AL6: =COUNTIFS(Table1[[#All],[Building]],"DAD1",Table1[[#All],[Shift]],"Day Shift",Table1[[#All],[OFF1]],"OT",Table1[[#All],[Type]],"Direct")+COUNTIFS(Table1[[#All],[Building]],"DAD1",Table1[[#All],[Shift]],"Day Shift",Table1[[#All],[OFF2]],"OT",Table1[[#All],[Type]],"Support") -> 0 | AM6: =AI6-AJ6-AK6 -> 0 | AN6: =AM6/AI6 -> #DIV/0! | AO6: 0.9512 | AP6: =AN6/AO6 -> #DIV/0!
A7: Mid Shift | B7: =COUNTIFS(Roster!G:G,"AUH1",Roster!P:P,"Direct",Roster!J:J,"Mid Shift") -> 0 | C7: =SUMIFS($D$12:$D$27,$B$12:$B$27,"Mid Shift") -> 0 | D7: =SUMIFS($K$12:$K$27,$B$12:$B$27,"Mid Shift") -> 0 | E7: =SUMIFS($E$12:$E$27,$B$12:$B$27,"Mid Shift") -> 0 | F7: =COUNTIFS(Table1[[#All],[Building]],"AUH1",Table1[[#All],[Shift]],"Mid Shift",Table1[[#All],[OFF1]],"OT",Table1[[#All],[Type]],"Direct")+COUNTIFS(Table1[[#All],[Building]],"AUH1",Table1[[#All],[Shift]],"Mid Shift",Table1[[#All],[OFF2]],"OT",Table1[[#All],[Type]],"Direct") -> 0 | G7: =SUMIFS($H$12:$H$27,$B$12:$B$27,"Mid Shift")+SUMIFS($I$12:$I$27,$B$12:$B$27,"Mid Shift") -> 0 | H7: =D7-E7-G7 -> 0 | I7: =(H7-F7)/(D7-F7) -> #DIV/0! | J7: 0 | K7: =I7/J7 -> #DIV/0! | S7: Mid Shift | T7: =COUNTIFS(Roster!G:G,"AUH3",Roster!P:P,"Direct",Roster!J:J,"Mid Shift")+COUNTIFS(Roster!G:G,"DDB1",Roster!P:P,"Direct",Roster!J:J,"Mid Shift") -> 0 | U7: =SUMIFS($V$12:$V$14,$T$12:$T$14,"Mid Shift") -> 0 | V7: =SUMIFS($AC$12:$AC$14,$T$12:$T$14,"Mid Shift") -> 0 | W7: =SUMIFS($W$12:$W$14,$T$12:$T$14,"Mid Shift") -> 0 | X7: =COUNTIFS(Table1[[#All],[Building]],"AUH3",Table1[[#All],[Shift]],"Mid Shift",Table1[[#All],[OFF1]],"OT",Table1[[#All],[Type]],"Direct")+COUNTIFS(Table1[[#All],[Building]],"AUH3",Table1[[#All],[Shift]],"Mid Shift",Table1[[#All],[OFF2]],"OT",Table1[[#All],[Type]],"Direct") -> 0 | Y7: =SUMIFS($Z$12:$Z$14,$T$12:$T$14,"Mid Shift")+SUMIFS($AA$12:$AA$14,$T$12:$T$14,"Mid Shift") -> 0 | Z7: =V7-W7-Y7 -> 0 | AA7: =Z7/V7 -> #DIV/0! | AB7: 0 | AC7: =AA7/AB7 -> #DIV/0! | AF7: Mid Shift | AG7: =COUNTIFS(Roster!G:G,"DAD1",Roster!P:P,"Support",Roster!J:J,"Mid Shift") -> 0 | AH7: =SUMIFS($AI$12:$AI$15,$AG$12:$AG$15,"Mid Shift") -> 0 | AI7: =SUMIFS($AP$12:$AP$15,$AF$12:$AF$15,"Mid Shift") -> 0 | AJ7: =SUMIFS($AJ$12:$AJ$15,$AG$12:$AG$15,"Mid Shift") -> 0 | AK7: =SUMIFS($AM$12:$AM$15,$AG$12:$AG$15,"Mid Shift")+SUMIFS($AN$12:$AN$15,$AG$12:$AG$15,"Mid Shift") -> 0 | AL7: =COUNTIFS(Table1[[#All],[Building]],"DAD1",Table1[[#All],[Shift]],"Mid Shift",Table1[[#All],[OFF1]],"OT",Table1[[#All],[Type]],"Direct")+COUNTIFS(Table1[[#All],[Building]],"DAD1",Table1[[#All],[Shift]],"Mid Shift",Table1[[#All],[OFF2]],"OT",Table1[[#All],[Type]],"Direct") -> 0 | AM7: =AI7-AJ7-AK7 -> 0 | AN7: =AM7/AI7 -> #DIV/0! | AO7: 0.9565 | AP7: =AN7/AO7 -> #DIV/0!
A8: Night Shift | B8: =COUNTIFS(Roster!G:G,"AUH1",Roster!P:P,"Direct",Roster!J:J,"Night Shift") -> 569 | C8: =SUMIFS($D$12:$D$27,$B$12:$B$27,"Night Shift") -> 163 | D8: =SUMIFS($K$12:$K$27,$B$12:$B$27,"Night Shift") -> 392 | E8: =SUMIFS($E$12:$E$27,$B$12:$B$27,"Night Shift") -> 17 | F8: =COUNTIFS(Table1[[#All],[Building]],"AUH1",Table1[[#All],[Shift]],"Night Shift",Table1[[#All],[OFF1]],"OT",Table1[[#All],[Type]],"Direct")+COUNTIFS(Table1[[#All],[Building]],"AUH1",Table1[[#All],[Shift]],"Night Shift",Table1[[#All],[OFF2]],"OT",Table1[[#All],[Type]],"Direct") -> 14 | G8: =SUMIFS($H$12:$H$27,$B$12:$B$27,"Night Shift")+SUMIFS($I$12:$I$27,$B$12:$B$27,"Night Shift") -> 4 | H8: =D8-E8-G8 -> 371 | I8: =H8/D8 -> 0.94642857 | J8: 0.91797649 | K8: =I8/J8 -> 1.0309943 | S8: Night Shift | T8: =COUNTIFS(Roster!G:G,"AUH3",Roster!P:P,"Direct",Roster!J:J,"Night Shift")+COUNTIFS(Roster!G:G,"DDB1",Roster!P:P,"Direct",Roster!J:J,"Night Shift") -> 54 | U8: =SUMIFS($V$12:$V$14,$T$12:$T$14,"Night Shift") -> 21 | V8: =SUMIFS($AC$12:$AC$14,$T$12:$T$14,"Night Shift") -> 33 | W8: =SUMIFS($W$12:$W$14,$T$12:$T$14,"Night Shift") -> 0 | X8: =COUNTIFS(Table1[[#All],[Building]],"AUH3",Table1[[#All],[Shift]],"Night Shift",Table1[[#All],[OFF1]],"OT",Table1[[#All],[Type]],"Direct")+COUNTIFS(Table1[[#All],[Building]],"AUH3",Table1[[#All],[Shift]],"Night Shift",Table1[[#All],[OFF2]],"OT",Table1[[#All],[Type]],"Direct") -> 0 | Y8: =SUMIFS($Z$12:$Z$14,$T$12:$T$14,"Night Shift")+SUMIFS($AA$12:$AA$14,$T$12:$T$14,"Night Shift") -> 0 | Z8: =V8-W8-Y8 -> 33 | AA8: =Z8/V8 -> 1 | AB8: 0.91285714 | AC8: =AA8/AB8 -> 1.0954617 | AF8: Night Shift | AG8: =COUNTIFS(Roster!G:G,"DAD1",Roster!P:P,"Support",Roster!J:J,"Night Shift") -> 12 | AH8: =SUMIFS($AI$12:$AI$15,$AG$12:$AG$15,"Night Shift") -> 2 | AI8: =SUMIFS($AP$12:$AP$15,$AG$12:$AG$15,"Night Shift") -> 10 | AJ8: =SUMIFS($AJ$12:$AJ$15,$AG$12:$AG$15,"Night Shift") -> 1 | AK8: =SUMIFS($AM$12:$AM$15,$AG$12:$AG$15,"Night Shift")+SUMIFS($AN$12:$AN$15,$AG$12:$AG$15,"Night Shift") -> 0 | AL8: =COUNTIFS(Table1[[#All],[Building]],"DAD1",Table1[[#All],[Shift]],"Night Shift",Table1[[#All],[OFF1]],"OT",Table1[[#All],[Type]],"Support")+COUNTIFS(Table1[[#All],[Building]],"DAD1",Table1[[#All],[Shift]],"Night Shift",Table1[[#All],[OFF1]],"OT",Table1[[#All],[Type]],"Support") -> 0 | AM8: =AI8-AJ8-AK8 -> 9 | AN8: =AM8/AI8 -> 0.9 | AO8: 0.9568 | AP8: =AN8/AO8 -> 0.94063545
A9: Grand Total | B9: =SUM(B6:B8) -> 1241 | C9: =SUM(C6:C8) -> 439 | D9: =SUM(D6:D8) -> 781 | E9: =SUM(E6:E8) -> 43 | F9: =SUM(F6:F8) -> 21 | G9: =SUM(G6:G8) -> 17 | H9: =SUM(H6:H8) -> 721 | I9: =H9/D9 -> 0.92317542 | J9: 0.91101434 | K9: =I9/J9 -> 1.0133489 | S9: Grand Total | T9: =SUM(T6:T8) -> 93 | U9: =SUM(U6:U8) -> 33 | V9: =SUM(V6:V8) -> 60 | W9: =SUM(W6:W8) -> 2 | X9: =SUM(X6:X8) -> 0 | Y9: =SUM(Y6:Y8) -> 0 | Z9: =SUM(Z6:Z8) -> 58 | AA9: =Z9/V9 -> 0.96666667 | AB9: 0.93774194 | AC9: =AA9/AB9 -> 1.0308451 | AF9: Grand Total | AG9: =SUM(AG6:AG8) -> 12 | AH9: =SUM(AH6:AH8) -> 2 | AI9: =SUM(AI6:AI8) -> 10 | AJ9: =SUM(AJ6:AJ8) -> 1 | AK9: =SUM(AK6:AK8) -> 0 | AL9: =SUM(AL6:AL8) -> 0 | AM9: =SUM(AM6:AM8) -> 9 | AN9: =AM9/AI9 -> 0.9 | AO9: =AVERAGE(AO6,AO7,AO8) -> 0.95483333 | AP9: =AN9/AO9 -> 0.94257287
A11: Department | B11: Shift | C11: 0 | D11: OFF | E11: PL | F11: OT | G11: Present(Including OT) | H11: SL | I11: AB/ABWI | J11: Grand Total | K11: Scheduled | L11: Target | M11: Actual (without OT) | N11: Actual (with OT) | O11: HC As per Target % | P11: Actual HC Achived Without OT | Q11: Delta | S11: Department | T11: Shift | U11: 0 | V11: OFF | W11: PL | X11: OT | Y11: Present | Z11: SL | AA11: AB/ABWI | AB11: Grand Total | AC11: Scheduled | AD11: % | AF11: Department | AG11: Shift | AH11: 0 | AI11: OFF | AJ11: PL | AK11: Present | AL11: OT | AM11: SL | AN11: AB/ABWI | AO11: Grand Total | AP11: Scheduled | AQ11: %
A12: ICQA | B12: Day Shift | C12: =COUNTIFS(Roster!T:T,"0",Roster!O:O,"ICQA",Roster!J:J,"Day Shift",Roster!P:P,"Direct",Roster!G:G,"AUH1") -> 0 | D12: =COUNTIFS(Roster!T:T,"OFF",Roster!O:O,"ICQA",Roster!J:J,"Day Shift",Roster!P:P,"Direct",Roster!G:G,"AUH1") -> 10 | E12: =COUNTIFS(Roster!T:T,"PL",Roster!O:O,"ICQA",Roster!J:J,"Day Shift",Roster!P:P,"Direct",Roster!G:G,"AUH1") -> 0 | F12: =COUNTIFS(Table1[[#All],[Building]],"AUH1",Table1[[#All],[Shift]],"Day Shift",Table1[[#All],[OFF1]],"OT",Table1[[#All],[Department]],Dashboard!A12)+COUNTIFS(Table1[[#All],[Building]],"AUH1",Table1[[#All],[Shift]],"Day Shift",Table1[[#All],[OFF2]],"OT",Table1[[#All],[Department]],Dashboard!A12) -> 0 | G12: =COUNTIFS(Roster!T:T,"P",Roster!O:O,"ICQA",Roster!J:J,"Day Shift",Roster!P:P,"Direct",Roster!G:G,"AUH1") -> 33 | H12: =COUNTIFS(Roster!T:T,"SL",Roster!O:O,"ICQA",Roster!J:J,"Day Shift",Roster!P:P,"Direct",Roster!G:G,"AUH1") -> 0 | I12: =COUNTIFS(Roster!T:T,"AB",Roster!O:O,"ICQA",Roster!J:J,"Day Shift",Roster!P:P,"Direct",Roster!G:G,"AUH1")+COUNTIFS(Roster!T:T,"ABWI",Roster!O:O,"ICQA",Roster!J:J,"Day Shift",Roster!P:P,"Direct",Roster!G:G,"AUH1") -> 0 | J12: =SUM(G12:I12,)+SUM(C12:E12) -> 43 | K12: =(J12-D12)-C12-F12 -> 33 | L12: 0.87409091 | M12: =(G12-F12)/(K12) -> 1 | N12: =G12/K12 -> 1 | S12: Warehouse Deals | T12: Day Shift | U12: =COUNTIFS(Roster!T:T,"0",Roster!O:O,"Warehouse Deals",Roster!J:J,"Day Shift",Roster!P:P,"Direct",Roster!G:G,"AUH3")+COUNTIFS(Roster!T:T,"0",Roster!O:O,"Warehouse Deals",Roster!J:J,"Day Shift",Roster!P:P,"Direct",Roster!G:G,"DDB1") -> 0 | V12: =COUNTIFS(Roster!T:T,"OFF",Roster!O:O,"Warehouse Deals",Roster!J:J,"Day Shift",Roster!P:P,"Direct",Roster!G:G,"AUH3")+COUNTIFS(Roster!T:T,"OFF",Roster!O:O,"Warehouse Deals",Roster!J:J,"Day Shift",Roster!P:P,"Direct",Roster!G:G,"DDB1") -> 12 | W12: =COUNTIFS(Roster!T:T,"PL",Roster!O:O,"Warehouse Deals",Roster!J:J,"Day Shift",Roster!P:P,"Direct",Roster!G:G,"AUH3")+COUNTIFS(Roster!T:T,"PL",Roster!O:O,"Warehouse Deals",Roster!J:J,"Day Shift",Roster!P:P,"Direct",Roster!G:G,"DDB1") -> 2 | X12: =COUNTIFS(Table1[[#All],[Building]],"AUH3",Table1[[#All],[Shift]],"Day Shift",Table1[[#All],[OFF1]],"OT",Table1[[#All],[Department]],Dashboard!S12)+COUNTIFS(Table1[[#All],[Building]],"AUH3",Table1[[#All],[Shift]],"Day Shift",Table1[[#All],[OFF2]],"OT",Table1[[#All],[Department]],Dashboard!S12) -> 0 | Y12: =COUNTIFS(Roster!T:T,"P",Roster!O:O,"Warehouse Deals",Roster!J:J,"Day Shift",Roster!P:P,"Direct",Roster!G:G,"AUH3")+COUNTIFS(Roster!T:T,"P",Roster!O:O,"Warehouse Deals",Roster!J:J,"Day Shift",Roster!P:P,"Direct",Roster!G:G,"DDB1") -> 25 | Z12: =COUNTIFS(Roster!T:T,"SL",Roster!O:O,"Warehouse Deals",Roster!J:J,"Day Shift",Roster!P:P,"Direct",Roster!G:G,"AUH3")+COUNTIFS(Roster!T:T,"SL",Roster!O:O,"Warehouse Deals",Roster!J:J,"Day Shift",Roster!P:P,"Direct",Roster!G:G,"DDB1") -> 0 | AA12: =COUNTIFS(Roster!T:T,"AB",Roster!O:O,"Warehouse Deals",Roster!J:J,"Day Shift",Roster!P:P,"Direct",Roster!G:G,"AUH3")+COUNTIFS(Roster!T:T,"AB",Roster!O:O,"Warehouse Deals",Roster!J:J,"Day Shift",Roster!P:P,"Direct",Roster!G:G,"DDB1")+COUNTIFS(Roster!T:T,"ABWI",Roster!O:O,"Warehouse Deals",Roster!J:J,"Day Shift",Roster!P:P,"Direct",Roster!G:G,"AUH3")+COUNTIFS(Roster!T:T,"ABWI",Roster!O:O,"Warehouse Deals",Roster!J:J,"Day Shift",Roster!P:P,"Direct",Roster!G:G,"DDB1") -> 0 | AB12: =SUM(Y12:AA12,)+SUM(U12:W12) -> 39 | AC12: =(AB12-V12)-U12-X12 -> 27 | AD12: =Y12/AC12 -> 0.92592593 | AF12: Warehouse Deals | AG12: Day Shift | AH12: =COUNTIFS(Roster!T:T,"0",Roster!O:O,"Warehouse Deals",Roster!J:J,"Day Shift",Roster!P:P,"Support",Roster!G:G,"DAD1") -> 0 | AI12: =COUNTIFS(Roster!T:T,"OFF",Roster!O:O,"Warehouse Deals",Roster!J:J,"Day Shift",Roster!P:P,"Support",Roster!G:G,"DAD1") -> 0 | AJ12: =COUNTIFS(Roster!T:T,"PL",Roster!O:O,"Warehouse Deals",Roster!J:J,"Day Shift",Roster!P:P,"Support",Roster!G:G,"DAD1") -> 0 | AK12: =COUNTIFS(Roster!T:T,"P",Roster!O:O,"Warehouse Deals",Roster!J:J,"Day Shift",Roster!P:P,"Support",Roster!G:G,"DAD1") -> 0 | AL12: =COUNTIFS(Table1[[#All],[Building]],"DAD1",Table1[[#All],[Shift]],"Day Shift",Table1[[#All],[OFF1]],"OT",Table1[[#All],[Type]],"Support")+COUNTIFS(Table1[[#All],[Building]],"DAD1",Table1[[#All],[Shift]],"Day Shift",Table1[[#All],[OFF2]],"OT",Table1[[#All],[Type]],"Support") -> 0 | AM12: =COUNTIFS(Roster!T:T,"SL",Roster!O:O,"Warehouse Deals",Roster!J:J,"Day Shift",Roster!P:P,"Support",Roster!G:G,"DAD1") -> 0 | AN12: =COUNTIFS(Roster!T:T,"AB",Roster!O:O,"Warehouse Deals",Roster!J:J,"Day Shift",Roster!P:P,"Support",Roster!G:G,"DAD1")+COUNTIFS(Roster!T:T,"ABWI",Roster!O:O,"Warehouse Deals",Roster!J:J,"Day Shift",Roster!P:P,"Support",Roster!G:G,"DAD1") -> 0 | AO12: =SUM(AM12:AN12,)+SUM(AH12:AK12) -> 0 | AP12: =(AO12-AI12)-AH12 -> 0 | AQ12: =AK12/AP12 -> #DIV/0!
B13: Mid Shift | C13: 0 | D13: =COUNTIFS(Roster!T:T,"OFF",Roster!O:O,"ICQA",Roster!J:J,"Mid Shift",Roster!P:P,"Direct",Roster!G:G,"AUH1") -> 0 | E13: =COUNTIFS(Roster!T:T,"PL",Roster!O:O,"ICQA",Roster!J:J,"Mid Shift",Roster!P:P,"Direct",Roster!G:G,"AUH1") -> 0 | F13: =COUNTIFS(Table1[[#All],[Building]],"AUH1",Table1[[#All],[Shift]],"Mid Shift",Table1[[#All],[OFF1]],"OT",Table1[[#All],[Department]],Dashboard!A12)+COUNTIFS(Table1[[#All],[Building]],"AUH1",Table1[[#All],[Shift]],"Mid Shift",Table1[[#All],[OFF2]],"OT",Table1[[#All],[Department]],Dashboard!A12) -> 0 | G13: =COUNTIFS(Roster!T:T,"P",Roster!O:O,"ICQA",Roster!J:J,"Mid Shift",Roster!P:P,"Direct",Roster!G:G,"AUH1") -> 0 | H13: =COUNTIFS(Roster!T:T,"SL",Roster!O:O,"ICQA",Roster!J:J,"Mid Shift",Roster!P:P,"Direct",Roster!G:G,"AUH1") -> 0 | I13: =COUNTIFS(Roster!T:T,"AB",Roster!O:O,"ICQA",Roster!J:J,"Mid Shift",Roster!P:P,"Direct",Roster!G:G,"AUH1")+COUNTIFS(Roster!T:T,"ABWI",Roster!O:O,"ICQA",Roster!J:J,"Mid Shift",Roster!P:P,"Direct",Roster!G:G,"AUH1") -> 0 | J13: =SUM(G13:I13,)+SUM(C13:E13) -> 0 | K13: =(J13-D13)-C13-F13 -> 0 | M13: =(G13-F13)/(K13) -> #DIV/0! | N13: =(H13-G13)/(L13) -> #DIV/0! | T13: Mid Shift | U13: =COUNTIFS(Roster!T:T,"0",Roster!O:O,"Warehouse Deals",Roster!J:J,"Mid Shift",Roster!P:P,"Direct",Roster!G:G,"AUH3")+COUNTIFS(Roster!T:T,"0",Roster!O:O,"Warehouse Deals",Roster!J:J,"Mid Shift",Roster!P:P,"Direct",Roster!G:G,"DDB1") -> 0 | V13: =COUNTIFS(Roster!T:T,"OFF",Roster!O:O,"Warehouse Deals",Roster!J:J,"Mid Shift",Roster!P:P,"Direct",Roster!G:G,"AUH3")+COUNTIFS(Roster!T:T,"OFF",Roster!O:O,"Warehouse Deals",Roster!J:J,"Mid Shift",Roster!P:P,"Direct",Roster!G:G,"DDB1") -> 0 | W13: =COUNTIFS(Roster!T:T,"PL",Roster!O:O,"Warehouse Deals",Roster!J:J,"Mid Shift",Roster!P:P,"Direct",Roster!G:G,"AUH3")+COUNTIFS(Roster!T:T,"PL",Roster!O:O,"Warehouse Deals",Roster!J:J,"Mid Shift",Roster!P:P,"Direct",Roster!G:G,"DDB1") -> 0 | X13: =COUNTIFS(Table1[[#All],[Building]],"AUH3",Table1[[#All],[Shift]],"Mid Shift",Table1[[#All],[OFF1]],"OT",Table1[[#All],[Department]],Dashboard!S12)+COUNTIFS(Table1[[#All],[Building]],"AUH3",Table1[[#All],[Shift]],"Mid Shift",Table1[[#All],[OFF2]],"OT",Table1[[#All],[Department]],Dashboard!S12) -> 0 | Y13: =COUNTIFS(Roster!T:T,"P",Roster!O:O,"Warehouse Deals",Roster!J:J,"Mid Shift",Roster!P:P,"Direct",Roster!G:G,"AUH3")+COUNTIFS(Roster!T:T,"P",Roster!O:O,"Warehouse Deals",Roster!J:J,"Mid Shift",Roster!P:P,"Direct",Roster!G:G,"DDB1") -> 0 | Z13: =COUNTIFS(Roster!T:T,"SL",Roster!O:O,"Warehouse Deals",Roster!J:J,"Mid Shift",Roster!P:P,"Direct",Roster!G:G,"AUH3")+COUNTIFS(Roster!T:T,"SL",Roster!O:O,"Warehouse Deals",Roster!J:J,"Mid Shift",Roster!P:P,"Direct",Roster!G:G,"DDB1") -> 0 | AA13: =COUNTIFS(Roster!T:T,"AB",Roster!O:O,"Warehouse Deals",Roster!J:J,"Mid Shift",Roster!P:P,"Direct",Roster!G:G,"AUH3")+COUNTIFS(Roster!T:T,"AB",Roster!O:O,"Warehouse Deals",Roster!J:J,"Mid Shift",Roster!P:P,"Direct",Roster!G:G,"DDB1")+COUNTIFS(Roster!T:T,"ABWI",Roster!O:O,"Warehouse Deals",Roster!J:J,"Mid Shift",Roster!P:P,"Direct",Roster!G:G,"AUH3")+COUNTIFS(Roster!T:T,"ABWI",Roster!O:O,"Warehouse Deals",Roster!J:J,"Mid Shift",Roster!P:P,"Direct",Roster!G:G,"DDB1") -> 0 | AB13: =SUM(Y13:AA13,)+SUM(U13:W13) -> 0 | AC13: =(AB13-V13)-U13-X13 -> 0 | AD13: =Y13/AC13 -> #DIV/0! | AG13: Mid Shift | AH13: =COUNTIFS(Roster!T:T,"0",Roster!O:O,"Warehouse Deals",Roster!J:J,"Mid Shift",Roster!P:P,"Support",Roster!G:G,"DAD1") -> 0 | AI13: =COUNTIFS(Roster!T:T,"OFF",Roster!O:O,"Warehouse Deals",Roster!J:J,"Mid Shift",Roster!P:P,"Support",Roster!G:G,"DAD1") -> 0 | AJ13: =COUNTIFS(Roster!T:T,"PL",Roster!O:O,"Warehouse Deals",Roster!J:J,"Mid Shift",Roster!P:P,"Support",Roster!G:G,"DAD1") -> 0 | AK13: =COUNTIFS(Roster!T:T,"P",Roster!O:O,"Warehouse Deals",Roster!J:J,"Mid Shift",Roster!P:P,"Support",Roster!G:G,"DAD1") -> 0 | AL13: =COUNTIFS(Table1[[#All],[Building]],"DAD1",Table1[[#All],[Shift]],"Mid Shift",Table1[[#All],[OFF1]],"OT",Table1[[#All],[Type]],"Direct")+COUNTIFS(Table1[[#All],[Building]],"DAD1",Table1[[#All],[Shift]],"Mid Shift",Table1[[#All],[OFF2]],"OT",Table1[[#All],[Type]],"Direct") -> 0 | AM13: =COUNTIFS(Roster!T:T,"SL",Roster!O:O,"Warehouse Deals",Roster!J:J,"Mid Shift",Roster!P:P,"Support",Roster!G:G,"DAD1") -> 0 | AN13: =COUNTIFS(Roster!T:T,"AB",Roster!O:O,"Warehouse Deals",Roster!J:J,"Mid Shift",Roster!P:P,"Support",Roster!G:G,"DAD1")+COUNTIFS(Roster!T:T,"ABWI",Roster!O:O,"Warehouse Deals",Roster!J:J,"Mid Shift",Roster!P:P,"Support",Roster!G:G,"DAD1") -> 0 | AO13: =SUM(AM13:AN13,)+SUM(AH13:AK13) -> 0 | AP13: =(AO13-AI13)-AH13 -> 0 | AQ13: =AK13/AP13 -> #DIV/0!
B14: Night Shift | C14: =COUNTIFS(Roster!T:T,"0",Roster!O:O,"ICQA",Roster!J:J,"Night Shift",Roster!P:P,"Direct",Roster!G:G,"AUH1") -> 0 | D14: =COUNTIFS(Roster!T:T,"OFF",Roster!O:O,"ICQA",Roster!J:J,"Night Shift",Roster!P:P,"Direct",Roster!G:G,"AUH1") -> 3 | E14: =COUNTIFS(Roster!T:T,"PL",Roster!O:O,"ICQA",Roster!J:J,"Night Shift",Roster!P:P,"Direct",Roster!G:G,"AUH1") -> 0 | F14: =COUNTIFS(Table1[[#All],[Building]],"AUH1",Table1[[#All],[Shift]],"Night Shift",Table1[[#All],[OFF1]],"OT",Table1[[#All],[Department]],Dashboard!A12)+COUNTIFS(Table1[[#All],[Building]],"AUH1",Table1[[#All],[Shift]],"Night Shift",Table1[[#All],[OFF2]],"OT",Table1[[#All],[Department]],Dashboard!A12) -> 0 | G14: =COUNTIFS(Roster!T:T,"P",Roster!O:O,"ICQA",Roster!J:J,"Night Shift",Roster!P:P,"Direct",Roster!G:G,"AUH1") -> 4 | H14: =COUNTIFS(Roster!T:T,"SL",Roster!O:O,"ICQA",Roster!J:J,"Night Shift",Roster!P:P,"Direct",Roster!G:G,"AUH1") -> 0 | I14: =COUNTIFS(Roster!T:T,"AB",Roster!O:O,"ICQA",Roster!J:J,"Night Shift",Roster!P:P,"Direct",Roster!G:G,"AUH1")+COUNTIFS(Roster!T:T,"ABWI",Roster!O:O,"ICQA",Roster!J:J,"Night Shift",Roster!P:P,"Direct",Roster!G:G,"AUH1") -> 0 | J14: =SUM(G14:I14,)+SUM(C14:E14) -> 7 | K14: =(J14-D14)-C14-F14 -> 4 | L14: 0.965 | M14: =(G14-F14)/(K14) -> 1 | N14: =G14/K14 -> 1 | T14: Night Shift | U14: =COUNTIFS(Roster!T:T,"0",Roster!O:O,"Warehouse Deals",Roster!J:J,"Mid Shift",Roster!P:P,"Direct",Roster!G:G,"AUH3")+COUNTIFS(Roster!T:T,"0",Roster!O:O,"Warehouse Deals",Roster!J:J,"Mid Shift",Roster!P:P,"Direct",Roster!G:G,"DDB1") -> 0 | V14: =COUNTIFS(Roster!T:T,"OFF",Roster!O:O,"Warehouse Deals",Roster!J:J,"Night Shift",Roster!P:P,"Direct",Roster!G:G,"AUH3")+COUNTIFS(Roster!T:T,"OFF",Roster!O:O,"Warehouse Deals",Roster!J:J,"Night Shift",Roster!P:P,"Direct",Roster!G:G,"DDB1") -> 21 | W14: =COUNTIFS(Roster!T:T,"PL",Roster!O:O,"Warehouse Deals",Roster!J:J,"Night Shift",Roster!P:P,"Direct",Roster!G:G,"AUH3")+COUNTIFS(Roster!T:T,"PL",Roster!O:O,"Warehouse Deals",Roster!J:J,"Night Shift",Roster!P:P,"Direct",Roster!G:G,"DDB1") -> 0 | X14: =COUNTIFS(Table1[[#All],[Building]],"AUH3",Table1[[#All],[Shift]],"Night Shift",Table1[[#All],[OFF1]],"OT",Table1[[#All],[Department]],Dashboard!S12)+COUNTIFS(Table1[[#All],[Building]],"AUH3",Table1[[#All],[Shift]],"Night Shift",Table1[[#All],[OFF2]],"OT",Table1[[#All],[Department]],Dashboard!S12) -> 0 | Y14: =COUNTIFS(Roster!T:T,"P",Roster!O:O,"Warehouse Deals",Roster!J:J,"Night Shift",Roster!P:P,"Direct",Roster!G:G,"AUH3")+COUNTIFS(Roster!T:T,"P",Roster!O:O,"Warehouse Deals",Roster!J:J,"Night Shift",Roster!P:P,"Direct",Roster!G:G,"DDB1") -> 33 | Z14: =COUNTIFS(Roster!T:T,"SL",Roster!O:O,"Warehouse Deals",Roster!J:J,"Night Shift",Roster!P:P,"Direct",Roster!G:G,"AUH3")+COUNTIFS(Roster!T:T,"SL",Roster!O:O,"Warehouse Deals",Roster!J:J,"Night Shift",Roster!P:P,"Direct",Roster!G:G,"DDB1") -> 0 | AA14: =COUNTIFS(Roster!T:T,"AB",Roster!O:O,"Warehouse Deals",Roster!J:J,"Night Shift",Roster!P:P,"Direct",Roster!G:G,"AUH3")+COUNTIFS(Roster!T:T,"AB",Roster!O:O,"Warehouse Deals",Roster!J:J,"Night Shift",Roster!P:P,"Direct",Roster!G:G,"DDB1")+COUNTIFS(Roster!T:T,"ABWI",Roster!O:O,"Warehouse Deals",Roster!J:J,"Night Shift",Roster!P:P,"Direct",Roster!G:G,"AUH3")+COUNTIFS(Roster!T:T,"ABWI",Roster!O:O,"Warehouse Deals",Roster!J:J,"Night Shift",Roster!P:P,"Direct",Roster!G:G,"DDB1") -> 0 | AB14: =SUM(Y14:AA14,)+SUM(U14:W14) -> 54 | AC14: =(AB14-V14)-U14-X14 -> 33 | AD14: =Y14/AC14 -> 1 | AG14: Night Shift | AH14: =COUNTIFS(Roster!T:T,"0",Roster!O:O,"Warehouse Deals",Roster!J:J,"Night Shift",Roster!P:P,"Support",Roster!G:G,"DAD1") -> 0 | AI14: =COUNTIFS(Roster!T:T,"OFF",Roster!O:O,"Warehouse Deals",Roster!J:J,"Night Shift",Roster!P:P,"Support",Roster!G:G,"DAD1") -> 2 | AJ14: =COUNTIFS(Roster!T:T,"PL",Roster!O:O,"Warehouse Deals",Roster!J:J,"Night Shift",Roster!P:P,"Support",Roster!G:G,"DAD1") -> 1 | AK14: =COUNTIFS(Roster!T:T,"P",Roster!O:O,"Warehouse Deals",Roster!J:J,"Night Shift",Roster!P:P,"Support",Roster!G:G,"DAD1") -> 9 | AL14: =COUNTIFS(Table1[[#All],[Building]],"DAD1",Table1[[#All],[Shift]],"Night Shift",Table1[[#All],[OFF1]],"OT",Table1[[#All],[Type]],"Support")+COUNTIFS(Table1[[#All],[Building]],"DAD1",Table1[[#All],[Shift]],"Night Shift",Table1[[#All],[OFF1]],"OT",Table1[[#All],[Type]],"Support") -> 0 | AM14: =COUNTIFS(Roster!T:T,"SL",Roster!O:O,"Warehouse Deals",Roster!J:J,"Night Shift",Roster!P:P,"Support",Roster!G:G,"DAD1") -> 0 | AN14: =COUNTIFS(Roster!T:T,"AB",Roster!O:O,"Warehouse Deals",Roster!J:J,"Night Shift",Roster!P:P,"Support",Roster!G:G,"DAD1")+COUNTIFS(Roster!T:T,"ABWI",Roster!O:O,"Warehouse Deals",Roster!J:J,"Night Shift",Roster!P:P,"Support",Roster!G:G,"DAD1") -> 0 | AO14: =SUM(AM14:AN14,)+SUM(AH14:AK14) -> 12 | AP14: =(AO14-AI14)-AH14 -> 10 | AQ14: =AK14/AP14 -> 0.9
A15: ICQA Total | C15: =SUM(C12:C14) -> 0 | D15: =SUM(D12:D14) -> 13 | E15: =SUM(E12:E14) -> 0 | F15: =SUM(F12:F14) -> 0 | G15: =SUM(G12:G14) -> 37 | H15: =SUM(H12:H14) -> 0 | I15: =SUM(I12:I14) -> 0 | J15: =SUM(J12:J14) -> 50 | K15: =SUM(K12:K14) -> 37 | L15: 0.88391892 | M15: =(G15-F15)/(K15) -> 1 | N15: =G15/K15 -> 1 | O15: =L15*K15 -> 32.705 | P15: =G15-F15 -> 37 | Q15: =P15-O15 -> 4.295 | S15: SC Total | U15: =SUM(U12:U14) -> 0 | V15: =SUM(V12:V14) -> 33 | W15: =SUM(W12:W14) -> 2 | X15: =SUM(X12:X14) -> 0 | Y15: =SUM(Y12:Y14) -> 58 | Z15: =SUM(Z12:Z14) -> 0 | AA15: =SUM(AA12:AA14) -> 0 | AB15: =SUM(AB12:AB14) -> 93 | AC15: =SUM(AC12:AC14) -> 60 | AF15: Warehouse Deals | AH15: =SUM(AH12:AH14) -> 0 | AI15: =SUM(AI12:AI14) -> 2 | AJ15: =SUM(AJ12:AJ14) -> 1 | AK15: =SUM(AK12:AK14) -> 9 | AL15: =SUM(AL12:AL14) -> 0 | AM15: =SUM(AM12:AM14) -> 0 | AN15: =SUM(AN12:AN14) -> 0 | AO15: =SUM(AO12:AO14) -> 12 | AP15: =SUM(AP12:AP14) -> 10
A16: Inbound | B16: Day Shift | C16: =COUNTIFS(Roster!T:T,"0",Roster!O:O,"Inbound",Roster!J:J,"Day Shift",Roster!P:P,"Direct",Roster!G:G,"AUH1") -> 0 | D16: =COUNTIFS(Roster!T:T,"OFF",Roster!O:O,"Inbound",Roster!J:J,"Day Shift",Roster!P:P,"Direct",Roster!G:G,"AUH1") -> 156 | E16: =COUNTIFS(Roster!T:T,"PL",Roster!O:O,"Inbound",Roster!J:J,"Day Shift",Roster!P:P,"Direct",Roster!G:G,"AUH1") -> 5 | F16: =COUNTIFS(Table1[[#All],[Building]],"AUH1",Table1[[#All],[Shift]],"Day Shift",Table1[[#All],[OFF1]],"OT",Table1[[#All],[Department]],Dashboard!A16)+COUNTIFS(Table1[[#All],[Building]],"AUH1",Table1[[#All],[Shift]],"Day Shift",Table1[[#All],[OFF2]],"OT",Table1[[#All],[Department]],Dashboard!A16) -> 0 | G16: =COUNTIFS(Roster!T:T,"P",Roster!O:O,"Inbound",Roster!J:J,"Day Shift",Roster!P:P,"Direct",Roster!G:G,"AUH1") -> 68 | H16: =COUNTIFS(Roster!T:T,"SL",Roster!O:O,"Inbound",Roster!J:J,"Day Shift",Roster!P:P,"Direct",Roster!G:G,"AUH1") -> 1 | I16: =COUNTIFS(Roster!T:T,"AB",Roster!O:O,"Inbound",Roster!J:J,"Day Shift",Roster!P:P,"Direct",Roster!G:G,"AUH1")+COUNTIFS(Roster!T:T,"ABWI",Roster!O:O,"Inbound",Roster!J:J,"Day Shift",Roster!P:P,"Direct",Roster!G:G,"AUH1") -> 3 | J16: =SUM(G16:I16,)+SUM(C16:E16) -> 233 | K16: =(J16-D16)-C16-F16 -> 77 | L16: 0.8624359 | M16: =(G16-F16)/(K16) -> 0.88311688 | N16: =G16/K16 -> 0.88311688 | AF16: Grand Total | AH16: =AH15 -> 0 | AI16: =AI15 -> 2 | AJ16: =AJ15 -> 1 | AK16: =AK15 -> 9 | AL16: =AL15 -> 0 | AM16: =AM15 -> 0 | AN16: =AN15 -> 0 | AO16: =AO15 -> 12 | AP16: =AP15 -> 10
B17: Mid Shift | C17: =COUNTIFS(Roster!T:T,"0",Roster!O:O,"Inbound",Roster!J:J,"Mid Shift",Roster!P:P,"Direct",Roster!G:G,"AUH1") -> 0 | D17: =COUNTIFS(Roster!T:T,"OFF",Roster!O:O,"Inbound",Roster!J:J,"Mid Shift",Roster!P:P,"Direct",Roster!G:G,"AUH1") -> 0 | E17: =COUNTIFS(Roster!T:T,"PL",Roster!O:O,"Inbound",Roster!J:J,"Mid Shift",Roster!P:P,"Direct",Roster!G:G,"AUH1") -> 0 | F17: =COUNTIFS(Table1[[#All],[Building]],"AUH1",Table1[[#All],[Shift]],"Mid Shift",Table1[[#All],[OFF1]],"OT",Table1[[#All],[Department]],Dashboard!A16)+COUNTIFS(Table1[[#All],[Building]],"AUH1",Table1[[#All],[Shift]],"Mid Shift",Table1[[#All],[OFF2]],"OT",Table1[[#All],[Department]],Dashboard!A16) -> 0 | G17: =COUNTIFS(Roster!T:T,"P",Roster!O:O,"Inbound",Roster!J:J,"Mid Shift",Roster!P:P,"Direct",Roster!G:G,"AUH1") -> 0 | H17: =COUNTIFS(Roster!T:T,"SL",Roster!O:O,"Inbound",Roster!J:J,"Mid Shift",Roster!P:P,"Direct",Roster!G:G,"AUH1") -> 0 | I17: =COUNTIFS(Roster!T:T,"AB",Roster!O:O,"Inbound",Roster!J:J,"Mid Shift",Roster!P:P,"Direct",Roster!G:G,"AUH1")+COUNTIFS(Roster!T:T,"ABWI",Roster!O:O,"Inbound",Roster!J:J,"Mid Shift",Roster!P:P,"Direct",Roster!G:G,"AUH1") -> 0 | J17: =SUM(G17:I17,)+SUM(C17:E17) -> 0 | K17: =(J17-D17)-C17-F17 -> 0 | M17: =(G17-F17)/(K17) -> #DIV/0! | N17: =G17/K17 -> #DIV/0! | S17: Department | T17: Shift | U17: 0 | V17: OFF | W17: PL | X17: OT | Y17: Present | Z17: SL | AA17: AB/ABWI | AB17: Grand Total | AC17: Scheduled | AD17: %
B18: Night Shift | C18: =COUNTIFS(Roster!T:T,"0",Roster!O:O,"Inbound",Roster!J:J,"Night Shift",Roster!P:P,"Direct",Roster!G:G,"AUH1") -> 0 | D18: =COUNTIFS(Roster!T:T,"OFF",Roster!O:O,"Inbound",Roster!J:J,"Night Shift",Roster!P:P,"Direct",Roster!G:G,"AUH1") -> 40 | E18: =COUNTIFS(Roster!T:T,"PL",Roster!O:O,"Inbound",Roster!J:J,"Night Shift",Roster!P:P,"Direct",Roster!G:G,"AUH1") -> 3 | F18: =COUNTIFS(Table1[[#All],[Building]],"AUH1",Table1[[#All],[Shift]],"Night Shift",Table1[[#All],[OFF1]],"OT",Table1[[#All],[Department]],Dashboard!A16)+COUNTIFS(Table1[[#All],[Building]],"AUH1",Table1[[#All],[Shift]],"Night Shift",Table1[[#All],[OFF2]],"OT",Table1[[#All],[Department]],Dashboard!A16) -> 0 | G18: =COUNTIFS(Roster!T:T,"P",Roster!O:O,"Inbound",Roster!J:J,"Night Shift",Roster!P:P,"Direct",Roster!G:G,"AUH1") -> 41 | H18: =COUNTIFS(Roster!T:T,"SL",Roster!O:O,"Inbound",Roster!J:J,"Night Shift",Roster!P:P,"Direct",Roster!G:G,"AUH1") -> 0 | I18: =COUNTIFS(Roster!T:T,"AB",Roster!O:O,"Inbound",Roster!J:J,"Night Shift",Roster!P:P,"Direct",Roster!G:G,"AUH1")+COUNTIFS(Roster!T:T,"ABWI",Roster!O:O,"Inbound",Roster!J:J,"Night Shift",Roster!P:P,"Direct",Roster!G:G,"AUH1") -> 1 | J18: =SUM(G18:I18,)+SUM(C18:E18) -> 85 | K18: =(J18-D18)-C18-F18 -> 45 | L18: 0.87611111 | M18: =(G18-F18)/(K18) -> 0.91111111 | N18: =G18/K18 -> 0.91111111 | S18: Warehouse Deals | T18: Regular | U18: =COUNTIFS(Roster!G:G,"AUH3",Roster!P:P,"Direct",Roster!T:T,"0",Roster!E:E,"Regular")+COUNTIFS(Roster!G:G,"DDB1",Roster!P:P,"Direct",Roster!T:T,"0",Roster!E:E,"Regular") -> 0 | V18: =COUNTIFS(Roster!G:G,"AUH3",Roster!P:P,"Direct",Roster!T:T,"OFF",Roster!E:E,"Regular")+COUNTIFS(Roster!G:G,"DDB1",Roster!P:P,"Direct",Roster!T:T,"OFF",Roster!E:E,"Regular") -> 5 | W18: =COUNTIFS(Roster!G:G,"AUH3",Roster!P:P,"Direct",Roster!T:T,"PL",Roster!E:E,"Regular")+COUNTIFS(Roster!G:G,"DDB1",Roster!P:P,"Direct",Roster!T:T,"PL",Roster!E:E,"Regular") -> 0 | X18: =COUNTIFS(Table1[[#All],[Building]],"AUH3",Table1[[#All],[Employment Type]],"Regular",Table1[[#All],[OFF1]],"OT",Table1[[#All],[Department]],Dashboard!S18)+COUNTIFS(Table1[[#All],[Building]],"AUH3",Table1[[#All],[Employment Type]],"Regular",Table1[[#All],[OFF2]],"OT",Table1[[#All],[Department]],Dashboard!S18) -> 0 | Y18: =COUNTIFS(Roster!G:G,"AUH3",Roster!P:P,"Direct",Roster!T:T,"P",Roster!E:E,"Regular")+COUNTIFS(Roster!G:G,"DDB1",Roster!P:P,"Direct",Roster!T:T,"P",Roster!E:E,"Regular") -> 9 | Z18: =COUNTIFS(Roster!G:G,"AUH3",Roster!P:P,"Direct",Roster!T:T,"SL",Roster!E:E,"Regular")+COUNTIFS(Roster!G:G,"DDB1",Roster!P:P,"Direct",Roster!T:T,"SL",Roster!E:E,"Regular") -> 0 | AA18: =COUNTIFS(Roster!G:G,"AUH3",Roster!P:P,"Direct",Roster!T:T,"AB",Roster!E:E,"Regular")+COUNTIFS(Roster!G:G,"DDB1",Roster!P:P,"Direct",Roster!T:T,"AB",Roster!E:E,"Regular")+COUNTIFS(Roster!G:G,"AUH3",Roster!P:P,"Direct",Roster!T:T,"ABWI",Roster!E:E,"Regular")+COUNTIFS(Roster!G:G,"DDB1",Roster!P:P,"Direct",Roster!T:T,"ABWI",Roster!E:E,"Regular") -> 0 | AB18: =SUM(Y18:AA18,)+SUM(U18:W18) -> 14 | AC18: =(AB18-V18)-U18 -> 9 | AD18: =Y18/AC18 -> 1 | AL18: =1443+83 -> 1526
A19: Inbound Total | C19: =SUM(C16:C18) -> 0 | D19: =SUM(D16:D18) -> 196 | E19: =SUM(E16:E18) -> 8 | F19: =SUM(F16:F18) -> 0 | G19: =SUM(G16:G18) -> 109 | H19: =SUM(H16:H18) -> 1 | I19: =SUM(I16:I18) -> 4 | J19: =SUM(J16:J18) -> 318 | K19: =SUM(K16:K18) -> 122 | L19: 0.86743902 | M19: =(G19-F19)/(K19) -> 0.89344262 | N19: =G19/K19 -> 0.89344262 | O19: =L19*K19 -> 105.82756 | P19: =G19-F19 -> 109 | Q19: =P19-O19 -> 3.172439 | T19: Temporary | U19: =COUNTIFS(Roster!G:G,"AUH3",Roster!P:P,"Direct",Roster!T:T,"0",Roster!E:E,"Temporary")+COUNTIFS(Roster!G:G,"DDB1",Roster!P:P,"Direct",Roster!T:T,"0",Roster!E:E,"Temporary") -> 0 | V19: =COUNTIFS(Roster!G:G,"AUH3",Roster!P:P,"Direct",Roster!T:T,"OFF",Roster!E:E,"Temporary")+COUNTIFS(Roster!G:G,"DDB1",Roster!P:P,"Direct",Roster!T:T,"OFF",Roster!E:E,"Temporary") -> 28 | W19: =COUNTIFS(Roster!G:G,"AUH3",Roster!P:P,"Direct",Roster!T:T,"PL",Roster!E:E,"Temporary")+COUNTIFS(Roster!G:G,"DDB1",Roster!P:P,"Direct",Roster!T:T,"PL",Roster!E:E,"Temporary") -> 2 | X19: =COUNTIFS(Table1[[#All],[Building]],"AUH3",Table1[[#All],[Employment Type]],"Temporary",Table1[[#All],[OFF1]],"OT",Table1[[#All],[Department]],Dashboard!S18)+COUNTIFS(Table1[[#All],[Building]],"AUH3",Table1[[#All],[Employment Type]],"Temporary",Table1[[#All],[OFF2]],"OT",Table1[[#All],[Department]],Dashboard!S18) -> 0 | Y19: =COUNTIFS(Roster!G:G,"AUH3",Roster!P:P,"Direct",Roster!T:T,"P",Roster!E:E,"Temporary")+COUNTIFS(Roster!G:G,"DDB1",Roster!P:P,"Direct",Roster!T:T,"P",Roster!E:E,"Temporary") -> 49 | Z19: =COUNTIFS(Roster!G:G,"AUH3",Roster!P:P,"Direct",Roster!T:T,"SL",Roster!E:E,"Temporary")+COUNTIFS(Roster!G:G,"DDB1",Roster!P:P,"Direct",Roster!T:T,"SL",Roster!E:E,"Temporary") -> 0 | AA19: =COUNTIFS(Roster!G:G,"AUH3",Roster!P:P,"Direct",Roster!T:T,"AB",Roster!E:E,"Temporary")+COUNTIFS(Roster!G:G,"DDB1",Roster!P:P,"Direct",Roster!T:T,"AB",Roster!E:E,"Temporary")+COUNTIFS(Roster!G:G,"AUH3",Roster!P:P,"Direct",Roster!T:T,"ABWI",Roster!E:E,"Temporary")+COUNTIFS(Roster!G:G,"DDB1",Roster!P:P,"Direct",Roster!T:T,"ABWI",Roster!E:E,"Temporary") -> 0 | AB19: =SUM(Y19:AA19,)+SUM(U19:W19) -> 79 | AC19: =(AB19-V19)-U19 -> 51 | AD19: =Y19/AC19 -> 0.96078431
A20: Outbound | B20: Day Shift | C20: =COUNTIFS(Roster!T:T,"0",Roster!O:O,"Outbound",Roster!J:J,"Day Shift",Roster!P:P,"Direct",Roster!G:G,"AUH1") -> 0 | D20: =COUNTIFS(Roster!T:T,"OFF",Roster!O:O,"Outbound",Roster!J:J,"Day Shift",Roster!P:P,"Direct",Roster!G:G,"AUH1") -> 69 | E20: =COUNTIFS(Roster!T:T,"PL",Roster!O:O,"Outbound",Roster!J:J,"Day Shift",Roster!P:P,"Direct",Roster!G:G,"AUH1") -> 14 | F20: =COUNTIFS(Table1[[#All],[Building]],"AUH1",Table1[[#All],[Shift]],"Day Shift",Table1[[#All],[OFF1]],"OT",Table1[[#All],[Department]],Dashboard!A20)+COUNTIFS(Table1[[#All],[Building]],"AUH1",Table1[[#All],[Shift]],"Day Shift",Table1[[#All],[OFF2]],"OT",Table1[[#All],[Department]],Dashboard!A20) -> 7 | G20: =COUNTIFS(Roster!T:T,"P",Roster!O:O,"Outbound",Roster!J:J,"Day Shift",Roster!P:P,"Direct",Roster!G:G,"AUH1") -> 174 | H20: =COUNTIFS(Roster!T:T,"SL",Roster!O:O,"Outbound",Roster!J:J,"Day Shift",Roster!P:P,"Direct",Roster!G:G,"AUH1") -> 3 | I20: =COUNTIFS(Roster!T:T,"AB",Roster!O:O,"Outbound",Roster!J:J,"Day Shift",Roster!P:P,"Direct",Roster!G:G,"AUH1")+COUNTIFS(Roster!T:T,"ABWI",Roster!O:O,"Outbound",Roster!J:J,"Day Shift",Roster!P:P,"Direct",Roster!G:G,"AUH1") -> 4 | J20: =SUM(G20:I20,)+SUM(C20:E20) -> 264 | K20: =(J20-D20)-C20-F20 -> 188 | L20: 0.86440828 | M20: =(G20-F20)/(K20) -> 0.88829787 | N20: =G20/K20 -> 0.92553191 | S20: SC Total | U20: =SUM(U17:U19) -> 0 | V20: =SUM(V17:V19) -> 33 | W20: =SUM(W17:W19) -> 2 | X20: =SUM(X17:X19) -> 0 | Y20: =SUM(Y17:Y19) -> 58 | Z20: =SUM(Z17:Z19) -> 0 | AA20: =SUM(AA17:AA19) -> 0 | AB20: =SUM(AB17:AB19) -> 93 | AC20: =SUM(AC18:AC19) -> 60
B21: Mid Shift | C21: =COUNTIFS(Roster!T:T,"0",Roster!O:O,"Outbound",Roster!J:J,"Mid Shift",Roster!P:P,"Direct",Roster!G:G,"AUH1") -> 0 | D21: =COUNTIFS(Roster!T:T,"OFF",Roster!O:O,"Outbound",Roster!J:J,"Mid Shift",Roster!P:P,"Direct",Roster!G:G,"AUH1") -> 0 | E21: =COUNTIFS(Roster!T:T,"PL",Roster!O:O,"Outbound",Roster!J:J,"Mid Shift",Roster!P:P,"Direct",Roster!G:G,"AUH1") -> 0 | F21: =COUNTIFS(Table1[[#All],[Building]],"AUH1",Table1[[#All],[Shift]],"Mid Shift",Table1[[#All],[OFF1]],"OT",Table1[[#All],[Department]],Dashboard!A20)+COUNTIFS(Table1[[#All],[Building]],"AUH1",Table1[[#All],[Shift]],"Mid Shift",Table1[[#All],[OFF2]],"OT",Table1[[#All],[Department]],Dashboard!A20) -> 0 | G21: =COUNTIFS(Roster!T:T,"P",Roster!O:O,"Outbound",Roster!J:J,"Mid Shift",Roster!P:P,"Direct",Roster!G:G,"AUH1") -> 0 | H21: =COUNTIFS(Roster!T:T,"SL",Roster!O:O,"Outbound",Roster!J:J,"Mid Shift",Roster!P:P,"Direct",Roster!G:G,"AUH1") -> 0 | I21: =COUNTIFS(Roster!T:T,"AB",Roster!O:O,"Outbound",Roster!J:J,"Mid Shift",Roster!P:P,"Direct",Roster!G:G,"AUH1")+COUNTIFS(Roster!T:T,"ABWI",Roster!O:O,"Outbound",Roster!J:J,"Mid Shift",Roster!P:P,"Direct",Roster!G:G,"AUH1") -> 0 | J21: =SUM(G21:I21,)+SUM(C21:E21) -> 0 | K21: =(J21-D21)-C21-F21 -> 0 | M21: =(G21-F21)/(K21) -> #DIV/0! | N21: =G21/K21 -> #DIV/0!
B22: Night Shift | C22: =COUNTIFS(Roster!T:T,"0",Roster!O:O,"Outbound",Roster!J:J,"Night Shift",Roster!P:P,"Direct",Roster!G:G,"AUH1") -> 0 | D22: =COUNTIFS(Roster!T:T,"OFF",Roster!O:O,"Outbound",Roster!J:J,"Night Shift",Roster!P:P,"Direct",Roster!G:G,"AUH1") -> 94 | E22: =COUNTIFS(Roster!T:T,"PL",Roster!O:O,"Outbound",Roster!J:J,"Night Shift",Roster!P:P,"Direct",Roster!G:G,"AUH1") -> 11 | F22: =COUNTIFS(Table1[[#All],[Building]],"AUH1",Table1[[#All],[Shift]],"Night Shift",Table1[[#All],[OFF1]],"OT",Table1[[#All],[Department]],Dashboard!A20)+COUNTIFS(Table1[[#All],[Building]],"AUH1",Table1[[#All],[Shift]],"Night Shift",Table1[[#All],[OFF2]],"OT",Table1[[#All],[Department]],Dashboard!A20) -> 14 | G22: =COUNTIFS(Roster!T:T,"P",Roster!O:O,"Outbound",Roster!J:J,"Night Shift",Roster!P:P,"Direct",Roster!G:G,"AUH1") -> 283 | H22: =COUNTIFS(Roster!T:T,"SL",Roster!O:O,"Outbound",Roster!J:J,"Night Shift",Roster!P:P,"Direct",Roster!G:G,"AUH1") -> 0 | I22: =COUNTIFS(Roster!T:T,"AB",Roster!O:O,"Outbound",Roster!J:J,"Night Shift",Roster!P:P,"Direct",Roster!G:G,"AUH1")+COUNTIFS(Roster!T:T,"ABWI",Roster!O:O,"Outbound",Roster!J:J,"Night Shift",Roster!P:P,"Direct",Roster!G:G,"AUH1") -> 3 | J22: =SUM(G22:I22,)+SUM(C22:E22) -> 391 | K22: =(J22-D22)-C22-F22 -> 283 | L22: 0.90905594 | M22: =(G22-F22)/(K22) -> 0.95053004 | N22: =G22/K22 -> 1 | S22: Shift | T22: Total HC | U22: Unscheduled | V22: Schedule to Work | W22: PL | X22: OT | Y22: UPL | Z22: Present | AA22: Present % | AB22: LM Target | AC22: Target Achievement
A23: Outbound Total | C23: =SUM(C20:C22) -> 0 | D23: =SUM(D20:D22) -> 163 | E23: =SUM(E20:E22) -> 25 | F23: =SUM(F20:F22) -> 21 | G23: =SUM(G20:G22) -> 457 | H23: =SUM(H20:H22) -> 3 | I23: =SUM(I20:I22) -> 7 | J23: =SUM(J20:J22) -> 655 | K23: =SUM(K20:K22) -> 471 | L23: 0.89247253 | M23: =(G23-F23)/(K23) -> 0.92569002 | N23: =G23/K23 -> 0.97027601 | O23: =L23*K23 -> 420.35456 | P23: =G23-F23 -> 436 | Q23: =P23-O23 -> 15.64544 | S23: Regular | T23: =COUNTIFS(Roster!G:G,"AUH3",Roster!E:E,"Regular")+COUNTIFS(Roster!G:G,"DDB1",Roster!E:E,"Regular",Roster!P:P,"Direct") -> 14 | U23: =COUNTIFS(Roster!G:G,"AUH3",Roster!E:E,"Regular",Roster!T:T,"OFF",Roster!P:P,"Direct")+COUNTIFS(Roster!G:G,"DDB1",Roster!E:E,"Regular",Roster!T:T,"OFF",Roster!P:P,"Direct") -> 5 | V23: =SUMIFS($AC$18:$AC$19,$T$18:$T$19,"Regular") -> 9 | W23: =COUNTIFS(Roster!G:G,"AUH3",Roster!E:E,"Regular",Roster!T:T,"PL",Roster!P:P,"Direct")+COUNTIFS(Roster!G:G,"DDB1",Roster!E:E,"Regular",Roster!T:T,"PL",Roster!P:P,"Direct") -> 0 | X23: =COUNTIFS(Table1[[#All],[Building]],"AUH3",Table1[[#All],[Employment Type]],"Regular",Table1[[#All],[OFF1]],"OT",Table1[[#All],[Department]],Dashboard!S23)+COUNTIFS(Table1[[#All],[Building]],"AUH3",Table1[[#All],[Employment Type]],"Regular",Table1[[#All],[OFF2]],"OT",Table1[[#All],[Department]],Dashboard!S23) -> 0 | Y23: =COUNTIFS(Roster!G:G,"AUH3",Roster!E:E,"Regular",Roster!T:T,"AB",Roster!P:P,"Direct")+COUNTIFS(Roster!G:G,"AUH3",Roster!E:E,"Regular",Roster!T:T,"SL",Roster!P:P,"Direct")+COUNTIFS(Roster!G:G,"AUH3",Roster!E:E,"Regular",Roster!T:T,"ABWI",Roster!P:P,"Direct")+COUNTIFS(Roster!G:G,"DDB1",Roster!E:E,"Regular",Roster!T:T,"ABWI") -> 0 | Z23: =V23-W23-Y23 -> 9 | AA23: =Z23/V23 -> 1 | AB23: 0.92384615 | AC23: =AA23/AB23 -> 1.0824313
A24: CRET | B24: Day Shift | C24: =COUNTIFS(Roster!T:T,"0",Roster!O:O,"CRET",Roster!J:J,"Day Shift",Roster!P:P,"Direct",Roster!G:G,"AUH1") -> 0 | D24: =COUNTIFS(Roster!T:T,"OFF",Roster!O:O,"CRET",Roster!J:J,"Day Shift",Roster!P:P,"Direct",Roster!G:G,"AUH1") -> 41 | E24: =COUNTIFS(Roster!T:T,"PL",Roster!O:O,"CRET",Roster!J:J,"Day Shift",Roster!P:P,"Direct",Roster!G:G,"AUH1") -> 7 | F24: =COUNTIFS(Table1[[#All],[Building]],"AUH1",Table1[[#All],[Shift]],"Day Shift",Table1[[#All],[OFF1]],"OT",Table1[[#All],[Department]],Dashboard!A24)+COUNTIFS(Table1[[#All],[Building]],"AUH1",Table1[[#All],[Shift]],"Day Shift",Table1[[#All],[OFF2]],"OT",Table1[[#All],[Department]],Dashboard!A24) -> 0 | G24: =COUNTIFS(Roster!T:T,"P",Roster!O:O,"CRET",Roster!J:J,"Day Shift",Roster!P:P,"Direct",Roster!G:G,"AUH1") -> 82 | H24: =COUNTIFS(Roster!T:T,"SL",Roster!O:O,"CRET",Roster!J:J,"Day Shift",Roster!P:P,"Direct",Roster!G:G,"AUH1") -> 1 | I24: =COUNTIFS(Roster!T:T,"AB",Roster!O:O,"CRET",Roster!J:J,"Day Shift",Roster!P:P,"Direct",Roster!G:G,"AUH1")+COUNTIFS(Roster!T:T,"ABWI",Roster!O:O,"CRET",Roster!J:J,"Day Shift",Roster!P:P,"Direct",Roster!G:G,"AUH1") -> 1 | J24: =SUM(G24:I24,)+SUM(C24:E24) -> 132 | K24: =(J24-D24)-C24-F24 -> 91 | L24: 0.89978261 | M24: =(G24-F24)/(K24) -> 0.9010989 | N24: =G24/K24 -> 0.9010989 | S24: Temporary | T24: =COUNTIFS(Roster!G:G,"AUH3",Roster!E:E,"Temporary")+COUNTIFS(Roster!G:G,"DDB1",Roster!E:E,"Temporary",Roster!P:P,"Direct") -> 79 | U24: =COUNTIFS(Roster!G:G,"AUH3",Roster!E:E,"Temporary",Roster!T:T,"OFF",Roster!P:P,"Direct")+COUNTIFS(Roster!G:G,"DDB1",Roster!E:E,"Temporary",Roster!T:T,"OFF",Roster!P:P,"Direct") -> 28 | V24: =SUMIFS($AC$18:$AC$19,$T$18:$T$19,"Temporary") -> 51 | W24: =COUNTIFS(Roster!G:G,"AUH3",Roster!E:E,"Temporary",Roster!T:T,"PL",Roster!P:P,"Direct")+COUNTIFS(Roster!G:G,"DDB1",Roster!E:E,"Temporary",Roster!T:T,"PL",Roster!P:P,"Direct") -> 2 | X24: =COUNTIFS(Table1[[#All],[Building]],"AUH3",Table1[[#All],[Employment Type]],"Temporary",Table1[[#All],[OFF1]],"OT",Table1[[#All],[Department]],Dashboard!S23)+COUNTIFS(Table1[[#All],[Building]],"AUH3",Table1[[#All],[Employment Type]],"Temporary",Table1[[#All],[OFF2]],"OT",Table1[[#All],[Department]],Dashboard!S23) -> 0 | Y24: =COUNTIFS(Roster!G:G,"AUH3",Roster!E:E,"Temporary",Roster!T:T,"AB")+COUNTIFS(Roster!G:G,"AUH3",Roster!E:E,"Temporary",Roster!T:T,"SL")+COUNTIFS(Roster!G:G,"AUH3",Roster!E:E,"Temporary",Roster!T:T,"ABWI")+COUNTIFS(Roster!G:G,"DDB1",Roster!E:E,"Temporary",Roster!T:T,"ABWI",Roster!P:P,"Direct") -> 0 | Z24: =V24-W24-Y24 -> 49 | AA24: =Z24/V24 -> 0.96078431 | AB24: 0.90181818 | AC24: =AA24/AB24 -> 1.0653858
B25: Mid Shift | C25: =COUNTIFS(Roster!T:T,"0",Roster!O:O,"CRET",Roster!J:J,"Mid Shift",Roster!P:P,"Direct",Roster!G:G,"AUH1") -> 0 | D25: =COUNTIFS(Roster!T:T,"OFF",Roster!O:O,"CRET",Roster!J:J,"Mid Shift",Roster!P:P,"Direct",Roster!G:G,"AUH1") -> 0 | E25: =COUNTIFS(Roster!T:T,"PL",Roster!O:O,"CRET",Roster!J:J,"Mid Shift",Roster!P:P,"Direct",Roster!G:G,"AUH1") -> 0 | F25: =COUNTIFS(Table1[[#All],[Building]],"AUH1",Table1[[#All],[Shift]],"Mid Shift",Table1[[#All],[OFF1]],"OT",Table1[[#All],[Department]],Dashboard!A24)+COUNTIFS(Table1[[#All],[Building]],"AUH1",Table1[[#All],[Shift]],"Mid Shift",Table1[[#All],[OFF2]],"OT",Table1[[#All],[Department]],Dashboard!A24) -> 0 | G25: =COUNTIFS(Roster!T:T,"P",Roster!O:O,"CRET",Roster!J:J,"Mid Shift",Roster!P:P,"Direct",Roster!G:G,"AUH1") -> 0 | H25: =COUNTIFS(Roster!T:T,"SL",Roster!O:O,"CRET",Roster!J:J,"Mid Shift",Roster!P:P,"Direct",Roster!G:G,"AUH1") -> 0 | I25: =COUNTIFS(Roster!T:T,"AB",Roster!O:O,"CRET",Roster!J:J,"Mid Shift",Roster!P:P,"Direct",Roster!G:G,"AUH1")+COUNTIFS(Roster!T:T,"ABWI",Roster!O:O,"CRET",Roster!J:J,"Mid Shift",Roster!P:P,"Direct",Roster!G:G,"AUH1") -> 0 | J25: =SUM(G25:I25,)+SUM(C25:E25) -> 0 | K25: =(J25-D25)-C25-F25 -> 0 | M25: =(G25-F25)/(K25) -> #DIV/0! | N25: =G25/K25 -> #DIV/0!
B26: Night Shift | C26: =COUNTIFS(Roster!T:T,"0",Roster!O:O,"CRET",Roster!J:J,"Night Shift",Roster!P:P,"Direct",Roster!G:G,"AUH1") -> 0 | D26: =COUNTIFS(Roster!T:T,"OFF",Roster!O:O,"CRET",Roster!J:J,"Night Shift",Roster!P:P,"Direct",Roster!G:G,"AUH1") -> 26 | E26: =COUNTIFS(Roster!T:T,"PL",Roster!O:O,"CRET",Roster!J:J,"Night Shift",Roster!P:P,"Direct",Roster!G:G,"AUH1") -> 3 | F26: =COUNTIFS(Table1[[#All],[Building]],"AUH1",Table1[[#All],[Shift]],"Night Shift",Table1[[#All],[OFF1]],"OT",Table1[[#All],[Department]],Dashboard!A24)+COUNTIFS(Table1[[#All],[Building]],"AUH1",Table1[[#All],[Shift]],"Night Shift",Table1[[#All],[OFF2]],"OT",Table1[[#All],[Department]],Dashboard!A24) -> 0 | G26: =COUNTIFS(Roster!T:T,"P",Roster!O:O,"CRET",Roster!J:J,"Night Shift",Roster!P:P,"Direct",Roster!G:G,"AUH1") -> 57 | H26: =COUNTIFS(Roster!T:T,"SL",Roster!O:O,"CRET",Roster!J:J,"Night Shift",Roster!P:P,"Direct",Roster!G:G,"AUH1") -> 0 | I26: =COUNTIFS(Roster!T:T,"AB",Roster!O:O,"CRET",Roster!J:J,"Night Shift",Roster!P:P,"Direct",Roster!G:G,"AUH1")+COUNTIFS(Roster!T:T,"ABWI",Roster!O:O,"CRET",Roster!J:J,"Night Shift",Roster!P:P,"Direct",Roster!G:G,"AUH1") -> 0 | J26: =SUM(G26:I26,)+SUM(C26:E26) -> 86 | K26: =(J26-D26)-C26-F26 -> 60 | L26: 0.89833333 | M26: =(G26-F26)/(K26) -> 0.95 | N26: =G26/K26 -> 0.95
A27: CRET Total | C27: =SUM(C24:C26) -> 0 | D27: =SUM(D24:D26) -> 67 | E27: =SUM(E24:E26) -> 10 | F27: =SUM(F24:F26) -> 0 | G27: =SUM(G24:G26) -> 139 | H27: =SUM(H24:H26) -> 1 | I27: =SUM(I24:I26) -> 1 | J27: =SUM(J24:J26) -> 218 | K27: =SUM(K24:K26) -> 151 | L27: 0.89921053 | M27: =(G27-F27)/(K27) -> 0.9205298 | N27: =G27/K27 -> 0.9205298 | O27: =L27*K27 -> 135.78079 | P27: =G27-F27 -> 139 | Q27: =P27-O27 -> 3.2192105
A28: Grand Total | C28: =C15+C19+C23+C27 -> 0 | D28: =D15+D19+D23+D27 -> 439 | E28: =E15+E19+E23+E27 -> 43 | F28: =F15+F19+F23+F27 -> 21 | G28: =G15+G19+G23+G27 -> 742 | H28: =H15+H19+H23+H27 -> 5 | I28: =I15+I19+I23+I27 -> 12 | J28: =J15+J19+J23+J27 -> 1241 | K28: =K15+K19+K23+K27 -> 781 | L28: =J9 -> 0.91101434 | M28: =(G28-F28)/(K28) -> 0.92317542 | N28: =G28/K28 -> 0.95006402 | O28: =L28*K28 -> 711.5022 | P28: =G28-F28 -> 721 | Q28: =P28-O28 -> 9.4978005
E30: =E6/(D6-F6) -> 0.068062827 | F30: DS | G30: =G6/(D6-F6) -> 0.034031414
E31: =E9/(D9-F9) -> 0.056578947 | F31: Overall | G31: =G9/(D9-F9) -> 0.022368421
E32: =E8/(D8-F8) -> 0.044973545 | F32: NS | G32: =G8/(D8-F8) -> 0.010582011

Sheet Roster
A1: Date | B1: 46257 | C1: =TEXT(B1,"dddd") -> Sunday | F1: Target | G1: 0.0756 | Q1: P | R1: Present | S1: SL
Q2: AB | R2: Absent | S2: EL
Q3: PL | R3: Any Planned Leave | S3: ABWI
Q4: OFF | R4: Weekly Off | S4: 0
A6: S.No | B6: Psoft No | C6: AMZ ID | D6: EMP Name | E6: Employment Type | F6: Country | G6: Building | H6: LOB | I6: Cost Center | J6: Shift | K6: Shift Difference | L6: OFF1 | M6: OFF2 | N6: Job Title | O6: Department | P6: Type | Q6: 3P | R6: Line Manager Login | S6: Line Manager | T6: Attendance | U6: Remarks | V6: DOJ | W6: Process Path | X6: DWD Dashboard | Y6: GB LEAVES
A7: 1 | B7: 206875258 | C7: bakabdal | D7: ABDALLAH ABDALLAH ISSA | E7: Temporary | F7: UAE | G7: AUH1 | H7: FC | I7: 1299 | J7: Day Shift | K7: NA | L7: Sunday | M7: Monday | N7: Warehouse Associate 8W | O7: CRET | P7: Direct | Q7: Dulsco | R7: aanso | S7: Sohail,Anis | T7: OFF | V7: 46051 | W7: Customer Returns | X7: =VLOOKUP(Table1[[#This Row],[AMZ ID]],[1]Roster_1787503287932!$D$2:$AU$1370,25,0) -> Not Present | Y7: =VLOOKUP(Table1[[#This Row],[AMZ ID]],[1]Roster_1787503287932!$D$2:$AM$1370,35,0) -> 0
A8: 2 | B8: 206873715 | C8: zkasabda | D8: ABDALLAH KASSIM | E8: Temporary | F8: UAE | G8: AUH1 | H8: FC | I8: 1299 | J8: Day Shift | K8: NA | L8: Saturday | M8: Sunday | N8: Warehouse Associate 8W | O8: CRET | P8: Direct | Q8: Dulsco | R8: aanso | S8: Sohail,Anis | T8: OFF | V8: 46020 | W8: Customer Returns | X8: =VLOOKUP(Table1[[#This Row],[AMZ ID]],[1]Roster_1787503287932!$D$2:$AU$1370,25,0) -> Not Present | Y8: =VLOOKUP(Table1[[#This Row],[AMZ ID]],[1]Roster_1787503287932!$D$2:$AM$1370,35,0) -> 0
A9: 3 | B9: 203679309 | C9: njitaria | D9: Abdel Koudous Njitari Mah | E9: Temporary | F9: UAE | G9: AUH1 | H9: FC | I9: 1299 | J9: Night Shift | K9: NA | L9: Sunday | M9: Monday | N9: Warehouse Associate 12M | O9: CRET | P9: Direct | Q9: Fastlink | R9: aanso | S9: Sohail,Anis | T9: OFF | V9: 45488 | W9: Customer Returns | X9: =VLOOKUP(Table1[[#This Row],[AMZ ID]],[1]Roster_1787503287932!$D$2:$AU$1370,25,0) -> Not Present | Y9: =VLOOKUP(Table1[[#This Row],[AMZ ID]],[1]Roster_1787503287932!$D$2:$AM$1370,35,0) -> 0
A10: 4 | B10: 204864408 | C10: iddabdud | D10: ABDULMALIK IDDRISU | E10: Temporary | F10: UAE | G10: AUH1 | H10: FC | I10: 1299 | J10: Night Shift | K10: NA | L10: Sunday | M10: Monday | N10: Warehouse Associate 8W | O10: CRET | P10: Direct | Q10: Dulsco | R10: aanso | S10: Sohail,Anis | T10: OFF | V10: 45684 | W10: Customer Returns | X10: =VLOOKUP(Table1[[#This Row],[AMZ ID]],[1]Roster_1787503287932!$D$2:$AU$1370,25,0) -> Not Present | Y10: =VLOOKUP(Table1[[#This Row],[AMZ ID]],[1]Roster_1787503287932!$D$2:$AM$1370,35,0) -> 0
A11: 5 | B11: 203800376 | C11: kiwanuab | D11: ABDURASHID KIWANUKA | E11: Temporary | F11: UAE | G11: AUH1 | H11: FC | I11: 1299 | J11: Day Shift | K11: NA | L11: Wednesday | M11: Thursday | N11: Warehouse Associate 8W | O11: CRET | P11: Direct | Q11: Dulsco | R11: aanso | S11: Sohail,Anis | T11: P | V11: 45516 | W11: Customer Returns | X11: =VLOOKUP(Table1[[#This Row],[AMZ ID]],[1]Roster_1787503287932!$D$2:$AU$1370,25,0) -> Present | Y11: =VLOOKUP(Table1[[#This Row],[AMZ ID]],[1]Roster_1787503287932!$D$2:$AM$1370,35,0) -> 0
A12: 6 | B12: 206953791 | C12: abubodon | D12: ABUBAKAESWIDIQ ODONGO | E12: Temporary | F12: UAE | G12: AUH1 | H12: FC | I12: 1299 | J12: Day Shift | K12: NA | L12: Thursday | M12: Friday | N12: Warehouse Associate 24M | O12: CRET | P12: Direct | Q12: Dulsco | R12: aanso | S12: Sohail,Anis | T12: P | V12: 46048 | W12: Customer Returns | X12: =VLOOKUP(Table1[[#This Row],[AMZ ID]],[1]Roster_1787503287932!$D$2:$AU$1370,25,0) -> Present | Y12: =VLOOKUP(Table1[[#This Row],[AMZ ID]],[1]Roster_1787503287932!$D$2:$AM$1370,35,0) -> 0
A13: 7 | B13: 205608373 | C13: tiacquah | D13: ACQUAH TIMOTHY | E13: Temporary | F13: UAE | G13: AUH1 | H13: FC | I13: 1299 | J13: Night Shift | K13: NA | L13: Wednesday | M13: Thursday | N13: Warehouse Associate 8W | O13: CRET | P13: Direct | Q13: Dulsco | R13: aanso | S13: Sohail,Anis | T13: P | V13: 45845 | W13: Customer Returns | X13: =VLOOKUP(Table1[[#This Row],[AMZ ID]],[1]Roster_1787503287932!$D$2:$AU$1370,25,0) -> Present | Y13: =VLOOKUP(Table1[[#This Row],[AMZ ID]],[1]Roster_1787503287932!$D$2:$AM$1370,35,0) -> 0
A14: 8 | B14: 204869098 | C14: rosadamu | D14: Adams,Rose | E14: Temporary | F14: UAE | G14: AUH1 | H14: FC | I14: 1299 | J14: Night Shift | K14: NA | L14: Friday | M14: Saturday | N14: Warehouse Associate 8W | O14: CRET | P14: Direct | Q14: Quesscorp | R14: aanso | S14: Sohail,Anis | T14: P | V14: 45691 | W14: Customer Returns | X14: =VLOOKUP(Table1[[#This Row],[AMZ ID]],[1]Roster_1787503287932!$D$2:$AU$1370,25,0) -> Present | Y14: =VLOOKUP(Table1[[#This Row],[AMZ ID]],[1]Roster_1787503287932!$D$2:$AM$1370,35,0) -> 0
A15: 9 | B15: 206875144 | C15: ramaafid | D15: AFIDHU SWAMADU RAMADHANI | E15: Temporary | F15: UAE | G15: AUH1 | H15: FC | I15: 1299 | J15: Night Shift | K15: NA | L15: Sunday | M15: Monday | N15: Warehouse Associate 8W | O15: CRET | P15: Direct | Q15: Dulsco | R15: aanso | S15: Sohail,Anis | T15: OFF | V15: 46020 | W15: Customer Returns | X15: =VLOOKUP(Table1[[#This Row],[AMZ ID]],[1]Roster_1787503287932!$D$2:$AU$1370,25,0) -> Not Present | Y15: =VLOOKUP(Table1[[#This Row],[AMZ ID]],[1]Roster_1787503287932!$D$2:$AM$1370,35,0) -> 0
A16: 10 | B16: 204299542 | C16: ahmeumef | D16: Ahmed Tidjan Mefire Nchankou | E16: Temporary | F16: UAE | G16: AUH1 | H16: FC | I16: 1299 | J16: Night Shift | K16: NA | L16: Thursday | M16: Friday | N16: Warehouse Associate 8W | O16: CRET | P16: Direct | Q16: Quesscorp | R16: aanso | S16: Sohail,Anis | T16: P | V16: 45586 | W16: Customer Returns | X16: =VLOOKUP(Table1[[#This Row],[AMZ ID]],[1]Roster_1787503287932!$D$2:$AU$1370,25,0) -> Present | Y16: =VLOOKUP(Table1[[#This Row],[AMZ ID]],[1]Roster_1787503287932!$D$2:$AM$1370,35,0) -> 0
A17: 11 | B17: 206873708 | C17: xaijueli | D17: AIJUKA ELIYA | E17: Temporary | F17: UAE | G17: AUH1 | H17: FC | I17: 1299 | J17: Day Shift | K17: NA | L17: Saturday | M17: Sunday | N17: Warehouse Associate 8W | O17: CRET | P17: Direct | Q17: Dulsco | R17: aanso | S17: Sohail,Anis | T17: OFF | V17: 46020 | W17: Customer Returns | X17: =VLOOKUP(Table1[[#This Row],[AMZ ID]],[1]Roster_1787503287932!$D$2:$AU$1370,25,0) -> Not Present | Y17: =VLOOKUP(Table1[[#This Row],[AMZ ID]],[1]Roster_1787503287932!$D$2:$AM$1370,35,0) -> 0
A18: 12 | B18: 203469458 | C18: ndanzyco | D18: CongratesMoforkengNdanze | E18: Temporary | F18: UAE | G18: AUH1 | H18: FC | I18: 1299 | J18: Day Shift | K18: NA | L18: Monday | M18: Tuesday | N18: Warehouse Associate 24M | O18: CRET | P18: Direct | Q18: Adecco | R18: aanso | S18: Sohail,Anis | T18: PL | U18: Annual Leave | V18: 45456 | W18: Customer Returns | X18: =VLOOKUP(Table1[[#This Row],[AMZ ID]],[1]Roster_1787503287932!$D$2:$AU$1370,25,0) -> Not Present | Y18: =VLOOKUP(Table1[[#This Row],[AMZ ID]],[1]Roster_1787503287932!$D$2:$AM$1370,35,0) -> Carry Forwarded Annual Leave
A19: 13 | B19: 204403651 | C19: jalanssh | D19: ALAN SHIJU SHIJU | E19: Temporary | F19: UAE | G19: AUH1 | H19: FC | I19: 1299 | J19: Night Shift | K19: NA | L19: Wednesday | M19: Thursday | N19: Warehouse Associate 24M | O19: CRET | P19: Direct | Q19: Adecco | R19: aanso | S19: Sohail,Anis | T19: P | V19: 45596 | W19: Customer Returns | X19: =VLOOKUP(Table1[[#This Row],[AMZ ID]],[1]Roster_1787503287932!$D$2:$AU$1370,25,0) -> Present | Y19: =VLOOKUP(Table1[[#This Row],[AMZ ID]],[1]Roster_1787503287932!$D$2:$AM$1370,35,0) -> 0
A20: 14 | B20: 204299562 | C20: alectilo | D20: AlecTilowakuti | E20: Temporary | F20: UAE | G20: AUH1 | H20: FC | I20: 1299 | J20: Night Shift | K20: NA | L20: Monday | M20: Tuesday | N20: Warehouse Associate 24M | O20: CRET | P20: Direct | Q20: Quesscorp | R20: aanso | S20: Sohail,Anis | T20: P | V20: 45586 | W20: Customer Returns | X20: =VLOOKUP(Table1[[#This Row],[AMZ ID]],[1]Roster_1787503287932!$D$2:$AU$1370,25,0) -> Present | Y20: =VLOOKUP(Table1[[#This Row],[AMZ ID]],[1]Roster_1787503287932!$D$2:$AM$1370,35,0) -> 0
A21: 15 | B21: 206949071 | C21: alemuyom | D21: ALEX MUYOMBA | E21: Temporary | F21: UAE | G21: AUH1 | H21: FC | I21: 1299 | J21: Night Shift | K21: NA | L21: Thursday | M21: Friday | N21: Warehouse Associate 24M | O21: CRET | P21: Direct | Q21: Dulsco | R21: aanso | S21: Sohail,Anis | T21: P | V21: 46048 | W21: Customer Returns | X21: =VLOOKUP(Table1[[#This Row],[AMZ ID]],[1]Roster_1787503287932!$D$2:$AU$1370,25,0) -> Present | Y21: =VLOOKUP(Table1[[#This Row],[AMZ ID]],[1]Roster_1787503287932!$D$2:$AM$1370,35,0) -> 0
A22: 16 | B22: 203083928 | C22: galeowus | D22: Alex Owusu | E22: Temporary | F22: UAE | G22: AUH1 | H22: FC | I22: 1299 | J22: Day Shift | K22: NA | L22: Wednesday | M22: Thursday | N22: Warehouse Associate 12M | O22: CRET | P22: Direct | Q22: Fastlink | R22: aanso | S22: Sohail,Anis | T22: P | V22: 45488 | W22: Customer Returns | X22: =VLOOKUP(Table1[[#This Row],[AMZ ID]],[1]Roster_1787503287932!$D$2:$AU$1370,25,0) -> Present | Y22: =VLOOKUP(Table1[[#This Row],[AMZ ID]],[1]Roster_1787503287932!$D$2:$AM$1370,35,0) -> 0
A23: 17 | B23: 206926473 | C23: kwailaga | D23: ALI WAILAGALA | E23: Temporary | F23: UAE | G23: AUH1 | H23: FC | I23: 1299 | J23: Day Shift | K23: NA | L23: Tuesday | M23: Wednesday | N23: Warehouse Associate 8W | O23: CRET | P23: Direct | Q23: Dulsco | R23: aanso | S23: Sohail,Anis | T23: P | V23: 46048 | W23: Customer Returns | X23: =VLOOKUP(Table1[[#This Row],[AMZ ID]],[1]Roster_1787503287932!$D$2:$AU$1370,25,0) -> Present | Y23: =VLOOKUP(Table1[[#This Row],[AMZ ID]],[1]Roster_1787503287932!$D$2:$AM$1370,35,0) -> 0
A24: 18 | B24: 203469072 | C24: aliallaf | D24: Allafha Ali | E24: Temporary | F24: UAE | G24: AUH1 | H24: FC | I24: 1299 | J24: Night Shift | K24: NA | L24: Friday | M24: Saturday | N24: Warehouse Associate 12M | O24: CRET | P24: Direct | Q24: Fastlink | R24: aanso | S24: Sohail,Anis | T24: P | V24: 45456 | W24: Customer Returns | X24: =VLOOKUP(Table1[[#This Row],[AMZ ID]],[1]Roster_1787503287932!$D$2:$AU$1370,25,0) -> Present | Y24: =VLOOKUP(Table1[[#This Row],[AMZ ID]],[1]Roster_1787503287932!$D$2:$AM$1370,35,0) -> 0
A25: 19 | B25: 206875142 | C25: ddumalla | D25: ALLAN DDUMBA SSENTAMU | E25: Temporary | F25: UAE | G25: AUH1 | H25: FC | I25: 1299 | J25: Night Shift | K25: NA | L25: Sunday | M25: Monday | N25: Warehouse Associate 8W | O25: CRET | P25: Direct | Q25: Dulsco | R25: aanso | S25: Sohail,Anis | T25: OFF | V25: 46020 | W25: Customer Returns | X25: =VLOOKUP(Table1[[#This Row],[AMZ ID]],[1]Roster_1787503287932!$D$2:$AU$1370,25,0) -> Not Present | Y25: =VLOOKUP(Table1[[#This Row],[AMZ ID]],[1]Roster_1787503287932!$D$2:$AM$1370,35,0) -> 0
A26: 20 | B26: 206953811 | C26: allanmub | D26: ALLAN MUBANGIZI | E26: Temporary | F26: UAE | G26: AUH1 | H26: FC | I26: 1299 | J26: Night Shift | K26: NA | L26: Thursday | M26: Friday | N26: Warehouse Associate 24M | O26: CRET | P26: Direct | Q26: Dulsco | R26: bavameer | S26: Meera,Bava Bahrudeen | T26: P | V26: 46048 | W26: Customer Returns | X26: =VLOOKUP(Table1[[#This Row],[AMZ ID]],[1]Roster_1787503287932!$D$2:$AU$1370,25,0) -> Present | Y26: =VLOOKUP(Table1[[#This Row],[AMZ ID]],[1]Roster_1787503287932!$D$2:$AM$1370,35,0) -> 0
A27: 21 | B27: 206875146 | C27: alphaatk | D27: ALPHA ATHANASIO KINYAPALA | E27: Temporary | F27: UAE | G27: AUH1 | H27: FC | I27: 1299 | J27: Night Shift | K27: NA | L27: Saturday | M27: Sunday | N27: Warehouse Associate 8W | O27: CRET | P27: Direct | Q27: Dulsco | R27: aanso | S27: Sohail,Anis | T27: OFF | V27: 46020 | W27: Customer Returns | X27: =VLOOKUP(Table1[[#This Row],[AMZ ID]],[1]Roster_1787503287932!$D$2:$AU$1370,25,0) -> Not Present | Y27: =VLOOKUP(Table1[[#This Row],[AMZ ID]],[1]Roster_1787503287932!$D$2:$AM$1370,35,0) -> 0
A28: 22 | B28: 205496017 | C28: roambili | D28: AmbiliaRop | E28: Temporary | F28: UAE | G28: AUH1 | H28: FC | I28: 1299 | J28: Night Shift | K28: NA | L28: Tuesday | M28: Wednesday | N28: Warehouse Associate 8W | O28: CRET | P28: Direct | Q28: EFS | R28: aanso | S28: Sohail,Anis | T28: P | V28: 45831 | W28: Customer Returns | X28: =VLOOKUP(Table1[[#This Row],[AMZ ID]],[1]Roster_1787503287932!$D$2:$AU$1370,25,0) -> Present | Y28: =VLOOKUP(Table1[[#This Row],[AMZ ID]],[1]Roster_1787503287932!$D$2:$AM$1370,35,0) -> 0
A29: 23 | B29: 206294541 | C29: amkkamar | D29: AMIDU KAMARA | E29: Temporary | F29: UAE | G29: AUH1 | H29: FC | I29: 1299 | J29: Night Shift | K29: NA | L29: Thursday | M29: Friday | N29: Warehouse Associate 8W | O29: CRET | P29: Direct | Q29: EFS | R29: aanso | S29: Sohail,Anis | T29: P | V29: 45950 | W29: Customer Returns | X29: =VLOOKUP(Table1[[#This Row],[AMZ ID]],[1]Roster_1787503287932!$D$2:$AU$1370,25,0) -> Present | Y29: =VLOOKUP(Table1[[#This Row],[AMZ ID]],[1]Roster_1787503287932!$D$2:$AM$1370,35,0) -> 0
A30: 24 | B30: 203800382 | C30: abaaamon | D30: AMON ABAASA | E30: Temporary | F30: UAE | G30: AUH1 | H30: FC | I30: 1299 | J30: Day Shift | K30: NA | L30: Thursday | M30: Friday | N30: Warehouse Associate 8W | O30: CRET | P30: Direct | Q30: Dulsco | R30: aanso | S30: Sohail,Anis | T30: P | V30: 45516 | W30: Customer Returns | X30: =VLOOKUP(Table1[[#This Row],[AMZ ID]],[1]Roster_1787503287932!$D$2:$AU$1370,25,0) -> Present | Y30: =VLOOKUP(Table1[[#This Row],[AMZ ID]],[1]Roster_1787503287932!$D$2:$AM$1370,35,0) -> 0
