Workbook
Name HCData: #REF!

Sheet Dashboard
A1: AUH1 | S1: AUH3 | AF1: DAD1
A2: Previous Day HC | B2: L3 Ops Supervisors | C2: FTE HC | D2: NFTE HC | E2: Today's HC | F2: HC LM Target | G2: Achievement % | H2: Remarks | S2: Previous Day HC | T2: L3 Ops Supervisors | U2: FTE HC | V2: NFTE HC | W2: Today's HC | X2: HC LM Target | Y2: Achievement % | Z2: Remarks | AF2: Previous Day HC | AG2: L3 Ops Supervisors | AH2: FTE HC | AI2: NFTE HC | AJ2: Today's HC | AK2: HC LM Target | AL2: Achievement % | AM2: Remarks
A3: 1241 | B3: =COUNTIFS(Roster!P:P,"FC Associate III",Roster!G:G,"AUH1",Roster!R:R,"Direct") -> 28 | C3: =COUNTIFS(Roster!E:E,"Regular",Roster!G:G,"AUH1",Roster!R:R,"Direct") -> 58 | D3: =COUNTIFS(Roster!E:E,"Temporary",Roster!G:G,"AUH1",Roster!R:R,"Direct") -> 1176 | E3: =C3+D3 -> 1234 | F3: =E3 -> 1234 | G3: =E3/F3 -> 1 | S3: 82 | T3: =COUNTIFS(Roster!P:P,"Hub Supervisor",Roster!R:R,"Direct",Roster!Q:Q,"Warehouse Deals") -> 4 | U3: =COUNTIFS(Roster!E:E,"Regular",Roster!R:R,"Direct",Roster!Q:Q,"Warehouse Deals") -> 14 | V3: =COUNTIFS(Roster!E:E,"Temporary",Roster!R:R,"Direct",Roster!Q:Q,"Warehouse Deals") -> 86 | W3: =U3+V3 -> 100 | X3: =W3 -> 100 | Y3: =W3/X3 -> 1 | AF3: 12 | AG3: =COUNTIFS(Roster!P:P,"FC Associate III",Roster!G:G,"DAD1",Roster!R:R,"Support") -> 0 | AH3: =COUNTIFS(Roster!E:E,"Regular",Roster!G:G,"DAD1",Roster!R:R,"Support") -> 0 | AI3: =COUNTIFS(Roster!E:E,"Temporary",Roster!G:G,"DAD1",Roster!R:R,"Support") -> 12 | AJ3: =AH3+AI3 -> 12 | AK3: =AJ3 -> 12 | AL3: =AJ3/AK3 -> 1
A4: =Roster!B1 -> 46258 | S4: =Roster!B1 -> 46258 | AF4: =Roster!B1 -> 46258
A5: Shift | B5: Total HC | C5: Unscheduled | D5: Schedule to Work | E5: PL | F5: OT | G5: UPL | H5: Present | I5: Present % (without OT) | J5: LM Target | K5: Target Achievement | S5: Shift | T5: Total HC | U5: Unscheduled | V5: Schedule to Work | W5: PL | X5: OT | Y5: UPL | Z5: Present | AA5: Present % | AB5: LM Target | AC5: Target Achievement | AF5: Shift | AG5: Total HC | AH5: Unscheduled | AI5: Schedule to Work | AJ5: PL | AK5: UPL | AL5: OT | AM5: Present | AN5: Present % | AO5: LM Target | AP5: Target Achievement
A6: Day Shift | B6: =COUNTIFS(Roster!G:G,"AUH1",Roster!R:R,"Direct",Roster!L:L,"Day Shift") -> 668 | C6: =SUMIFS($D$12:$D$27,$B$12:$B$27,"Day Shift") -> 248 | D6: =SUMIFS($K$12:$K$27,$B$12:$B$27,"Day Shift") -> 408 | E6: =SUMIFS($E$12:$E$27,$B$12:$B$27,"Day Shift") -> 23 | F6: =COUNTIFS(Table1[[#All],[Building]],"AUH1",Table1[[#All],[Shift]],"Day Shift",Table1[[#All],[OFF1]],"OT",Table1[[#All],[Type]],"Direct")+COUNTIFS(Table1[[#All],[Building]],"AUH1",Table1[[#All],[Shift]],"Day Shift",Table1[[#All],[OFF2]],"OT",Table1[[#All],[Type]],"Direct") -> 12 | G6: =SUMIFS($H$12:$H$26,$B$12:$B$26,"Day Shift")+SUMIFS($I$12:$I$26,$B$12:$B$26,"Day Shift") -> 15 | H6: =D6-E6-G6 -> 370 | I6: =H6/D6 -> 0.90686275 | J6: 0.88391892 | K6: =I6/J6 -> 1.0259569 | S6: Day Shift | T6: =COUNTIFS(Roster!G:G,"AUH3",Roster!R:R,"Direct",Roster!L:L,"Day Shift")+COUNTIFS(Roster!G:G,"DDB1",Roster!R:R,"Direct",Roster!L:L,"Day Shift") -> 39 | U6: =SUMIFS($V$12:$V$14,$T$12:$T$14,"Day Shift") -> 12 | V6: =SUMIFS($AC$12:$AC$14,$T$12:$T$14,"Day Shift") -> 27 | W6: =SUMIFS($W$12:$W$14,$T$12:$T$14,"Day Shift") -> 0 | X6: =COUNTIFS(Table1[[#All],[Building]],"AUH3",Table1[[#All],[Shift]],"Day Shift",Table1[[#All],[OFF1]],"OT",Table1[[#All],[Type]],"Direct")+COUNTIFS(Table1[[#All],[Building]],"AUH3",Table1[[#All],[Shift]],"Day Shift",Table1[[#All],[OFF2]],"OT",Table1[[#All],[Type]],"Direct") -> 0 | Y6: =SUMIFS($Z$12:$Z$14,$T$12:$T$14,"Day Shift")+SUMIFS($AA$12:$AA$14,$T$12:$T$14,"Day Shift") -> 0 | Z6: =V6-W6-Y6 -> 27 | AA6: =Z6/V6 -> 1 | AB6: 0.89307692 | AC6: =AA6/AB6 -> 1.1197244 | AF6: Day Shift | AG6: =COUNTIFS(Roster!G:G,"DAD1",Roster!R:R,"Support",Roster!L:L,"Day Shift") -> 0 | AH6: =SUMIFS($AI$12:$AI$15,$AG$12:$AG$15,"Day Shift") -> 0 | AI6: =SUMIFS($AP$12:$AP$15,$AG$12:$AG$15,"Day Shift") -> 0 | AJ6: =SUMIFS($AJ$12:$AJ$15,$AG$12:$AG$15,"Day Shift") -> 0 | AK6: =SUMIFS($AM$12:$AM$15,$AG$12:$AG$15,"Day Shift")+SUMIFS($AN$12:$AN$15,$AG$12:$AG$15,"Day Shift") -> 0 | AL6: =COUNTIFS(Table1[[#All],[Building]],"DAD1",Table1[[#All],[Shift]],"Day Shift",Table1[[#All],[OFF1]],"OT",Table1[[#All],[Type]],"Direct")+COUNTIFS(Table1[[#All],[Building]],"DAD1",Table1[[#All],[Shift]],"Day Shift",Table1[[#All],[OFF2]],"OT",Table1[[#All],[Type]],"Support") -> 0 | AM6: =AI6-AJ6-AK6 -> 0 | AN6: =AM6/AI6 -> #DIV/0! | AO6: 0.9512 | AP6: =AN6/AO6 -> #DIV/0!
A7: Mid Shift | B7: =COUNTIFS(Roster!G:G,"AUH1",Roster!R:R,"Direct",Roster!L:L,"Mid Shift") -> 0 | C7: =SUMIFS($D$12:$D$27,$B$12:$B$27,"Mid Shift") -> 0 | D7: =SUMIFS($K$12:$K$27,$B$12:$B$27,"Mid Shift") -> 0 | E7: =SUMIFS($E$12:$E$27,$B$12:$B$27,"Mid Shift") -> 0 | F7: =COUNTIFS(Table1[[#All],[Building]],"AUH1",Table1[[#All],[Shift]],"Mid Shift",Table1[[#All],[OFF1]],"OT",Table1[[#All],[Type]],"Direct")+COUNTIFS(Table1[[#All],[Building]],"AUH1",Table1[[#All],[Shift]],"Mid Shift",Table1[[#All],[OFF2]],"OT",Table1[[#All],[Type]],"Direct") -> 0 | G7: =SUMIFS($H$12:$H$27,$B$12:$B$27,"Mid Shift")+SUMIFS($I$12:$I$27,$B$12:$B$27,"Mid Shift") -> 0 | H7: =D7-E7-G7 -> 0 | I7: =(H7-F7)/(D7-F7) -> #DIV/0! | J7: 0 | K7: =I7/J7 -> #DIV/0! | S7: Mid Shift | T7: =COUNTIFS(Roster!G:G,"AUH3",Roster!R:R,"Direct",Roster!L:L,"Mid Shift")+COUNTIFS(Roster!G:G,"DDB1",Roster!R:R,"Direct",Roster!L:L,"Mid Shift") -> 0 | U7: =SUMIFS($V$12:$V$14,$T$12:$T$14,"Mid Shift") -> 0 | V7: =SUMIFS($AC$12:$AC$14,$T$12:$T$14,"Mid Shift") -> 0 | W7: =SUMIFS($W$12:$W$14,$T$12:$T$14,"Mid Shift") -> 0 | X7: =COUNTIFS(Table1[[#All],[Building]],"AUH3",Table1[[#All],[Shift]],"Mid Shift",Table1[[#All],[OFF1]],"OT",Table1[[#All],[Type]],"Direct")+COUNTIFS(Table1[[#All],[Building]],"AUH3",Table1[[#All],[Shift]],"Mid Shift",Table1[[#All],[OFF2]],"OT",Table1[[#All],[Type]],"Direct") -> 0 | Y7: =SUMIFS($Z$12:$Z$14,$T$12:$T$14,"Mid Shift")+SUMIFS($AA$12:$AA$14,$T$12:$T$14,"Mid Shift") -> 0 | Z7: =V7-W7-Y7 -> 0 | AA7: =Z7/V7 -> #DIV/0! | AB7: 0 | AC7: =AA7/AB7 -> #DIV/0! | AF7: Mid Shift | AG7: =COUNTIFS(Roster!G:G,"DAD1",Roster!R:R,"Support",Roster!L:L,"Mid Shift") -> 0 | AH7: =SUMIFS($AI$12:$AI$15,$AG$12:$AG$15,"Mid Shift") -> 0 | AI7: =SUMIFS($AP$12:$AP$15,$AF$12:$AF$15,"Mid Shift") -> 0 | AJ7: =SUMIFS($AJ$12:$AJ$15,$AG$12:$AG$15,"Mid Shift") -> 0 | AK7: =SUMIFS($AM$12:$AM$15,$AG$12:$AG$15,"Mid Shift")+SUMIFS($AN$12:$AN$15,$AG$12:$AG$15,"Mid Shift") -> 0 | AL7: =COUNTIFS(Table1[[#All],[Building]],"DAD1",Table1[[#All],[Shift]],"Mid Shift",Table1[[#All],[OFF1]],"OT",Table1[[#All],[Type]],"Direct")+COUNTIFS(Table1[[#All],[Building]],"DAD1",Table1[[#All],[Shift]],"Mid Shift",Table1[[#All],[OFF2]],"OT",Table1[[#All],[Type]],"Direct") -> 0 | AM7: =AI7-AJ7-AK7 -> 0 | AN7: =AM7/AI7 -> #DIV/0! | AO7: 0.9565 | AP7: =AN7/AO7 -> #DIV/0!
A8: Night Shift | B8: =COUNTIFS(Roster!G:G,"AUH1",Roster!R:R,"Direct",Roster!L:L,"Night Shift") -> 566 | C8: =SUMIFS($D$12:$D$27,$B$12:$B$27,"Night Shift") -> 174 | D8: =SUMIFS($K$12:$K$27,$B$12:$B$27,"Night Shift") -> 388 | E8: =SUMIFS($E$12:$E$27,$B$12:$B$27,"Night Shift") -> 15 | F8: =COUNTIFS(Table1[[#All],[Building]],"AUH1",Table1[[#All],[Shift]],"Night Shift",Table1[[#All],[OFF1]],"OT",Table1[[#All],[Type]],"Direct")+COUNTIFS(Table1[[#All],[Building]],"AUH1",Table1[[#All],[Shift]],"Night Shift",Table1[[#All],[OFF2]],"OT",Table1[[#All],[Type]],"Direct") -> 4 | G8: =SUMIFS($H$12:$H$27,$B$12:$B$27,"Night Shift")+SUMIFS($I$12:$I$27,$B$12:$B$27,"Night Shift") -> 7 | H8: =D8-E8-G8 -> 366 | I8: =H8/D8 -> 0.94329897 | J8: 0.90377551 | K8: =I8/J8 -> 1.0437315 | S8: Night Shift | T8: =COUNTIFS(Roster!G:G,"AUH3",Roster!R:R,"Direct",Roster!L:L,"Night Shift")+COUNTIFS(Roster!G:G,"DDB1",Roster!R:R,"Direct",Roster!L:L,"Night Shift") -> 61 | U8: =SUMIFS($V$12:$V$14,$T$12:$T$14,"Night Shift") -> 21 | V8: =SUMIFS($AC$12:$AC$14,$T$12:$T$14,"Night Shift") -> 40 | W8: =SUMIFS($W$12:$W$14,$T$12:$T$14,"Night Shift") -> 1 | X8: =COUNTIFS(Table1[[#All],[Building]],"AUH3",Table1[[#All],[Shift]],"Night Shift",Table1[[#All],[OFF1]],"OT",Table1[[#All],[Type]],"Direct")+COUNTIFS(Table1[[#All],[Building]],"AUH3",Table1[[#All],[Shift]],"Night Shift",Table1[[#All],[OFF2]],"OT",Table1[[#All],[Type]],"Direct") -> 0 | Y8: =SUMIFS($Z$12:$Z$14,$T$12:$T$14,"Night Shift")+SUMIFS($AA$12:$AA$14,$T$12:$T$14,"Night Shift") -> 1 | Z8: =V8-W8-Y8 -> 38 | AA8: =Z8/V8 -> 0.95 | AB8: 0.91736842 | AC8: =AA8/AB8 -> 1.0355709 | AF8: Night Shift | AG8: =COUNTIFS(Roster!G:G,"DAD1",Roster!R:R,"Support",Roster!L:L,"Night Shift") -> 12 | AH8: =SUMIFS($AI$12:$AI$15,$AG$12:$AG$15,"Night Shift") -> 2 | AI8: =SUMIFS($AP$12:$AP$15,$AG$12:$AG$15,"Night Shift") -> 10 | AJ8: =SUMIFS($AJ$12:$AJ$15,$AG$12:$AG$15,"Night Shift") -> 0 | AK8: =SUMIFS($AM$12:$AM$15,$AG$12:$AG$15,"Night Shift")+SUMIFS($AN$12:$AN$15,$AG$12:$AG$15,"Night Shift") -> 0 | AL8: =COUNTIFS(Table1[[#All],[Building]],"DAD1",Table1[[#All],[Shift]],"Night Shift",Table1[[#All],[OFF1]],"OT",Table1[[#All],[Type]],"Support")+COUNTIFS(Table1[[#All],[Building]],"DAD1",Table1[[#All],[Shift]],"Night Shift",Table1[[#All],[OFF1]],"OT",Table1[[#All],[Type]],"Support") -> 0 | AM8: =AI8-AJ8-AK8 -> 10 | AN8: =AM8/AI8 -> 1 | AO8: 0.9568 | AP8: =AN8/AO8 -> 1.0451505
A9: Grand Total | B9: =SUM(B6:B8) -> 1234 | C9: =SUM(C6:C8) -> 422 | D9: =SUM(D6:D8) -> 796 | E9: =SUM(E6:E8) -> 38 | F9: =SUM(F6:F8) -> 16 | G9: =SUM(G6:G8) -> 22 | H9: =SUM(H6:H8) -> 736 | I9: =H9/D9 -> 0.92462312 | J9: 0.89366083 | K9: =I9/J9 -> 1.0346466 | S9: Grand Total | T9: =SUM(T6:T8) -> 100 | U9: =SUM(U6:U8) -> 33 | V9: =SUM(V6:V8) -> 67 | W9: =SUM(W6:W8) -> 1 | X9: =SUM(X6:X8) -> 0 | Y9: =SUM(Y6:Y8) -> 1 | Z9: =SUM(Z6:Z8) -> 65 | AA9: =Z9/V9 -> 0.97014925 | AB9: 0.9079085 | AC9: =AA9/AB9 -> 1.068554 | AF9: Grand Total | AG9: =SUM(AG6:AG8) -> 12 | AH9: =SUM(AH6:AH8) -> 2 | AI9: =SUM(AI6:AI8) -> 10 | AJ9: =SUM(AJ6:AJ8) -> 0 | AK9: =SUM(AK6:AK8) -> 0 | AL9: =SUM(AL6:AL8) -> 0 | AM9: =SUM(AM6:AM8) -> 10 | AN9: =AM9/AI9 -> 1 | AO9: =AVERAGE(AO6,AO7,AO8) -> 0.95483333 | AP9: =AN9/AO9 -> 1.0473032
A11: Department | B11: Shift | C11: 0 | D11: OFF | E11: PL | F11: OT | G11: Present(Including OT) | H11: SL | I11: AB/ABWI | J11: Grand Total | K11: Scheduled | L11: Target | M11: Actual (without OT) | N11: Actual (with OT) | O11: HC As per Target % | P11: Actual HC Achived Without OT | Q11: Delta | S11: Department | T11: Shift | U11: 0 | V11: OFF | W11: PL | X11: OT | Y11: Present | Z11: SL | AA11: AB/ABWI | AB11: Grand Total | AC11: Scheduled | AD11: % | AF11: Department | AG11: Shift | AH11: 0 | AI11: OFF | AJ11: PL | AK11: Present | AL11: OT | AM11: SL | AN11: AB/ABWI | AO11: Grand Total | AP11: Scheduled | AQ11: %
A12: ICQA | B12: Day Shift | C12: =COUNTIFS(Roster!V:V,"0",Roster!Q:Q,"ICQA",Roster!L:L,"Day Shift",Roster!R:R,"Direct",Roster!G:G,"AUH1") -> 0 | D12: =COUNTIFS(Roster!V:V,"OFF",Roster!Q:Q,"ICQA",Roster!L:L,"Day Shift",Roster!R:R,"Direct",Roster!G:G,"AUH1") -> 11 | E12: =COUNTIFS(Roster!V:V,"PL",Roster!Q:Q,"ICQA",Roster!L:L,"Day Shift",Roster!R:R,"Direct",Roster!G:G,"AUH1") -> 1 | F12: =COUNTIFS(Table1[[#All],[Building]],"AUH1",Table1[[#All],[Shift]],"Day Shift",Table1[[#All],[OFF1]],"OT",Table1[[#All],[Department]],Dashboard!A12)+COUNTIFS(Table1[[#All],[Building]],"AUH1",Table1[[#All],[Shift]],"Day Shift",Table1[[#All],[OFF2]],"OT",Table1[[#All],[Department]],Dashboard!A12) -> 0 | G12: =COUNTIFS(Roster!V:V,"P",Roster!Q:Q,"ICQA",Roster!L:L,"Day Shift",Roster!R:R,"Direct",Roster!G:G,"AUH1") -> 30 | H12: =COUNTIFS(Roster!V:V,"SL",Roster!Q:Q,"ICQA",Roster!L:L,"Day Shift",Roster!R:R,"Direct",Roster!G:G,"AUH1") -> 1 | I12: =COUNTIFS(Roster!V:V,"AB",Roster!Q:Q,"ICQA",Roster!L:L,"Day Shift",Roster!R:R,"Direct",Roster!G:G,"AUH1")+COUNTIFS(Roster!V:V,"ABWI",Roster!Q:Q,"ICQA",Roster!L:L,"Day Shift",Roster!R:R,"Direct",Roster!G:G,"AUH1") -> 0 | J12: =SUM(G12:I12,)+SUM(C12:E12) -> 43 | K12: =(J12-D12)-C12-F12 -> 32 | L12: 0.87125 | M12: =(G12-F12)/(K12) -> 0.9375 | N12: =G12/K12 -> 0.9375 | S12: Warehouse Deals | T12: Day Shift | U12: =COUNTIFS(Roster!V:V,"0",Roster!Q:Q,"Warehouse Deals",Roster!L:L,"Day Shift",Roster!R:R,"Direct",Roster!G:G,"AUH3")+COUNTIFS(Roster!V:V,"0",Roster!Q:Q,"Warehouse Deals",Roster!L:L,"Day Shift",Roster!R:R,"Direct",Roster!G:G,"DDB1") -> 0 | V12: =COUNTIFS(Roster!V:V,"OFF",Roster!Q:Q,"Warehouse Deals",Roster!L:L,"Day Shift",Roster!R:R,"Direct",Roster!G:G,"AUH3")+COUNTIFS(Roster!V:V,"OFF",Roster!Q:Q,"Warehouse Deals",Roster!L:L,"Day Shift",Roster!R:R,"Direct",Roster!G:G,"DDB1") -> 12 | W12: =COUNTIFS(Roster!V:V,"PL",Roster!Q:Q,"Warehouse Deals",Roster!L:L,"Day Shift",Roster!R:R,"Direct",Roster!G:G,"AUH3")+COUNTIFS(Roster!V:V,"PL",Roster!Q:Q,"Warehouse Deals",Roster!L:L,"Day Shift",Roster!R:R,"Direct",Roster!G:G,"DDB1") -> 0 | X12: =COUNTIFS(Table1[[#All],[Building]],"AUH3",Table1[[#All],[Shift]],"Day Shift",Table1[[#All],[OFF1]],"OT",Table1[[#All],[Department]],Dashboard!S12)+COUNTIFS(Table1[[#All],[Building]],"AUH3",Table1[[#All],[Shift]],"Day Shift",Table1[[#All],[OFF2]],"OT",Table1[[#All],[Department]],Dashboard!S12) -> 0 | Y12: =COUNTIFS(Roster!V:V,"P",Roster!Q:Q,"Warehouse Deals",Roster!L:L,"Day Shift",Roster!R:R,"Direct",Roster!G:G,"AUH3")+COUNTIFS(Roster!V:V,"P",Roster!Q:Q,"Warehouse Deals",Roster!L:L,"Day Shift",Roster!R:R,"Direct",Roster!G:G,"DDB1") -> 27 | Z12: =COUNTIFS(Roster!V:V,"SL",Roster!Q:Q,"Warehouse Deals",Roster!L:L,"Day Shift",Roster!R:R,"Direct",Roster!G:G,"AUH3")+COUNTIFS(Roster!V:V,"SL",Roster!Q:Q,"Warehouse Deals",Roster!L:L,"Day Shift",Roster!R:R,"Direct",Roster!G:G,"DDB1") -> 0 | AA12: =COUNTIFS(Roster!V:V,"AB",Roster!Q:Q,"Warehouse Deals",Roster!L:L,"Day Shift",Roster!R:R,"Direct",Roster!G:G,"AUH3")+COUNTIFS(Roster!V:V,"AB",Roster!Q:Q,"Warehouse Deals",Roster!L:L,"Day Shift",Roster!R:R,"Direct",Roster!G:G,"DDB1")+COUNTIFS(Roster!V:V,"ABWI",Roster!Q:Q,"Warehouse Deals",Roster!L:L,"Day Shift",Roster!R:R,"Direct",Roster!G:G,"AUH3")+COUNTIFS(Roster!V:V,"ABWI",Roster!Q:Q,"Warehouse Deals",Roster!L:L,"Day Shift",Roster!R:R,"Direct",Roster!G:G,"DDB1") -> 0 | AB12: =SUM(Y12:AA12,)+SUM(U12:W12) -> 39 | AC12: =(AB12-V12)-U12-X12 -> 27 | AD12: =Y12/AC12 -> 1 | AF12: Warehouse Deals | AG12: Day Shift | AH12: =COUNTIFS(Roster!V:V,"0",Roster!Q:Q,"Warehouse Deals",Roster!L:L,"Day Shift",Roster!R:R,"Support",Roster!G:G,"DAD1") -> 0 | AI12: =COUNTIFS(Roster!V:V,"OFF",Roster!Q:Q,"Warehouse Deals",Roster!L:L,"Day Shift",Roster!R:R,"Support",Roster!G:G,"DAD1") -> 0 | AJ12: =COUNTIFS(Roster!V:V,"PL",Roster!Q:Q,"Warehouse Deals",Roster!L:L,"Day Shift",Roster!R:R,"Support",Roster!G:G,"DAD1") -> 0 | AK12: =COUNTIFS(Roster!V:V,"P",Roster!Q:Q,"Warehouse Deals",Roster!L:L,"Day Shift",Roster!R:R,"Support",Roster!G:G,"DAD1") -> 0 | AL12: =COUNTIFS(Table1[[#All],[Building]],"DAD1",Table1[[#All],[Shift]],"Day Shift",Table1[[#All],[OFF1]],"OT",Table1[[#All],[Type]],"Support")+COUNTIFS(Table1[[#All],[Building]],"DAD1",Table1[[#All],[Shift]],"Day Shift",Table1[[#All],[OFF2]],"OT",Table1[[#All],[Type]],"Support") -> 0 | AM12: =COUNTIFS(Roster!V:V,"SL",Roster!Q:Q,"Warehouse Deals",Roster!L:L,"Day Shift",Roster!R:R,"Support",Roster!G:G,"DAD1") -> 0 | AN12: =COUNTIFS(Roster!V:V,"AB",Roster!Q:Q,"Warehouse Deals",Roster!L:L,"Day Shift",Roster!R:R,"Support",Roster!G:G,"DAD1")+COUNTIFS(Roster!V:V,"ABWI",Roster!Q:Q,"Warehouse Deals",Roster!L:L,"Day Shift",Roster!R:R,"Support",Roster!G:G,"DAD1") -> 0 | AO12: =SUM(AM12:AN12,)+SUM(AH12:AK12) -> 0 | AP12: =(AO12-AI12)-AH12 -> 0 | AQ12: =AK12/AP12 -> #DIV/0!
B13: Mid Shift | C13: 0 | D13: =COUNTIFS(Roster!V:V,"OFF",Roster!Q:Q,"ICQA",Roster!L:L,"Mid Shift",Roster!R:R,"Direct",Roster!G:G,"AUH1") -> 0 | E13: =COUNTIFS(Roster!V:V,"PL",Roster!Q:Q,"ICQA",Roster!L:L,"Mid Shift",Roster!R:R,"Direct",Roster!G:G,"AUH1") -> 0 | F13: =COUNTIFS(Table1[[#All],[Building]],"AUH1",Table1[[#All],[Shift]],"Mid Shift",Table1[[#All],[OFF1]],"OT",Table1[[#All],[Department]],Dashboard!A12)+COUNTIFS(Table1[[#All],[Building]],"AUH1",Table1[[#All],[Shift]],"Mid Shift",Table1[[#All],[OFF2]],"OT",Table1[[#All],[Department]],Dashboard!A12) -> 0 | G13: =COUNTIFS(Roster!V:V,"P",Roster!Q:Q,"ICQA",Roster!L:L,"Mid Shift",Roster!R:R,"Direct",Roster!G:G,"AUH1") -> 0 | H13: =COUNTIFS(Roster!V:V,"SL",Roster!Q:Q,"ICQA",Roster!L:L,"Mid Shift",Roster!R:R,"Direct",Roster!G:G,"AUH1") -> 0 | I13: =COUNTIFS(Roster!V:V,"AB",Roster!Q:Q,"ICQA",Roster!L:L,"Mid Shift",Roster!R:R,"Direct",Roster!G:G,"AUH1")+COUNTIFS(Roster!V:V,"ABWI",Roster!Q:Q,"ICQA",Roster!L:L,"Mid Shift",Roster!R:R,"Direct",Roster!G:G,"AUH1") -> 0 | J13: =SUM(G13:I13,)+SUM(C13:E13) -> 0 | K13: =(J13-D13)-C13-F13 -> 0 | M13: =(G13-F13)/(K13) -> #DIV/0! | N13: =(H13-G13)/(L13) -> #DIV/0! | T13: Mid Shift | U13: =COUNTIFS(Roster!V:V,"0",Roster!Q:Q,"Warehouse Deals",Roster!L:L,"Mid Shift",Roster!R:R,"Direct",Roster!G:G,"AUH3")+COUNTIFS(Roster!V:V,"0",Roster!Q:Q,"Warehouse Deals",Roster!L:L,"Mid Shift",Roster!R:R,"Direct",Roster!G:G,"DDB1") -> 0 | V13: =COUNTIFS(Roster!V:V,"OFF",Roster!Q:Q,"Warehouse Deals",Roster!L:L,"Mid Shift",Roster!R:R,"Direct",Roster!G:G,"AUH3")+COUNTIFS(Roster!V:V,"OFF",Roster!Q:Q,"Warehouse Deals",Roster!L:L,"Mid Shift",Roster!R:R,"Direct",Roster!G:G,"DDB1") -> 0 | W13: =COUNTIFS(Roster!V:V,"PL",Roster!Q:Q,"Warehouse Deals",Roster!L:L,"Mid Shift",Roster!R:R,"Direct",Roster!G:G,"AUH3")+COUNTIFS(Roster!V:V,"PL",Roster!Q:Q,"Warehouse Deals",Roster!L:L,"Mid Shift",Roster!R:R,"Direct",Roster!G:G,"DDB1") -> 0 | X13: =COUNTIFS(Table1[[#All],[Building]],"AUH3",Table1[[#All],[Shift]],"Mid Shift",Table1[[#All],[OFF1]],"OT",Table1[[#All],[Department]],Dashboard!S12)+COUNTIFS(Table1[[#All],[Building]],"AUH3",Table1[[#All],[Shift]],"Mid Shift",Table1[[#All],[OFF2]],"OT",Table1[[#All],[Department]],Dashboard!S12) -> 0 | Y13: =COUNTIFS(Roster!V:V,"P",Roster!Q:Q,"Warehouse Deals",Roster!L:L,"Mid Shift",Roster!R:R,"Direct",Roster!G:G,"AUH3")+COUNTIFS(Roster!V:V,"P",Roster!Q:Q,"Warehouse Deals",Roster!L:L,"Mid Shift",Roster!R:R,"Direct",Roster!G:G,"DDB1") -> 0 | Z13: =COUNTIFS(Roster!V:V,"SL",Roster!Q:Q,"Warehouse Deals",Roster!L:L,"Mid Shift",Roster!R:R,"Direct",Roster!G:G,"AUH3")+COUNTIFS(Roster!V:V,"SL",Roster!Q:Q,"Warehouse Deals",Roster!L:L,"Mid Shift",Roster!R:R,"Direct",Roster!G:G,"DDB1") -> 0 | AA13: =COUNTIFS(Roster!V:V,"AB",Roster!Q:Q,"Warehouse Deals",Roster!L:L,"Mid Shift",Roster!R:R,"Direct",Roster!G:G,"AUH3")+COUNTIFS(Roster!V:V,"AB",Roster!Q:Q,"Warehouse Deals",Roster!L:L,"Mid Shift",Roster!R:R,"Direct",Roster!G:G,"DDB1")+COUNTIFS(Roster!V:V,"ABWI",Roster!Q:Q,"Warehouse Deals",Roster!L:L,"Mid Shift",Roster!R:R,"Direct",Roster!G:G,"AUH3")+COUNTIFS(Roster!V:V,"ABWI",Roster!Q:Q,"Warehouse Deals",Roster!L:L,"Mid Shift",Roster!R:R,"Direct",Roster!G:G,"DDB1") -> 0 | AB13: =SUM(Y13:AA13,)+SUM(U13:W13) -> 0 | AC13: =(AB13-V13)-U13-X13 -> 0 | AD13: =Y13/AC13 -> #DIV/0! | AG13: Mid Shift | AH13: =COUNTIFS(Roster!V:V,"0",Roster!Q:Q,"Warehouse Deals",Roster!L:L,"Mid Shift",Roster!R:R,"Support",Roster!G:G,"DAD1") -> 0 | AI13: =COUNTIFS(Roster!V:V,"OFF",Roster!Q:Q,"Warehouse Deals",Roster!L:L,"Mid Shift",Roster!R:R,"Support",Roster!G:G,"DAD1") -> 0 | AJ13: =COUNTIFS(Roster!V:V,"PL",Roster!Q:Q,"Warehouse Deals",Roster!L:L,"Mid Shift",Roster!R:R,"Support",Roster!G:G,"DAD1") -> 0 | AK13: =COUNTIFS(Roster!V:V,"P",Roster!Q:Q,"Warehouse Deals",Roster!L:L,"Mid Shift",Roster!R:R,"Support",Roster!G:G,"DAD1") -> 0 | AL13: =COUNTIFS(Table1[[#All],[Building]],"DAD1",Table1[[#All],[Shift]],"Mid Shift",Table1[[#All],[OFF1]],"OT",Table1[[#All],[Type]],"Direct")+COUNTIFS(Table1[[#All],[Building]],"DAD1",Table1[[#All],[Shift]],"Mid Shift",Table1[[#All],[OFF2]],"OT",Table1[[#All],[Type]],"Direct") -> 0 | AM13: =COUNTIFS(Roster!V:V,"SL",Roster!Q:Q,"Warehouse Deals",Roster!L:L,"Mid Shift",Roster!R:R,"Support",Roster!G:G,"DAD1") -> 0 | AN13: =COUNTIFS(Roster!V:V,"AB",Roster!Q:Q,"Warehouse Deals",Roster!L:L,"Mid Shift",Roster!R:R,"Support",Roster!G:G,"DAD1")+COUNTIFS(Roster!V:V,"ABWI",Roster!Q:Q,"Warehouse Deals",Roster!L:L,"Mid Shift",Roster!R:R,"Support",Roster!G:G,"DAD1") -> 0 | AO13: =SUM(AM13:AN13,)+SUM(AH13:AK13) -> 0 | AP13: =(AO13-AI13)-AH13 -> 0 | AQ13: =AK13/AP13 -> #DIV/0!
B14: Night Shift | C14: =COUNTIFS(Roster!V:V,"0",Roster!Q:Q,"ICQA",Roster!L:L,"Night Shift",Roster!R:R,"Direct",Roster!G:G,"AUH1") -> 0 | D14: =COUNTIFS(Roster!V:V,"OFF",Roster!Q:Q,"ICQA",Roster!L:L,"Night Shift",Roster!R:R,"Direct",Roster!G:G,"AUH1") -> 2 | E14: =COUNTIFS(Roster!V:V,"PL",Roster!Q:Q,"ICQA",Roster!L:L,"Night Shift",Roster!R:R,"Direct",Roster!G:G,"AUH1") -> 0 | F14: =COUNTIFS(Table1[[#All],[Building]],"AUH1",Table1[[#All],[Shift]],"Night Shift",Table1[[#All],[OFF1]],"OT",Table1[[#All],[Department]],Dashboard!A12)+COUNTIFS(Table1[[#All],[Building]],"AUH1",Table1[[#All],[Shift]],"Night Shift",Table1[[#All],[OFF2]],"OT",Table1[[#All],[Department]],Dashboard!A12) -> 0 | G14: =COUNTIFS(Roster!V:V,"P",Roster!Q:Q,"ICQA",Roster!L:L,"Night Shift",Roster!R:R,"Direct",Roster!G:G,"AUH1") -> 5 | H14: =COUNTIFS(Roster!V:V,"SL",Roster!Q:Q,"ICQA",Roster!L:L,"Night Shift",Roster!R:R,"Direct",Roster!G:G,"AUH1") -> 0 | I14: =COUNTIFS(Roster!V:V,"AB",Roster!Q:Q,"ICQA",Roster!L:L,"Night Shift",Roster!R:R,"Direct",Roster!G:G,"AUH1")+COUNTIFS(Roster!V:V,"ABWI",Roster!Q:Q,"ICQA",Roster!L:L,"Night Shift",Roster!R:R,"Direct",Roster!G:G,"AUH1") -> 0 | J14: =SUM(G14:I14,)+SUM(C14:E14) -> 7 | K14: =(J14-D14)-C14-F14 -> 5 | L14: 0.965 | M14: =(G14-F14)/(K14) -> 1 | N14: =G14/K14 -> 1 | T14: Night Shift | U14: =COUNTIFS(Roster!V:V,"0",Roster!Q:Q,"Warehouse Deals",Roster!L:L,"Mid Shift",Roster!R:R,"Direct",Roster!G:G,"AUH3")+COUNTIFS(Roster!V:V,"0",Roster!Q:Q,"Warehouse Deals",Roster!L:L,"Mid Shift",Roster!R:R,"Direct",Roster!G:G,"DDB1") -> 0 | V14: =COUNTIFS(Roster!V:V,"OFF",Roster!Q:Q,"Warehouse Deals",Roster!L:L,"Night Shift",Roster!R:R,"Direct",Roster!G:G,"AUH3")+COUNTIFS(Roster!V:V,"OFF",Roster!Q:Q,"Warehouse Deals",Roster!L:L,"Night Shift",Roster!R:R,"Direct",Roster!G:G,"DDB1") -> 21 | W14: =COUNTIFS(Roster!V:V,"PL",Roster!Q:Q,"Warehouse Deals",Roster!L:L,"Night Shift",Roster!R:R,"Direct",Roster!G:G,"AUH3")+COUNTIFS(Roster!V:V,"PL",Roster!Q:Q,"Warehouse Deals",Roster!L:L,"Night Shift",Roster!R:R,"Direct",Roster!G:G,"DDB1") -> 1 | X14: =COUNTIFS(Table1[[#All],[Building]],"AUH3",Table1[[#All],[Shift]],"Night Shift",Table1[[#All],[OFF1]],"OT",Table1[[#All],[Department]],Dashboard!S12)+COUNTIFS(Table1[[#All],[Building]],"AUH3",Table1[[#All],[Shift]],"Night Shift",Table1[[#All],[OFF2]],"OT",Table1[[#All],[Department]],Dashboard!S12) -> 0 | Y14: =COUNTIFS(Roster!V:V,"P",Roster!Q:Q,"Warehouse Deals",Roster!L:L,"Night Shift",Roster!R:R,"Direct",Roster!G:G,"AUH3")+COUNTIFS(Roster!V:V,"P",Roster!Q:Q,"Warehouse Deals",Roster!L:L,"Night Shift",Roster!R:R,"Direct",Roster!G:G,"DDB1") -> 38 | Z14: =COUNTIFS(Roster!V:V,"SL",Roster!Q:Q,"Warehouse Deals",Roster!L:L,"Night Shift",Roster!R:R,"Direct",Roster!G:G,"AUH3")+COUNTIFS(Roster!V:V,"SL",Roster!Q:Q,"Warehouse Deals",Roster!L:L,"Night Shift",Roster!R:R,"Direct",Roster!G:G,"DDB1") -> 1 | AA14: =COUNTIFS(Roster!V:V,"AB",Roster!Q:Q,"Warehouse Deals",Roster!L:L,"Night Shift",Roster!R:R,"Direct",Roster!G:G,"AUH3")+COUNTIFS(Roster!V:V,"AB",Roster!Q:Q,"Warehouse Deals",Roster!L:L,"Night Shift",Roster!R:R,"Direct",Roster!G:G,"DDB1")+COUNTIFS(Roster!V:V,"ABWI",Roster!Q:Q,"Warehouse Deals",Roster!L:L,"Night Shift",Roster!R:R,"Direct",Roster!G:G,"AUH3")+COUNTIFS(Roster!V:V,"ABWI",Roster!Q:Q,"Warehouse Deals",Roster!L:L,"Night Shift",Roster!R:R,"Direct",Roster!G:G,"DDB1") -> 0 | AB14: =SUM(Y14:AA14,)+SUM(U14:W14) -> 61 | AC14: =(AB14-V14)-U14-X14 -> 40 | AD14: =Y14/AC14 -> 0.95 | AG14: Night Shift | AH14: =COUNTIFS(Roster!V:V,"0",Roster!Q:Q,"Warehouse Deals",Roster!L:L,"Night Shift",Roster!R:R,"Support",Roster!G:G,"DAD1") -> 0 | AI14: =COUNTIFS(Roster!V:V,"OFF",Roster!Q:Q,"Warehouse Deals",Roster!L:L,"Night Shift",Roster!R:R,"Support",Roster!G:G,"DAD1") -> 2 | AJ14: =COUNTIFS(Roster!V:V,"PL",Roster!Q:Q,"Warehouse Deals",Roster!L:L,"Night Shift",Roster!R:R,"Support",Roster!G:G,"DAD1") -> 0 | AK14: =COUNTIFS(Roster!V:V,"P",Roster!Q:Q,"Warehouse Deals",Roster!L:L,"Night Shift",Roster!R:R,"Support",Roster!G:G,"DAD1") -> 10 | AL14: =COUNTIFS(Table1[[#All],[Building]],"DAD1",Table1[[#All],[Shift]],"Night Shift",Table1[[#All],[OFF1]],"OT",Table1[[#All],[Type]],"Support")+COUNTIFS(Table1[[#All],[Building]],"DAD1",Table1[[#All],[Shift]],"Night Shift",Table1[[#All],[OFF1]],"OT",Table1[[#All],[Type]],"Support") -> 0 | AM14: =COUNTIFS(Roster!V:V,"SL",Roster!Q:Q,"Warehouse Deals",Roster!L:L,"Night Shift",Roster!R:R,"Support",Roster!G:G,"DAD1") -> 0 | AN14: =COUNTIFS(Roster!V:V,"AB",Roster!Q:Q,"Warehouse Deals",Roster!L:L,"Night Shift",Roster!R:R,"Support",Roster!G:G,"DAD1")+COUNTIFS(Roster!V:V,"ABWI",Roster!Q:Q,"Warehouse Deals",Roster!L:L,"Night Shift",Roster!R:R,"Support",Roster!G:G,"DAD1") -> 0 | AO14: =SUM(AM14:AN14,)+SUM(AH14:AK14) -> 12 | AP14: =(AO14-AI14)-AH14 -> 10 | AQ14: =AK14/AP14 -> 1
A15: ICQA Total | C15: =SUM(C12:C14) -> 0 | D15: =SUM(D12:D14) -> 13 | E15: =SUM(E12:E14) -> 1 | F15: =SUM(F12:F14) -> 0 | G15: =SUM(G12:G14) -> 35 | H15: =SUM(H12:H14) -> 1 | I15: =SUM(I12:I14) -> 0 | J15: =SUM(J12:J14) -> 50 | K15: =SUM(K12:K14) -> 37 | L15: 0.88391892 | M15: =(G15-F15)/(K15) -> 0.94594595 | N15: =G15/K15 -> 0.94594595 | O15: =L15*K15 -> 32.705 | P15: =G15-F15 -> 35 | Q15: =P15-O15 -> 2.295 | S15: SC Total | U15: =SUM(U12:U14) -> 0 | V15: =SUM(V12:V14) -> 33 | W15: =SUM(W12:W14) -> 1 | X15: =SUM(X12:X14) -> 0 | Y15: =SUM(Y12:Y14) -> 65 | Z15: =SUM(Z12:Z14) -> 1 | AA15: =SUM(AA12:AA14) -> 0 | AB15: =SUM(AB12:AB14) -> 100 | AC15: =SUM(AC12:AC14) -> 67 | AF15: Warehouse Deals | AH15: =SUM(AH12:AH14) -> 0 | AI15: =SUM(AI12:AI14) -> 2 | AJ15: =SUM(AJ12:AJ14) -> 0 | AK15: =SUM(AK12:AK14) -> 10 | AL15: =SUM(AL12:AL14) -> 0 | AM15: =SUM(AM12:AM14) -> 0 | AN15: =SUM(AN12:AN14) -> 0 | AO15: =SUM(AO12:AO14) -> 12 | AP15: =SUM(AP12:AP14) -> 10
A16: Inbound | B16: Day Shift | C16: =COUNTIFS(Roster!V:V,"0",Roster!Q:Q,"Inbound",Roster!L:L,"Day Shift",Roster!R:R,"Direct",Roster!G:G,"AUH1") -> 0 | D16: =COUNTIFS(Roster!V:V,"OFF",Roster!Q:Q,"Inbound",Roster!L:L,"Day Shift",Roster!R:R,"Direct",Roster!G:G,"AUH1") -> 137 | E16: =COUNTIFS(Roster!V:V,"PL",Roster!Q:Q,"Inbound",Roster!L:L,"Day Shift",Roster!R:R,"Direct",Roster!G:G,"AUH1") -> 2 | F16: =COUNTIFS(Table1[[#All],[Building]],"AUH1",Table1[[#All],[Shift]],"Day Shift",Table1[[#All],[OFF1]],"OT",Table1[[#All],[Department]],Dashboard!A16)+COUNTIFS(Table1[[#All],[Building]],"AUH1",Table1[[#All],[Shift]],"Day Shift",Table1[[#All],[OFF2]],"OT",Table1[[#All],[Department]],Dashboard!A16) -> 0 | G16: =COUNTIFS(Roster!V:V,"P",Roster!Q:Q,"Inbound",Roster!L:L,"Day Shift",Roster!R:R,"Direct",Roster!G:G,"AUH1") -> 85 | H16: =COUNTIFS(Roster!V:V,"SL",Roster!Q:Q,"Inbound",Roster!L:L,"Day Shift",Roster!R:R,"Direct",Roster!G:G,"AUH1") -> 3 | I16: =COUNTIFS(Roster!V:V,"AB",Roster!Q:Q,"Inbound",Roster!L:L,"Day Shift",Roster!R:R,"Direct",Roster!G:G,"AUH1")+COUNTIFS(Roster!V:V,"ABWI",Roster!Q:Q,"Inbound",Roster!L:L,"Day Shift",Roster!R:R,"Direct",Roster!G:G,"AUH1") -> 2 | J16: =SUM(G16:I16,)+SUM(C16:E16) -> 229 | K16: =(J16-D16)-C16-F16 -> 92 | L16: 0.89131579 | M16: =(G16-F16)/(K16) -> 0.92391304 | N16: =G16/K16 -> 0.92391304 | AF16: Grand Total | AH16: =AH15 -> 0 | AI16: =AI15 -> 2 | AJ16: =AJ15 -> 0 | AK16: =AK15 -> 10 | AL16: =AL15 -> 0 | AM16: =AM15 -> 0 | AN16: =AN15 -> 0 | AO16: =AO15 -> 12 | AP16: =AP15 -> 10
B17: Mid Shift | C17: =COUNTIFS(Roster!V:V,"0",Roster!Q:Q,"Inbound",Roster!L:L,"Mid Shift",Roster!R:R,"Direct",Roster!G:G,"AUH1") -> 0 | D17: =COUNTIFS(Roster!V:V,"OFF",Roster!Q:Q,"Inbound",Roster!L:L,"Mid Shift",Roster!R:R,"Direct",Roster!G:G,"AUH1") -> 0 | E17: =COUNTIFS(Roster!V:V,"PL",Roster!Q:Q,"Inbound",Roster!L:L,"Mid Shift",Roster!R:R,"Direct",Roster!G:G,"AUH1") -> 0 | F17: =COUNTIFS(Table1[[#All],[Building]],"AUH1",Table1[[#All],[Shift]],"Mid Shift",Table1[[#All],[OFF1]],"OT",Table1[[#All],[Department]],Dashboard!A16)+COUNTIFS(Table1[[#All],[Building]],"AUH1",Table1[[#All],[Shift]],"Mid Shift",Table1[[#All],[OFF2]],"OT",Table1[[#All],[Department]],Dashboard!A16) -> 0 | G17: =COUNTIFS(Roster!V:V,"P",Roster!Q:Q,"Inbound",Roster!L:L,"Mid Shift",Roster!R:R,"Direct",Roster!G:G,"AUH1") -> 0 | H17: =COUNTIFS(Roster!V:V,"SL",Roster!Q:Q,"Inbound",Roster!L:L,"Mid Shift",Roster!R:R,"Direct",Roster!G:G,"AUH1") -> 0 | I17: =COUNTIFS(Roster!V:V,"AB",Roster!Q:Q,"Inbound",Roster!L:L,"Mid Shift",Roster!R:R,"Direct",Roster!G:G,"AUH1")+COUNTIFS(Roster!V:V,"ABWI",Roster!Q:Q,"Inbound",Roster!L:L,"Mid Shift",Roster!R:R,"Direct",Roster!G:G,"AUH1") -> 0 | J17: =SUM(G17:I17,)+SUM(C17:E17) -> 0 | K17: =(J17-D17)-C17-F17 -> 0 | M17: =(G17-F17)/(K17) -> #DIV/0! | N17: =G17/K17 -> #DIV/0! | S17: Department | T17: Shift | U17: 0 | V17: OFF | W17: PL | X17: OT | Y17: Present | Z17: SL | AA17: AB/ABWI | AB17: Grand Total | AC17: Scheduled | AD17: %
B18: Night Shift | C18: =COUNTIFS(Roster!V:V,"0",Roster!Q:Q,"Inbound",Roster!L:L,"Night Shift",Roster!R:R,"Direct",Roster!G:G,"AUH1") -> 0 | D18: =COUNTIFS(Roster!V:V,"OFF",Roster!Q:Q,"Inbound",Roster!L:L,"Night Shift",Roster!R:R,"Direct",Roster!G:G,"AUH1") -> 34 | E18: =COUNTIFS(Roster!V:V,"PL",Roster!Q:Q,"Inbound",Roster!L:L,"Night Shift",Roster!R:R,"Direct",Roster!G:G,"AUH1") -> 3 | F18: =COUNTIFS(Table1[[#All],[Building]],"AUH1",Table1[[#All],[Shift]],"Night Shift",Table1[[#All],[OFF1]],"OT",Table1[[#All],[Department]],Dashboard!A16)+COUNTIFS(Table1[[#All],[Building]],"AUH1",Table1[[#All],[Shift]],"Night Shift",Table1[[#All],[OFF2]],"OT",Table1[[#All],[Department]],Dashboard!A16) -> 0 | G18: =COUNTIFS(Roster!V:V,"P",Roster!Q:Q,"Inbound",Roster!L:L,"Night Shift",Roster!R:R,"Direct",Roster!G:G,"AUH1") -> 45 | H18: =COUNTIFS(Roster!V:V,"SL",Roster!Q:Q,"Inbound",Roster!L:L,"Night Shift",Roster!R:R,"Direct",Roster!G:G,"AUH1") -> 0 | I18: =COUNTIFS(Roster!V:V,"AB",Roster!Q:Q,"Inbound",Roster!L:L,"Night Shift",Roster!R:R,"Direct",Roster!G:G,"AUH1")+COUNTIFS(Roster!V:V,"ABWI",Roster!Q:Q,"Inbound",Roster!L:L,"Night Shift",Roster!R:R,"Direct",Roster!G:G,"AUH1") -> 0 | J18: =SUM(G18:I18,)+SUM(C18:E18) -> 82 | K18: =(J18-D18)-C18-F18 -> 48 | L18: 0.88336735 | M18: =(G18-F18)/(K18) -> 0.9375 | N18: =G18/K18 -> 0.9375 | S18: Warehouse Deals | T18: Regular | U18: =COUNTIFS(Roster!G:G,"AUH3",Roster!R:R,"Direct",Roster!V:V,"0",Roster!E:E,"Regular")+COUNTIFS(Roster!G:G,"DDB1",Roster!R:R,"Direct",Roster!V:V,"0",Roster!E:E,"Regular") -> 0 | V18: =COUNTIFS(Roster!G:G,"AUH3",Roster!R:R,"Direct",Roster!V:V,"OFF",Roster!E:E,"Regular")+COUNTIFS(Roster!G:G,"DDB1",Roster!R:R,"Direct",Roster!V:V,"OFF",Roster!E:E,"Regular") -> 5 | W18: =COUNTIFS(Roster!G:G,"AUH3",Roster!R:R,"Direct",Roster!V:V,"PL",Roster!E:E,"Regular")+COUNTIFS(Roster!G:G,"DDB1",Roster!R:R,"Direct",Roster!V:V,"PL",Roster!E:E,"Regular") -> 0 | X18: =COUNTIFS(Table1[[#All],[Building]],"AUH3",Table1[[#All],[Employment Type]],"Regular",Table1[[#All],[OFF1]],"OT",Table1[[#All],[Department]],Dashboard!S18)+COUNTIFS(Table1[[#All],[Building]],"AUH3",Table1[[#All],[Employment Type]],"Regular",Table1[[#All],[OFF2]],"OT",Table1[[#All],[Department]],Dashboard!S18) -> 0 | Y18: =COUNTIFS(Roster!G:G,"AUH3",Roster!R:R,"Direct",Roster!V:V,"P",Roster!E:E,"Regular")+COUNTIFS(Roster!G:G,"DDB1",Roster!R:R,"Direct",Roster!V:V,"P",Roster!E:E,"Regular") -> 9 | Z18: =COUNTIFS(Roster!G:G,"AUH3",Roster!R:R,"Direct",Roster!V:V,"SL",Roster!E:E,"Regular")+COUNTIFS(Roster!G:G,"DDB1",Roster!R:R,"Direct",Roster!V:V,"SL",Roster!E:E,"Regular") -> 0 | AA18: =COUNTIFS(Roster!G:G,"AUH3",Roster!R:R,"Direct",Roster!V:V,"AB",Roster!E:E,"Regular")+COUNTIFS(Roster!G:G,"DDB1",Roster!R:R,"Direct",Roster!V:V,"AB",Roster!E:E,"Regular")+COUNTIFS(Roster!G:G,"AUH3",Roster!R:R,"Direct",Roster!V:V,"ABWI",Roster!E:E,"Regular")+COUNTIFS(Roster!G:G,"DDB1",Roster!R:R,"Direct",Roster!V:V,"ABWI",Roster!E:E,"Regular") -> 0 | AB18: =SUM(Y18:AA18,)+SUM(U18:W18) -> 14 | AC18: =(AB18-V18)-U18 -> 9 | AD18: =Y18/AC18 -> 1 | AL18: =1443+83 -> 1526
A19: Inbound Total | C19: =SUM(C16:C18) -> 0 | D19: =SUM(D16:D18) -> 171 | E19: =SUM(E16:E18) -> 5 | F19: =SUM(F16:F18) -> 0 | G19: =SUM(G16:G18) -> 130 | H19: =SUM(H16:H18) -> 3 | I19: =SUM(I16:I18) -> 2 | J19: =SUM(J16:J18) -> 311 | K19: =SUM(K16:K18) -> 140 | L19: 0.88861111 | M19: =(G19-F19)/(K19) -> 0.92857143 | N19: =G19/K19 -> 0.92857143 | O19: =L19*K19 -> 124.40556 | P19: =G19-F19 -> 130 | Q19: =P19-O19 -> 5.5944444 | T19: Temporary | U19: =COUNTIFS(Roster!G:G,"AUH3",Roster!R:R,"Direct",Roster!V:V,"0",Roster!E:E,"Temporary")+COUNTIFS(Roster!G:G,"DDB1",Roster!R:R,"Direct",Roster!V:V,"0",Roster!E:E,"Temporary") -> 0 | V19: =COUNTIFS(Roster!G:G,"AUH3",Roster!R:R,"Direct",Roster!V:V,"OFF",Roster!E:E,"Temporary")+COUNTIFS(Roster!G:G,"DDB1",Roster!R:R,"Direct",Roster!V:V,"OFF",Roster!E:E,"Temporary") -> 28 | W19: =COUNTIFS(Roster!G:G,"AUH3",Roster!R:R,"Direct",Roster!V:V,"PL",Roster!E:E,"Temporary")+COUNTIFS(Roster!G:G,"DDB1",Roster!R:R,"Direct",Roster!V:V,"PL",Roster!E:E,"Temporary") -> 1 | X19: =COUNTIFS(Table1[[#All],[Building]],"AUH3",Table1[[#All],[Employment Type]],"Temporary",Table1[[#All],[OFF1]],"OT",Table1[[#All],[Department]],Dashboard!S18)+COUNTIFS(Table1[[#All],[Building]],"AUH3",Table1[[#All],[Employment Type]],"Temporary",Table1[[#All],[OFF2]],"OT",Table1[[#All],[Department]],Dashboard!S18) -> 0 | Y19: =COUNTIFS(Roster!G:G,"AUH3",Roster!R:R,"Direct",Roster!V:V,"P",Roster!E:E,"Temporary")+COUNTIFS(Roster!G:G,"DDB1",Roster!R:R,"Direct",Roster!V:V,"P",Roster!E:E,"Temporary") -> 56 | Z19: =COUNTIFS(Roster!G:G,"AUH3",Roster!R:R,"Direct",Roster!V:V,"SL",Roster!E:E,"Temporary")+COUNTIFS(Roster!G:G,"DDB1",Roster!R:R,"Direct",Roster!V:V,"SL",Roster!E:E,"Temporary") -> 1 | AA19: =COUNTIFS(Roster!G:G,"AUH3",Roster!R:R,"Direct",Roster!V:V,"AB",Roster!E:E,"Temporary")+COUNTIFS(Roster!G:G,"DDB1",Roster!R:R,"Direct",Roster!V:V,"AB",Roster!E:E,"Temporary")+COUNTIFS(Roster!G:G,"AUH3",Roster!R:R,"Direct",Roster!V:V,"ABWI",Roster!E:E,"Temporary")+COUNTIFS(Roster!G:G,"DDB1",Roster!R:R,"Direct",Roster!V:V,"ABWI",Roster!E:E,"Temporary") -> 0 | AB19: =SUM(Y19:AA19,)+SUM(U19:W19) -> 86 | AC19: =(AB19-V19)-U19 -> 58 | AD19: =Y19/AC19 -> 0.96551724
A20: Outbound | B20: Day Shift | C20: =COUNTIFS(Roster!V:V,"0",Roster!Q:Q,"Outbound",Roster!L:L,"Day Shift",Roster!R:R,"Direct",Roster!G:G,"AUH1") -> 0 | D20: =COUNTIFS(Roster!V:V,"OFF",Roster!Q:Q,"Outbound",Roster!L:L,"Day Shift",Roster!R:R,"Direct",Roster!G:G,"AUH1") -> 67 | E20: =COUNTIFS(Roster!V:V,"PL",Roster!Q:Q,"Outbound",Roster!L:L,"Day Shift",Roster!R:R,"Direct",Roster!G:G,"AUH1") -> 13 | F20: =COUNTIFS(Table1[[#All],[Building]],"AUH1",Table1[[#All],[Shift]],"Day Shift",Table1[[#All],[OFF1]],"OT",Table1[[#All],[Department]],Dashboard!A20)+COUNTIFS(Table1[[#All],[Building]],"AUH1",Table1[[#All],[Shift]],"Day Shift",Table1[[#All],[OFF2]],"OT",Table1[[#All],[Department]],Dashboard!A20) -> 12 | G20: =COUNTIFS(Roster!V:V,"P",Roster!Q:Q,"Outbound",Roster!L:L,"Day Shift",Roster!R:R,"Direct",Roster!G:G,"AUH1") -> 179 | H20: =COUNTIFS(Roster!V:V,"SL",Roster!Q:Q,"Outbound",Roster!L:L,"Day Shift",Roster!R:R,"Direct",Roster!G:G,"AUH1") -> 5 | I20: =COUNTIFS(Roster!V:V,"AB",Roster!Q:Q,"Outbound",Roster!L:L,"Day Shift",Roster!R:R,"Direct",Roster!G:G,"AUH1")+COUNTIFS(Roster!V:V,"ABWI",Roster!Q:Q,"Outbound",Roster!L:L,"Day Shift",Roster!R:R,"Direct",Roster!G:G,"AUH1") -> 0 | J20: =SUM(G20:I20,)+SUM(C20:E20) -> 264 | K20: =(J20-D20)-C20-F20 -> 185 | L20: 0.87055556 | M20: =(G20-F20)/(K20) -> 0.9027027 | N20: =G20/K20 -> 0.96756757 | S20: SC Total | U20: =SUM(U17:U19) -> 0 | V20: =SUM(V17:V19) -> 33 | W20: =SUM(W17:W19) -> 1 | X20: =SUM(X17:X19) -> 0 | Y20: =SUM(Y17:Y19) -> 65 | Z20: =SUM(Z17:Z19) -> 1 | AA20: =SUM(AA17:AA19) -> 0 | AB20: =SUM(AB17:AB19) -> 100 | AC20: =SUM(AC18:AC19) -> 67
B21: Mid Shift | C21: =COUNTIFS(Roster!V:V,"0",Roster!Q:Q,"Outbound",Roster!L:L,"Mid Shift",Roster!R:R,"Direct",Roster!G:G,"AUH1") -> 0 | D21: =COUNTIFS(Roster!V:V,"OFF",Roster!Q:Q,"Outbound",Roster!L:L,"Mid Shift",Roster!R:R,"Direct",Roster!G:G,"AUH1") -> 0 | E21: =COUNTIFS(Roster!V:V,"PL",Roster!Q:Q,"Outbound",Roster!L:L,"Mid Shift",Roster!R:R,"Direct",Roster!G:G,"AUH1") -> 0 | F21: =COUNTIFS(Table1[[#All],[Building]],"AUH1",Table1[[#All],[Shift]],"Mid Shift",Table1[[#All],[OFF1]],"OT",Table1[[#All],[Department]],Dashboard!A20)+COUNTIFS(Table1[[#All],[Building]],"AUH1",Table1[[#All],[Shift]],"Mid Shift",Table1[[#All],[OFF2]],"OT",Table1[[#All],[Department]],Dashboard!A20) -> 0 | G21: =COUNTIFS(Roster!V:V,"P",Roster!Q:Q,"Outbound",Roster!L:L,"Mid Shift",Roster!R:R,"Direct",Roster!G:G,"AUH1") -> 0 | H21: =COUNTIFS(Roster!V:V,"SL",Roster!Q:Q,"Outbound",Roster!L:L,"Mid Shift",Roster!R:R,"Direct",Roster!G:G,"AUH1") -> 0 | I21: =COUNTIFS(Roster!V:V,"AB",Roster!Q:Q,"Outbound",Roster!L:L,"Mid Shift",Roster!R:R,"Direct",Roster!G:G,"AUH1")+COUNTIFS(Roster!V:V,"ABWI",Roster!Q:Q,"Outbound",Roster!L:L,"Mid Shift",Roster!R:R,"Direct",Roster!G:G,"AUH1") -> 0 | J21: =SUM(G21:I21,)+SUM(C21:E21) -> 0 | K21: =(J21-D21)-C21-F21 -> 0 | M21: =(G21-F21)/(K21) -> #DIV/0! | N21: =G21/K21 -> #DIV/0!
B22: Night Shift | C22: =COUNTIFS(Roster!V:V,"0",Roster!Q:Q,"Outbound",Roster!L:L,"Night Shift",Roster!R:R,"Direct",Roster!G:G,"AUH1") -> 0 | D22: =COUNTIFS(Roster!V:V,"OFF",Roster!Q:Q,"Outbound",Roster!L:L,"Night Shift",Roster!R:R,"Direct",Roster!G:G,"AUH1") -> 112 | E22: =COUNTIFS(Roster!V:V,"PL",Roster!Q:Q,"Outbound",Roster!L:L,"Night Shift",Roster!R:R,"Direct",Roster!G:G,"AUH1") -> 10 | F22: =COUNTIFS(Table1[[#All],[Building]],"AUH1",Table1[[#All],[Shift]],"Night Shift",Table1[[#All],[OFF1]],"OT",Table1[[#All],[Department]],Dashboard!A20)+COUNTIFS(Table1[[#All],[Building]],"AUH1",Table1[[#All],[Shift]],"Night Shift",Table1[[#All],[OFF2]],"OT",Table1[[#All],[Department]],Dashboard!A20) -> 4 | G22: =COUNTIFS(Roster!V:V,"P",Roster!Q:Q,"Outbound",Roster!L:L,"Night Shift",Roster!R:R,"Direct",Roster!G:G,"AUH1") -> 264 | H22: =COUNTIFS(Roster!V:V,"SL",Roster!Q:Q,"Outbound",Roster!L:L,"Night Shift",Roster!R:R,"Direct",Roster!G:G,"AUH1") -> 1 | I22: =COUNTIFS(Roster!V:V,"AB",Roster!Q:Q,"Outbound",Roster!L:L,"Night Shift",Roster!R:R,"Direct",Roster!G:G,"AUH1")+COUNTIFS(Roster!V:V,"ABWI",Roster!Q:Q,"Outbound",Roster!L:L,"Night Shift",Roster!R:R,"Direct",Roster!G:G,"AUH1") -> 4 | J22: =SUM(G22:I22,)+SUM(C22:E22) -> 391 | K22: =(J22-D22)-C22-F22 -> 275 | L22: 0.90384892 | M22: =(G22-F22)/(K22) -> 0.94545455 | N22: =G22/K22 -> 0.96 | S22: Shift | T22: Total HC | U22: Unscheduled | V22: Schedule to Work | W22: PL | X22: OT | Y22: UPL | Z22: Present | AA22: Present % | AB22: LM Target | AC22: Target Achievement
A23: Outbound Total | C23: =SUM(C20:C22) -> 0 | D23: =SUM(D20:D22) -> 179 | E23: =SUM(E20:E22) -> 23 | F23: =SUM(F20:F22) -> 16 | G23: =SUM(G20:G22) -> 443 | H23: =SUM(H20:H22) -> 6 | I23: =SUM(I20:I22) -> 4 | J23: =SUM(J20:J22) -> 655 | K23: =SUM(K20:K22) -> 460 | L23: 0.89076419 | M23: =(G23-F23)/(K23) -> 0.92826087 | N23: =G23/K23 -> 0.96304348 | O23: =L23*K23 -> 409.75153 | P23: =G23-F23 -> 427 | Q23: =P23-O23 -> 17.248472 | S23: Regular | T23: =COUNTIFS(Roster!G:G,"AUH3",Roster!E:E,"Regular")+COUNTIFS(Roster!G:G,"DDB1",Roster!E:E,"Regular",Roster!R:R,"Direct") -> 14 | U23: =COUNTIFS(Roster!G:G,"AUH3",Roster!E:E,"Regular",Roster!V:V,"OFF",Roster!R:R,"Direct")+COUNTIFS(Roster!G:G,"DDB1",Roster!E:E,"Regular",Roster!V:V,"OFF",Roster!R:R,"Direct") -> 5 | V23: =SUMIFS($AC$18:$AC$19,$T$18:$T$19,"Regular") -> 9 | W23: =COUNTIFS(Roster!G:G,"AUH3",Roster!E:E,"Regular",Roster!V:V,"PL",Roster!R:R,"Direct")+COUNTIFS(Roster!G:G,"DDB1",Roster!E:E,"Regular",Roster!V:V,"PL",Roster!R:R,"Direct") -> 0 | X23: =COUNTIFS(Table1[[#All],[Building]],"AUH3",Table1[[#All],[Employment Type]],"Regular",Table1[[#All],[OFF1]],"OT",Table1[[#All],[Department]],Dashboard!S23)+COUNTIFS(Table1[[#All],[Building]],"AUH3",Table1[[#All],[Employment Type]],"Regular",Table1[[#All],[OFF2]],"OT",Table1[[#All],[Department]],Dashboard!S23) -> 0 | Y23: =COUNTIFS(Roster!G:G,"AUH3",Roster!E:E,"Regular",Roster!V:V,"AB",Roster!R:R,"Direct")+COUNTIFS(Roster!G:G,"AUH3",Roster!E:E,"Regular",Roster!V:V,"SL",Roster!R:R,"Direct")+COUNTIFS(Roster!G:G,"AUH3",Roster!E:E,"Regular",Roster!V:V,"ABWI",Roster!R:R,"Direct")+COUNTIFS(Roster!G:G,"DDB1",Roster!E:E,"Regular",Roster!V:V,"ABWI") -> 0 | Z23: =V23-W23-Y23 -> 9 | AA23: =Z23/V23 -> 1 | AB23: 0.92384615 | AC23: =AA23/AB23 -> 1.0824313
A24: CRET | B24: Day Shift | C24: =COUNTIFS(Roster!V:V,"0",Roster!Q:Q,"CRET",Roster!L:L,"Day Shift",Roster!R:R,"Direct",Roster!G:G,"AUH1") -> 0 | D24: =COUNTIFS(Roster!V:V,"OFF",Roster!Q:Q,"CRET",Roster!L:L,"Day Shift",Roster!R:R,"Direct",Roster!G:G,"AUH1") -> 33 | E24: =COUNTIFS(Roster!V:V,"PL",Roster!Q:Q,"CRET",Roster!L:L,"Day Shift",Roster!R:R,"Direct",Roster!G:G,"AUH1") -> 7 | F24: =COUNTIFS(Table1[[#All],[Building]],"AUH1",Table1[[#All],[Shift]],"Day Shift",Table1[[#All],[OFF1]],"OT",Table1[[#All],[Department]],Dashboard!A24)+COUNTIFS(Table1[[#All],[Building]],"AUH1",Table1[[#All],[Shift]],"Day Shift",Table1[[#All],[OFF2]],"OT",Table1[[#All],[Department]],Dashboard!A24) -> 0 | G24: =COUNTIFS(Roster!V:V,"P",Roster!Q:Q,"CRET",Roster!L:L,"Day Shift",Roster!R:R,"Direct",Roster!G:G,"AUH1") -> 88 | H24: =COUNTIFS(Roster!V:V,"SL",Roster!Q:Q,"CRET",Roster!L:L,"Day Shift",Roster!R:R,"Direct",Roster!G:G,"AUH1") -> 3 | I24: =COUNTIFS(Roster!V:V,"AB",Roster!Q:Q,"CRET",Roster!L:L,"Day Shift",Roster!R:R,"Direct",Roster!G:G,"AUH1")+COUNTIFS(Roster!V:V,"ABWI",Roster!Q:Q,"CRET",Roster!L:L,"Day Shift",Roster!R:R,"Direct",Roster!G:G,"AUH1") -> 1 | J24: =SUM(G24:I24,)+SUM(C24:E24) -> 132 | K24: =(J24-D24)-C24-F24 -> 99 | L24: 0.905 | M24: =(G24-F24)/(K24) -> 0.88888889 | N24: =G24/K24 -> 0.88888889 | S24: Temporary | T24: =COUNTIFS(Roster!G:G,"AUH3",Roster!E:E,"Temporary")+COUNTIFS(Roster!G:G,"DDB1",Roster!E:E,"Temporary",Roster!R:R,"Direct") -> 86 | U24: =COUNTIFS(Roster!G:G,"AUH3",Roster!E:E,"Temporary",Roster!V:V,"OFF",Roster!R:R,"Direct")+COUNTIFS(Roster!G:G,"DDB1",Roster!E:E,"Temporary",Roster!V:V,"OFF",Roster!R:R,"Direct") -> 28 | V24: =SUMIFS($AC$18:$AC$19,$T$18:$T$19,"Temporary") -> 58 | W24: =COUNTIFS(Roster!G:G,"AUH3",Roster!E:E,"Temporary",Roster!V:V,"PL",Roster!R:R,"Direct")+COUNTIFS(Roster!G:G,"DDB1",Roster!E:E,"Temporary",Roster!V:V,"PL",Roster!R:R,"Direct") -> 1 | X24: =COUNTIFS(Table1[[#All],[Building]],"AUH3",Table1[[#All],[Employment Type]],"Temporary",Table1[[#All],[OFF1]],"OT",Table1[[#All],[Department]],Dashboard!S23)+COUNTIFS(Table1[[#All],[Building]],"AUH3",Table1[[#All],[Employment Type]],"Temporary",Table1[[#All],[OFF2]],"OT",Table1[[#All],[Department]],Dashboard!S23) -> 0 | Y24: =COUNTIFS(Roster!G:G,"AUH3",Roster!E:E,"Temporary",Roster!V:V,"AB")+COUNTIFS(Roster!G:G,"AUH3",Roster!E:E,"Temporary",Roster!V:V,"SL")+COUNTIFS(Roster!G:G,"AUH3",Roster!E:E,"Temporary",Roster!V:V,"ABWI")+COUNTIFS(Roster!G:G,"DDB1",Roster!E:E,"Temporary",Roster!V:V,"ABWI",Roster!R:R,"Direct") -> 1 | Z24: =V24-W24-Y24 -> 56 | AA24: =Z24/V24 -> 0.96551724 | AB24: 0.90181818 | AC24: =AA24/AB24 -> 1.070634
B25: Mid Shift | C25: =COUNTIFS(Roster!V:V,"0",Roster!Q:Q,"CRET",Roster!L:L,"Mid Shift",Roster!R:R,"Direct",Roster!G:G,"AUH1") -> 0 | D25: =COUNTIFS(Roster!V:V,"OFF",Roster!Q:Q,"CRET",Roster!L:L,"Mid Shift",Roster!R:R,"Direct",Roster!G:G,"AUH1") -> 0 | E25: =COUNTIFS(Roster!V:V,"PL",Roster!Q:Q,"CRET",Roster!L:L,"Mid Shift",Roster!R:R,"Direct",Roster!G:G,"AUH1") -> 0 | F25: =COUNTIFS(Table1[[#All],[Building]],"AUH1",Table1[[#All],[Shift]],"Mid Shift",Table1[[#All],[OFF1]],"OT",Table1[[#All],[Department]],Dashboard!A24)+COUNTIFS(Table1[[#All],[Building]],"AUH1",Table1[[#All],[Shift]],"Mid Shift",Table1[[#All],[OFF2]],"OT",Table1[[#All],[Department]],Dashboard!A24) -> 0 | G25: =COUNTIFS(Roster!V:V,"P",Roster!Q:Q,"CRET",Roster!L:L,"Mid Shift",Roster!R:R,"Direct",Roster!G:G,"AUH1") -> 0 | H25: =COUNTIFS(Roster!V:V,"SL",Roster!Q:Q,"CRET",Roster!L:L,"Mid Shift",Roster!R:R,"Direct",Roster!G:G,"AUH1") -> 0 | I25: =COUNTIFS(Roster!V:V,"AB",Roster!Q:Q,"CRET",Roster!L:L,"Mid Shift",Roster!R:R,"Direct",Roster!G:G,"AUH1")+COUNTIFS(Roster!V:V,"ABWI",Roster!Q:Q,"CRET",Roster!L:L,"Mid Shift",Roster!R:R,"Direct",Roster!G:G,"AUH1") -> 0 | J25: =SUM(G25:I25,)+SUM(C25:E25) -> 0 | K25: =(J25-D25)-C25-F25 -> 0 | M25: =(G25-F25)/(K25) -> #DIV/0! | N25: =G25/K25 -> #DIV/0!
B26: Night Shift | C26: =COUNTIFS(Roster!V:V,"0",Roster!Q:Q,"CRET",Roster!L:L,"Night Shift",Roster!R:R,"Direct",Roster!G:G,"AUH1") -> 0 | D26: =COUNTIFS(Roster!V:V,"OFF",Roster!Q:Q,"CRET",Roster!L:L,"Night Shift",Roster!R:R,"Direct",Roster!G:G,"AUH1") -> 26 | E26: =COUNTIFS(Roster!V:V,"PL",Roster!Q:Q,"CRET",Roster!L:L,"Night Shift",Roster!R:R,"Direct",Roster!G:G,"AUH1") -> 2 | F26: =COUNTIFS(Table1[[#All],[Building]],"AUH1",Table1[[#All],[Shift]],"Night Shift",Table1[[#All],[OFF1]],"OT",Table1[[#All],[Department]],Dashboard!A24)+COUNTIFS(Table1[[#All],[Building]],"AUH1",Table1[[#All],[Shift]],"Night Shift",Table1[[#All],[OFF2]],"OT",Table1[[#All],[Department]],Dashboard!A24) -> 0 | G26: =COUNTIFS(Roster!V:V,"P",Roster!Q:Q,"CRET",Roster!L:L,"Night Shift",Roster!R:R,"Direct",Roster!G:G,"AUH1") -> 56 | H26: =COUNTIFS(Roster!V:V,"SL",Roster!Q:Q,"CRET",Roster!L:L,"Night Shift",Roster!R:R,"Direct",Roster!G:G,"AUH1") -> 0 | I26: =COUNTIFS(Roster!V:V,"AB",Roster!Q:Q,"CRET",Roster!L:L,"Night Shift",Roster!R:R,"Direct",Roster!G:G,"AUH1")+COUNTIFS(Roster!V:V,"ABWI",Roster!Q:Q,"CRET",Roster!L:L,"Night Shift",Roster!R:R,"Direct",Roster!G:G,"AUH1") -> 2 | J26: =SUM(G26:I26,)+SUM(C26:E26) -> 86 | K26: =(J26-D26)-C26-F26 -> 60 | L26: 0.915 | M26: =(G26-F26)/(K26) -> 0.93333333 | N26: =G26/K26 -> 0.93333333
A27: CRET Total | C27: =SUM(C24:C26) -> 0 | D27: =SUM(D24:D26) -> 59 | E27: =SUM(E24:E26) -> 9 | F27: =SUM(F24:F26) -> 0 | G27: =SUM(G24:G26) -> 144 | H27: =SUM(H24:H26) -> 3 | I27: =SUM(I24:I26) -> 3 | J27: =SUM(J24:J26) -> 218 | K27: =SUM(K24:K26) -> 159 | L27: 0.90875 | M27: =(G27-F27)/(K27) -> 0.90566038 | N27: =G27/K27 -> 0.90566038 | O27: =L27*K27 -> 144.49125 | P27: =G27-F27 -> 144 | Q27: =P27-O27 -> -0.49125
A28: Grand Total | C28: =C15+C19+C23+C27 -> 0 | D28: =D15+D19+D23+D27 -> 422 | E28: =E15+E19+E23+E27 -> 38 | F28: =F15+F19+F23+F27 -> 16 | G28: =G15+G19+G23+G27 -> 752 | H28: =H15+H19+H23+H27 -> 13 | I28: =I15+I19+I23+I27 -> 9 | J28: =J15+J19+J23+J27 -> 1234 | K28: =K15+K19+K23+K27 -> 796 | L28: =J9 -> 0.89366083 | M28: =(G28-F28)/(K28) -> 0.92462312 | N28: =G28/K28 -> 0.94472362 | O28: =L28*K28 -> 711.35402 | P28: =G28-F28 -> 736 | Q28: =P28-O28 -> 24.645982
E30: =E6/(D6-F6) -> 0.058080808 | F30: DS | G30: =G6/(D6-F6) -> 0.037878788
E31: =E9/(D9-F9) -> 0.048717949 | F31: Overall | G31: =G9/(D9-F9) -> 0.028205128
E32: =E8/(D8-F8) -> 0.0390625 | F32: NS | G32: =G8/(D8-F8) -> 0.018229167

Sheet Roster
A1: Date | B1: 46258 | C1: =TEXT(B1,"dddd") -> Monday | F1: Target | G1: 0.0713 | S1: P | T1: Present | U1: SL
S2: AB | T2: Absent | U2: EL
S3: PL | T3: Any Planned Leave | U3: ABWI
S4: OFF | T4: Weekly Off | U4: 0
A6: S.No | B6: Psoft No | C6: AMZ ID | D6: EMP Name | E6: Employment Type | F6: Country | G6: Building | H6: Column1 | I6: Column2 | J6: LOB | K6: Cost Center | L6: Shift | M6: Shift Difference | N6: OFF1 | O6: OFF2 | P6: Job Title | Q6: Department | R6: Type | S6: 3P | T6: Line Manager Login | U6: Line Manager | V6: Attendance | W6: Remarks | X6: DOJ | Y6: Process Path | Z6: DWD Dashboard | AA6: GB LEAVES
A7: 1 | B7: 206875258 | C7: bakabdal | D7: ABDALLAH ABDALLAH ISSA | E7: Temporary | F7: UAE | G7: AUH1 | H7: =VLOOKUP(Table1[[#This Row],[Psoft No]],[1]Roster!$C$2:$H$1402,6,) -> AUH1 | I7: =Table1[[#This Row],[Building]]=Table1[[#This Row],[Column1]] -> TRUE | J7: FC | K7: 1299 | L7: Day Shift | M7: NA | N7: Sunday | O7: Monday | P7: Warehouse Associate 8W | Q7: CRET | R7: Direct | S7: Dulsco | T7: aanso | U7: Sohail,Anis | V7: OFF | X7: 46051 | Y7: Customer Returns | Z7: Not Present | AA7: 0
A8: 2 | B8: 206873715 | C8: zkasabda | D8: ABDALLAH KASSIM | E8: Temporary | F8: UAE | G8: AUH1 | H8: =VLOOKUP(Table1[[#This Row],[Psoft No]],[1]Roster!$C$2:$H$1402,6,) -> AUH1 | I8: =Table1[[#This Row],[Building]]=Table1[[#This Row],[Column1]] -> TRUE | J8: FC | K8: 1299 | L8: Day Shift | M8: NA | N8: Saturday | O8: Sunday | P8: Warehouse Associate 8W | Q8: CRET | R8: Direct | S8: Dulsco | T8: aanso | U8: Sohail,Anis | V8: =VLOOKUP(Table1[[#This Row],[Psoft No]],[2]Sheet1!$A$2:$G$386,7,0) -> P | X8: 46020 | Y8: Customer Returns | Z8: Present | AA8: 0
A9: 3 | B9: 203679309 | C9: njitaria | D9: Abdel Koudous Njitari Mah | E9: Temporary | F9: UAE | G9: AUH1 | H9: =VLOOKUP(Table1[[#This Row],[Psoft No]],[1]Roster!$C$2:$H$1402,6,) -> AUH1 | I9: =Table1[[#This Row],[Building]]=Table1[[#This Row],[Column1]] -> TRUE | J9: FC | K9: 1299 | L9: Night Shift | M9: NA | N9: Sunday | O9: Monday | P9: Warehouse Associate 12M | Q9: CRET | R9: Direct | S9: Fastlink | T9: aanso | U9: Sohail,Anis | V9: OFF | X9: 45488 | Y9: Customer Returns | Z9: Not Present | AA9: 0
A10: 4 | B10: 204864408 | C10: iddabdud | D10: ABDULMALIK IDDRISU | E10: Temporary | F10: UAE | G10: AUH1 | H10: =VLOOKUP(Table1[[#This Row],[Psoft No]],[1]Roster!$C$2:$H$1402,6,) -> AUH1 | I10: =Table1[[#This Row],[Building]]=Table1[[#This Row],[Column1]] -> TRUE | J10: FC | K10: 1299 | L10: Night Shift | M10: NA | N10: Sunday | O10: Monday | P10: Warehouse Associate 8W | Q10: CRET | R10: Direct | S10: Dulsco | T10: aanso | U10: Sohail,Anis | V10: OFF | X10: 45684 | Y10: Customer Returns | Z10: Not Present | AA10: 0
A11: 5 | B11: 203800376 | C11: kiwanuab | D11: ABDURASHID KIWANUKA | E11: Temporary | F11: UAE | G11: AUH1 | H11: =VLOOKUP(Table1[[#This Row],[Psoft No]],[1]Roster!$C$2:$H$1402,6,) -> AUH1 | I11: =Table1[[#This Row],[Building]]=Table1[[#This Row],[Column1]] -> TRUE | J11: FC | K11: 1299 | L11: Day Shift | M11: NA | N11: Wednesday | O11: Thursday | P11: Warehouse Associate 8W | Q11: CRET | R11: Direct | S11: Dulsco | T11: aanso | U11: Sohail,Anis | V11: =VLOOKUP(Table1[[#This Row],[Psoft No]],[2]Sheet1!$A$2:$G$386,7,0) -> P | X11: 45516 | Y11: Customer Returns | Z11: Present | AA11: 0
A12: 6 | B12: 206953791 | C12: abubodon | D12: ABUBAKAESWIDIQ ODONGO | E12: Temporary | F12: UAE | G12: AUH1 | H12: =VLOOKUP(Table1[[#This Row],[Psoft No]],[1]Roster!$C$2:$H$1402,6,) -> AUH1 | I12: =Table1[[#This Row],[Building]]=Table1[[#This Row],[Column1]] -> TRUE | J12: FC | K12: 1299 | L12: Day Shift | M12: NA | N12: Thursday | O12: Friday | P12: Warehouse Associate 24M | Q12: CRET | R12: Direct | S12: Dulsco | T12: aanso | U12: Sohail,Anis | V12: =VLOOKUP(Table1[[#This Row],[Psoft No]],[2]Sheet1!$A$2:$G$386,7,0) -> P | X12: 46048 | Y12: Customer Returns | Z12: Present | AA12: 0
A13: 7 | B13: 205608373 | C13: tiacquah | D13: ACQUAH TIMOTHY | E13: Temporary | F13: UAE | G13: AUH1 | H13: =VLOOKUP(Table1[[#This Row],[Psoft No]],[1]Roster!$C$2:$H$1402,6,) -> AUH1 | I13: =Table1[[#This Row],[Building]]=Table1[[#This Row],[Column1]] -> TRUE | J13: FC | K13: 1299 | L13: Night Shift | M13: NA | N13: Wednesday | O13: Thursday | P13: Warehouse Associate 8W | Q13: CRET | R13: Direct | S13: Dulsco | T13: aanso | U13: Sohail,Anis | V13: P | X13: 45845 | Y13: Customer Returns | Z13: Present | AA13: 0
A14: 8 | B14: 204869098 | C14: rosadamu | D14: Adams,Rose | E14: Temporary | F14: UAE | G14: AUH1 | H14: =VLOOKUP(Table1[[#This Row],[Psoft No]],[1]Roster!$C$2:$H$1402,6,) -> AUH1 | I14: =Table1[[#This Row],[Building]]=Table1[[#This Row],[Column1]] -> TRUE | J14: FC | K14: 1299 | L14: Night Shift | M14: NA | N14: Friday | O14: Saturday | P14: Warehouse Associate 8W | Q14: CRET | R14: Direct | S14: Quesscorp | T14: aanso | U14: Sohail,Anis | V14: P | X14: 45691 | Y14: Customer Returns | Z14: Present | AA14: 0
A15: 9 | B15: 206875144 | C15: ramaafid | D15: AFIDHU SWAMADU RAMADHANI | E15: Temporary | F15: UAE | G15: AUH1 | H15: =VLOOKUP(Table1[[#This Row],[Psoft No]],[1]Roster!$C$2:$H$1402,6,) -> AUH1 | I15: =Table1[[#This Row],[Building]]=Table1[[#This Row],[Column1]] -> TRUE | J15: FC | K15: 1299 | L15: Night Shift | M15: NA | N15: Sunday | O15: Monday | P15: Warehouse Associate 8W | Q15: CRET | R15: Direct | S15: Dulsco | T15: aanso | U15: Sohail,Anis | V15: OFF | X15: 46020 | Y15: Customer Returns | Z15: Not Present | AA15: 0
A16: 10 | B16: 204299542 | C16: ahmeumef | D16: Ahmed Tidjan Mefire Nchankou | E16: Temporary | F16: UAE | G16: AUH1 | H16: =VLOOKUP(Table1[[#This Row],[Psoft No]],[1]Roster!$C$2:$H$1402,6,) -> AUH1 | I16: =Table1[[#This Row],[Building]]=Table1[[#This Row],[Column1]] -> TRUE | J16: FC | K16: 1299 | L16: Night Shift | M16: NA | N16: Thursday | O16: Friday | P16: Warehouse Associate 8W | Q16: CRET | R16: Direct | S16: Quesscorp | T16: aanso | U16: Sohail,Anis | V16: P | X16: 45586 | Y16: Customer Returns | Z16: Present | AA16: 0
A17: 11 | B17: 206873708 | C17: xaijueli | D17: AIJUKA ELIYA | E17: Temporary | F17: UAE | G17: AUH1 | H17: =VLOOKUP(Table1[[#This Row],[Psoft No]],[1]Roster!$C$2:$H$1402,6,) -> AUH1 | I17: =Table1[[#This Row],[Building]]=Table1[[#This Row],[Column1]] -> TRUE | J17: FC | K17: 1299 | L17: Day Shift | M17: NA | N17: Saturday | O17: Sunday | P17: Warehouse Associate 8W | Q17: CRET | R17: Direct | S17: Dulsco | T17: aanso | U17: Sohail,Anis | V17: =VLOOKUP(Table1[[#This Row],[Psoft No]],[2]Sheet1!$A$2:$G$386,7,0) -> P | X17: 46020 | Y17: Customer Returns | Z17: Present | AA17: 0
A18: 12 | B18: 203469458 | C18: ndanzyco | D18: CongratesMoforkengNdanze | E18: Temporary | F18: UAE | G18: AUH1 | H18: =VLOOKUP(Table1[[#This Row],[Psoft No]],[1]Roster!$C$2:$H$1402,6,) -> AUH1 | I18: =Table1[[#This Row],[Building]]=Table1[[#This Row],[Column1]] -> TRUE | J18: FC | K18: 1299 | L18: Day Shift | M18: NA | N18: Monday | O18: Tuesday | P18: Warehouse Associate 24M | Q18: CRET | R18: Direct | S18: Adecco | T18: aanso | U18: Sohail,Anis | V18: OFF | X18: 45456 | Y18: Customer Returns | Z18: Not Present | AA18: Carry Forwarded Annual Leave
A19: 13 | B19: 204403651 | C19: jalanssh | D19: ALAN SHIJU SHIJU | E19: Temporary | F19: UAE | G19: AUH1 | H19: =VLOOKUP(Table1[[#This Row],[Psoft No]],[1]Roster!$C$2:$H$1402,6,) -> AUH1 | I19: =Table1[[#This Row],[Building]]=Table1[[#This Row],[Column1]] -> TRUE | J19: FC | K19: 1299 | L19: Night Shift | M19: NA | N19: Wednesday | O19: Thursday | P19: Warehouse Associate 24M | Q19: CRET | R19: Direct | S19: Adecco | T19: aanso | U19: Sohail,Anis | V19: P | X19: 45596 | Y19: Customer Returns | Z19: Present | AA19: 0
A20: 14 | B20: 204299562 | C20: alectilo | D20: AlecTilowakuti | E20: Temporary | F20: UAE | G20: AUH1 | H20: =VLOOKUP(Table1[[#This Row],[Psoft No]],[1]Roster!$C$2:$H$1402,6,) -> AUH1 | I20: =Table1[[#This Row],[Building]]=Table1[[#This Row],[Column1]] -> TRUE | J20: FC | K20: 1299 | L20: Night Shift | M20: NA | N20: Monday | O20: Tuesday | P20: Warehouse Associate 24M | Q20: CRET | R20: Direct | S20: Quesscorp | T20: aanso | U20: Sohail,Anis | V20: OFF | X20: 45586 | Y20: Customer Returns | Z20: Not Present | AA20: 0
A21: 15 | B21: 206949071 | C21: alemuyom | D21: ALEX MUYOMBA | E21: Temporary | F21: UAE | G21: AUH1 | H21: =VLOOKUP(Table1[[#This Row],[Psoft No]],[1]Roster!$C$2:$H$1402,6,) -> AUH1 | I21: =Table1[[#This Row],[Building]]=Table1[[#This Row],[Column1]] -> TRUE | J21: FC | K21: 1299 | L21: Night Shift | M21: NA | N21: Thursday | O21: Friday | P21: Warehouse Associate 24M | Q21: CRET | R21: Direct | S21: Dulsco | T21: aanso | U21: Sohail,Anis | V21: P | X21: 46048 | Y21: Customer Returns | Z21: Present | AA21: 0
A22: 16 | B22: 203083928 | C22: galeowus | D22: Alex Owusu | E22: Temporary | F22: UAE | G22: AUH1 | H22: =VLOOKUP(Table1[[#This Row],[Psoft No]],[1]Roster!$C$2:$H$1402,6,) -> AUH1 | I22: =Table1[[#This Row],[Building]]=Table1[[#This Row],[Column1]] -> TRUE | J22: FC | K22: 1299 | L22: Day Shift | M22: NA | N22: Wednesday | O22: Thursday | P22: Warehouse Associate 12M | Q22: CRET | R22: Direct | S22: Fastlink | T22: aanso | U22: Sohail,Anis | V22: =VLOOKUP(Table1[[#This Row],[Psoft No]],[2]Sheet1!$A$2:$G$386,7,0) -> P | X22: 45488 | Y22: Customer Returns | Z22: Present | AA22: 0
A23: 17 | B23: 206926473 | C23: kwailaga | D23: ALI WAILAGALA | E23: Temporary | F23: UAE | G23: AUH1 | H23: =VLOOKUP(Table1[[#This Row],[Psoft No]],[1]Roster!$C$2:$H$1402,6,) -> AUH1 | I23: =Table1[[#This Row],[Building]]=Table1[[#This Row],[Column1]] -> TRUE | J23: FC | K23: 1299 | L23: Day Shift | M23: NA | N23: Tuesday | O23: Wednesday | P23: Warehouse Associate 8W | Q23: CRET | R23: Direct | S23: Dulsco | T23: aanso | U23: Sohail,Anis | V23: =VLOOKUP(Table1[[#This Row],[Psoft No]],[2]Sheet1!$A$2:$G$386,7,0) -> P | X23: 46048 | Y23: Customer Returns | Z23: Present | AA23: 0
A24: 18 | B24: 203469072 | C24: aliallaf | D24: Allafha Ali | E24: Temporary | F24: UAE | G24: AUH1 | H24: =VLOOKUP(Table1[[#This Row],[Psoft No]],[1]Roster!$C$2:$H$1402,6,) -> AUH1 | I24: =Table1[[#This Row],[Building]]=Table1[[#This Row],[Column1]] -> TRUE | J24: FC | K24: 1299 | L24: Night Shift | M24: NA | N24: Friday | O24: Saturday | P24: Warehouse Associate 12M | Q24: CRET | R24: Direct | S24: Fastlink | T24: aanso | U24: Sohail,Anis | V24: P | X24: 45456 | Y24: Customer Returns | Z24: Present | AA24: 0
A25: 19 | B25: 206875142 | C25: ddumalla | D25: ALLAN DDUMBA SSENTAMU | E25: Temporary | F25: UAE | G25: AUH1 | H25: =VLOOKUP(Table1[[#This Row],[Psoft No]],[1]Roster!$C$2:$H$1402,6,) -> AUH1 | I25: =Table1[[#This Row],[Building]]=Table1[[#This Row],[Column1]] -> TRUE | J25: FC | K25: 1299 | L25: Night Shift | M25: NA | N25: Sunday | O25: Monday | P25: Warehouse Associate 8W | Q25: CRET | R25: Direct | S25: Dulsco | T25: aanso | U25: Sohail,Anis | V25: OFF | X25: 46020 | Y25: Customer Returns | Z25: Not Present | AA25: 0
A26: 20 | B26: 206953811 | C26: allanmub | D26: ALLAN MUBANGIZI | E26: Temporary | F26: UAE | G26: AUH1 | H26: =VLOOKUP(Table1[[#This Row],[Psoft No]],[1]Roster!$C$2:$H$1402,6,) -> AUH1 | I26: =Table1[[#This Row],[Building]]=Table1[[#This Row],[Column1]] -> TRUE | J26: FC | K26: 1299 | L26: Night Shift | M26: NA | N26: Thursday | O26: Friday | P26: Warehouse Associate 24M | Q26: CRET | R26: Direct | S26: Dulsco | T26: bavameer | U26: Meera,Bava Bahrudeen | V26: P | X26: 46048 | Y26: Customer Returns | Z26: Present | AA26: 0
A27: 21 | B27: 206875146 | C27: alphaatk | D27: ALPHA ATHANASIO KINYAPALA | E27: Temporary | F27: UAE | G27: AUH1 | H27: =VLOOKUP(Table1[[#This Row],[Psoft No]],[1]Roster!$C$2:$H$1402,6,) -> AUH1 | I27: =Table1[[#This Row],[Building]]=Table1[[#This Row],[Column1]] -> TRUE | J27: FC | K27: 1299 | L27: Night Shift | M27: NA | N27: Saturday | O27: Sunday | P27: Warehouse Associate 8W | Q27: CRET | R27: Direct | S27: Dulsco | T27: aanso | U27: Sohail,Anis | V27: P | X27: 46020 | Y27: Customer Returns | Z27: Present | AA27: 0
A28: 22 | B28: 205496017 | C28: roambili | D28: AmbiliaRop | E28: Temporary | F28: UAE | G28: AUH1 | H28: =VLOOKUP(Table1[[#This Row],[Psoft No]],[1]Roster!$C$2:$H$1402,6,) -> AUH1 | I28: =Table1[[#This Row],[Building]]=Table1[[#This Row],[Column1]] -> TRUE | J28: FC | K28: 1299 | L28: Night Shift | M28: NA | N28: Tuesday | O28: Wednesday | P28: Warehouse Associate 8W | Q28: CRET | R28: Direct | S28: EFS | T28: aanso | U28: Sohail,Anis | V28: P | X28: 45831 | Y28: Customer Returns | Z28: Present | AA28: 0
A29: 23 | B29: 206294541 | C29: amkkamar | D29: AMIDU KAMARA | E29: Temporary | F29: UAE | G29: AUH1 | H29: =VLOOKUP(Table1[[#This Row],[Psoft No]],[1]Roster!$C$2:$H$1402,6,) -> AUH1 | I29: =Table1[[#This Row],[Building]]=Table1[[#This Row],[Column1]] -> TRUE | J29: FC | K29: 1299 | L29: Night Shift | M29: NA | N29: Thursday | O29: Friday | P29: Warehouse Associate 8W | Q29: CRET | R29: Direct | S29: EFS | T29: aanso | U29: Sohail,Anis | V29: P | X29: 45950 | Y29: Customer Returns | Z29: Present | AA29: 0
